Workbook
Name liste_évaluation: #REF!
Name valeurs: #REF!
Name valeurs: #REF!
Name valeurs: #REF!
Name valeurs: #REF!
Name valeurs: #REF!
Name valeurs: #REF!
Name valeurs: #REF!

Sheet Accueil

Sheet Méthodologie

Sheet Contexte
B2: Étapes préalables et description du contexte de priorisation
B4: Organisation pour laquelle la priorisation est effectuée
B5: Niveau d'avancement dans la mise en œuvre des ONR
B6: Documents politiques et stratégiques existants ou en préparation qui peuvent faciliter l'identification des cibles et ONR prioritaires
B7: Sources d'information pertinentes sur la situation relativement à l'atteinte des cibles des ONR
B8: Service responsable de la priorisation
B10: Noms et titres des analystes
B11: Personne responsable de l'analyse et du suivi
B12: Date de l'analyse

Sheet ONR 1
L1: 0 | M1: 1 | N1: 2 | O1: 3 | P1: 4 | Q1: 5
B2: ONR 1 - SOBRIÉTÉ : S'engager à optimiser les outils numériques pour limiter leurs impacts et consommation
D4: Importance de la cible | F4: Performance actuelle | H4: Compétences interne-externe | J4: Priorité | V4: Mise en œuvre
D5: Enjeux: opportunités et menaces | E5: Importance de la cible (Objectifs de TNRC) | F5: Performance actuelle évaluée (Expérimentations) | G5: Documentation de la performance actuelle et description des mesures déjà en place ( Analyse des expérimentations à date ) | H5: Compétences | I5: Forces et faiblesses | J5: Niveau de priorité | K5: Valeur priorité | L5: Intervention urgente | M5: Intervention prioritaire | N5: Intervention à moyen terme | O5: Intervention à long terme | P5: Intervention de consolidation | Q5: Intervention non prioritaire | R5: Intervention non pertinente | S5: Priorité texte | T5: Priorité valeur | U5: Valeur type d'action | V5: Stratégies d'action pouvant contribuer à l'atteinte de la cible
B6: Cibles: évaluer les niveaux d'importance, de performance et de compétence des cibles ci-dessous, et identifier des pistes d'actions favorisant l'atteinte des cibles
B7: 1.1 | C7: En intégrant le Cycle de Vie complet des équipements et logiciels pour le mettre au service de la transition énergétique | J7: =S7 | K7: =E7*10+F7 -> 0 | L7: =OR(K7=31) -> FALSE | M7: =OR(K7=21,K7=32) -> FALSE | N7: =OR(K7=22,K7=33) -> FALSE | O7: =OR(K7=11,K7=12) -> FALSE | P7: =OR(K7=23,K7=34) -> FALSE | Q7: =OR(K7=13,K7=14,K7=24) -> FALSE | R7: =OR(K7=1,K7=2,K7=3,K7=4) -> FALSE | S7: =IF(COUNTA(E7:F7)<2,"",(IF(L7=TRUE,$L$5,IF(M7=TRUE,$M$5,IF(N7=TRUE,$N$5,IF(O7=TRUE,$O$5,IF(P7=TRUE,$P$5,IF(Q7=TRUE,$Q$5,IF(R7=TRUE,$R$5,0))))))))) | T7: =IF(COUNTA(E7:F7)<2,"",(IF(L7=TRUE,6,IF(M7=TRUE,5,IF(N7=TRUE,4,IF(O7=TRUE,3,IF(P7=TRUE,2,IF(Q7=TRUE,1,IF(R7=TRUE,0,0))))))))) | U7: =T7*10+#REF! -> #VALUE!
B8: 1.2 | C8: En permettant la durée de vie des équipements, même au-delà de leur amortissement comptable et en valorisant les gains et roi pour chacune des partie prenantes | J8: =S8 | K8: =E8*10+F8 -> 0 | L8: =OR(K8=31) -> FALSE | M8: =OR(K8=21,K8=32) -> FALSE | N8: =OR(K8=22,K8=33) -> FALSE | O8: =OR(K8=11,K8=12) -> FALSE | P8: =OR(K8=23,K8=34) -> FALSE | Q8: =OR(K8=13,K8=14,K8=24) -> FALSE | R8: =OR(K8=1,K8=2,K8=3,K8=4) -> FALSE | S8: =IF(COUNTA(E8:F8)<2,"",(IF(L8=TRUE,$L$5,IF(M8=TRUE,$M$5,IF(N8=TRUE,$N$5,IF(O8=TRUE,$O$5,IF(P8=TRUE,$P$5,IF(Q8=TRUE,$Q$5,IF(R8=TRUE,$R$5,0))))))))) | T8: =IF(COUNTA(E8:F8)<2,"",(IF(L8=TRUE,6,IF(M8=TRUE,5,IF(N8=TRUE,4,IF(O8=TRUE,3,IF(P8=TRUE,2,IF(Q8=TRUE,1,IF(R8=TRUE,0,0))))))))) | U8: =T8*10+H8 -> #VALUE!
B9: 1.3 | C9: En permettant de concevoir de manière responsable les services numériques et en intégrant des technologies ou des dispositifs proactifs vis-àvis des ODD. | J9: =S9 | K9: =E9*10+F9 -> 0 | L9: =OR(K9=31) -> FALSE | M9: =OR(K9=21,K9=32) -> FALSE | N9: =OR(K9=22,K9=33) -> FALSE | O9: =OR(K9=11,K9=12) -> FALSE | P9: =OR(K9=23,K9=34) -> FALSE | Q9: =OR(K9=13,K9=14,K9=24) -> FALSE | R9: =OR(K9=1,K9=2,K9=3,K9=4) -> FALSE | S9: =IF(COUNTA(E9:F9)<2,"",(IF(L9=TRUE,$L$5,IF(M9=TRUE,$M$5,IF(N9=TRUE,$N$5,IF(O9=TRUE,$O$5,IF(P9=TRUE,$P$5,IF(Q9=TRUE,$Q$5,IF(R9=TRUE,$R$5,0))))))))) | T9: =IF(COUNTA(E9:F9)<2,"",(IF(L9=TRUE,6,IF(M9=TRUE,5,IF(N9=TRUE,4,IF(O9=TRUE,3,IF(P9=TRUE,2,IF(Q9=TRUE,1,IF(R9=TRUE,0,0))))))))) | U9: =T9*10+H9 -> #VALUE!
B10: 1.4 | C10: En favorisant des usages et des pratiques limitant les consommations de matériels, de ressources, d’énergies et de consommables | J10: =S10 | K10: =E10*10+F10 -> 0 | L10: =OR(K10=31) -> FALSE | M10: =OR(K10=21,K10=32) -> FALSE | N10: =OR(K10=22,K10=33) -> FALSE | O10: =OR(K10=11,K10=12) -> FALSE | P10: =OR(K10=23,K10=34) -> FALSE | Q10: =OR(K10=13,K10=14,K10=24) -> FALSE | R10: =OR(K10=1,K10=2,K10=3,K10=4) -> FALSE | S10: =IF(COUNTA(E10:F10)<2,"",(IF(L10=TRUE,$L$5,IF(M10=TRUE,$M$5,IF(N10=TRUE,$N$5,IF(O10=TRUE,$O$5,IF(P10=TRUE,$P$5,IF(Q10=TRUE,$Q$5,IF(R10=TRUE,$R$5,0))))))))) | T10: =IF(COUNTA(E10:F10)<2,"",(IF(L10=TRUE,6,IF(M10=TRUE,5,IF(N10=TRUE,4,IF(O10=TRUE,3,IF(P10=TRUE,2,IF(Q10=TRUE,1,IF(R10=TRUE,0,0))))))))) | U10: =T10*10+H10 -> #VALUE!
B11: 1.5 | C11: En considérant nos déchets comme une ressource et leur traitement comme une source d’emplois participant au développement de l’économie circulaire. | J11: =S11 | K11: =E11*10+F11 -> 0 | L11: =OR(K11=31) -> FALSE | M11: =OR(K11=21,K11=32) -> FALSE | N11: =OR(K11=22,K11=33) -> FALSE | O11: =OR(K11=11,K11=12) -> FALSE | P11: =OR(K11=23,K11=34) -> FALSE | Q11: =OR(K11=13,K11=14,K11=24) -> FALSE | R11: =OR(K11=1,K11=2,K11=3,K11=4) -> FALSE | S11: =IF(COUNTA(E11:F11)<2,"",(IF(L11=TRUE,$L$5,IF(M11=TRUE,$M$5,IF(N11=TRUE,$N$5,IF(O11=TRUE,$O$5,IF(P11=TRUE,$P$5,IF(Q11=TRUE,$Q$5,IF(R11=TRUE,$R$5,0))))))))) | T11: =IF(COUNTA(E11:F11)<2,"",(IF(L11=TRUE,6,IF(M11=TRUE,5,IF(N11=TRUE,4,IF(O11=TRUE,3,IF(P11=TRUE,2,IF(Q11=TRUE,1,IF(R11=TRUE,0,0))))))))) | U11: =T11*10+H11 -> #VALUE!
B12: 1.6 | C12: En privilégiant et en favorisant l’utilisation de sources d’énergies renouvelables. | J12: =S12 | K12: =E12*10+F12 -> 0 | L12: =OR(K12=31) -> FALSE | M12: =OR(K12=21,K12=32) -> FALSE | N12: =OR(K12=22,K12=33) -> FALSE | O12: =OR(K12=11,K12=12) -> FALSE | P12: =OR(K12=23,K12=34) -> FALSE | Q12: =OR(K12=13,K12=14,K12=24) -> FALSE | R12: =OR(K12=1,K12=2,K12=3,K12=4) -> FALSE | S12: =IF(COUNTA(E12:F12)<2,"",(IF(L12=TRUE,$L$5,IF(M12=TRUE,$M$5,IF(N12=TRUE,$N$5,IF(O12=TRUE,$O$5,IF(P12=TRUE,$P$5,IF(Q12=TRUE,$Q$5,IF(R12=TRUE,$R$5,0))))))))) | T12: =IF(COUNTA(E12:F12)<2,"",(IF(L12=TRUE,6,IF(M12=TRUE,5,IF(N12=TRUE,4,IF(O12=TRUE,3,IF(P12=TRUE,2,IF(Q12=TRUE,1,IF(R12=TRUE,0,0))))))))) | U12: =T12*10+H12 -> #VALUE!
B13: 1.7 | C13: En favorisant l'utilisation d'IA lorsque nécessaire uniquement et en privilégiant des IA frugales | J13: =S13 | K13: =E13*10+F13 -> 0 | L13: =OR(K13=31) -> FALSE | M13: =OR(K13=21,K13=32) -> FALSE | N13: =OR(K13=22,K13=33) -> FALSE | O13: =OR(K13=11,K13=12) -> FALSE | P13: =OR(K13=23,K13=34) -> FALSE | Q13: =OR(K13=13,K13=14,K13=24) -> FALSE | R13: =OR(K13=1,K13=2,K13=3,K13=4) -> FALSE | S13: =IF(COUNTA(E13:F13)<2,"",(IF(L13=TRUE,$L$5,IF(M13=TRUE,$M$5,IF(N13=TRUE,$N$5,IF(O13=TRUE,$O$5,IF(P13=TRUE,$P$5,IF(Q13=TRUE,$Q$5,IF(R13=TRUE,$R$5,0))))))))) | T13: =IF(COUNTA(E13:F13)<2,"",(IF(L13=TRUE,6,IF(M13=TRUE,5,IF(N13=TRUE,4,IF(O13=TRUE,3,IF(P13=TRUE,2,IF(Q13=TRUE,1,IF(R13=TRUE,0,0))))))))) | U13: =T13*10+H13 -> #VALUE!

Sheet ONR 2
L1: 0 | M1: 1 | N1: 2 | O1: 3 | P1: 4 | Q1: 5
B2: ONR 2 - INCLUSION : S'engager à développer des services numériques accessibles à toutes et tous, inclusifs et durables
D4: Importance de la cible | F4: Performance actuelle | H4: Compétences interne-externe | J4: Priorité | V4: Mise en œuvre
D5: Enjeux: opportunités et menaces | E5: Importance de la cible (Objectifs de TNRC) | F5: Performance actuelle évaluée (Expérimentations) | G5: Documentation de la performance actuelle et description des mesures déjà en place ( Analyse des expérimentations à date ) | H5: Compétences | I5: Forces et faiblesses | J5: Niveau de priorité | K5: Valeur priorité | L5: Intervention urgente | M5: Intervention prioritaire | N5: Intervention à moyen terme | O5: Intervention à long terme | P5: Intervention de consolidation | Q5: Intervention non prioritaire | R5: Intervention non pertinente | S5: Priorité texte | T5: Priorité valeur | U5: Valeur type d'action | V5: Stratégies d'action pouvant contribuer à l'atteinte de la cible | W5: Adhérence
B6: Cibles: évaluer les niveaux d'importance, de performance et de compétence des cibles ci-dessous, et identifier des pistes d'actions favorisant l'atteinte des cibles
B7: 2.1 | C7: En généralisant une démarche d’achats responsables avec l’adoption de clauses sociétales et environnementales. | J7: =S7 | K7: =E7*10+F7 -> 0 | L7: =OR(K7=31) -> FALSE | M7: =OR(K7=21,K7=32) -> FALSE | N7: =OR(K7=22,K7=33) -> FALSE | O7: =OR(K7=11,K7=12) -> FALSE | P7: =OR(K7=23,K7=34) -> FALSE | Q7: =OR(K7=13,K7=14,K7=24) -> FALSE | R7: =OR(K7=1,K7=2,K7=3,K7=4) -> FALSE | S7: =IF(COUNTA(E7:F7)<2,"",(IF(L7=TRUE,$L$5,IF(M7=TRUE,$M$5,IF(N7=TRUE,$N$5,IF(O7=TRUE,$O$5,IF(P7=TRUE,$P$5,IF(Q7=TRUE,$Q$5,IF(R7=TRUE,$R$5,0))))))))) | T7: =IF(COUNTA(E7:F7)<2,"",(IF(L7=TRUE,6,IF(M7=TRUE,5,IF(N7=TRUE,4,IF(O7=TRUE,3,IF(P7=TRUE,2,IF(Q7=TRUE,1,IF(R7=TRUE,0,0))))))))) | U7: =T7*10+H7 -> #VALUE!
B8: 2.2 | C8: En permettant des applications accessibles à tous - en mesurant le niveau de conformité RGAA et en accompagnat les entreprises du territoire à se conformer à la règlementation | J8: =S8 | K8: =E8*10+F8 -> 0 | L8: =OR(K8=31) -> FALSE | M8: =OR(K8=21,K8=32) -> FALSE | N8: =OR(K8=22,K8=33) -> FALSE | O8: =OR(K8=11,K8=12) -> FALSE | P8: =OR(K8=23,K8=34) -> FALSE | Q8: =OR(K8=13,K8=14,K8=24) -> FALSE | R8: =OR(K8=1,K8=2,K8=3,K8=4) -> FALSE | S8: =IF(COUNTA(E8:F8)<2,"",(IF(L8=TRUE,$L$5,IF(M8=TRUE,$M$5,IF(N8=TRUE,$N$5,IF(O8=TRUE,$O$5,IF(P8=TRUE,$P$5,IF(Q8=TRUE,$Q$5,IF(R8=TRUE,$R$5,0))))))))) | T8: =IF(COUNTA(E8:F8)<2,"",(IF(L8=TRUE,6,IF(M8=TRUE,5,IF(N8=TRUE,4,IF(O8=TRUE,3,IF(P8=TRUE,2,IF(Q8=TRUE,1,IF(R8=TRUE,0,0))))))))) | U8: =T8*10+H8 -> #VALUE!
B9: 2.3 | C9: En déployant les applications autour des 3 U : Utiles, Utilisables, Utilisées pour en simplifier l’usage en intégrant l’accessibilité universelle pour réussir l’e-inclusion de tous | J9: =S9 | K9: =E9*10+F9 -> 0 | L9: =OR(K9=31) -> FALSE | M9: =OR(K9=21,K9=32) -> FALSE | N9: =OR(K9=22,K9=33) -> FALSE | O9: =OR(K9=11,K9=12) -> FALSE | P9: =OR(K9=23,K9=34) -> FALSE | Q9: =OR(K9=13,K9=14,K9=24) -> FALSE | R9: =OR(K9=1,K9=2,K9=3,K9=4) -> FALSE | S9: =IF(COUNTA(E9:F9)<2,"",(IF(L9=TRUE,$L$5,IF(M9=TRUE,$M$5,IF(N9=TRUE,$N$5,IF(O9=TRUE,$O$5,IF(P9=TRUE,$P$5,IF(Q9=TRUE,$Q$5,IF(R9=TRUE,$R$5,0))))))))) | T9: =IF(COUNTA(E9:F9)<2,"",(IF(L9=TRUE,6,IF(M9=TRUE,5,IF(N9=TRUE,4,IF(O9=TRUE,3,IF(P9=TRUE,2,IF(Q9=TRUE,1,IF(R9=TRUE,0,0))))))))) | U9: =T9*10+H9 -> #VALUE!
B10: 2.4 | C10: En associant l’utilisateur à la conception pour éviter des outils surdimensionnés et améliorer progressivement le niveau de conformité des services en ligne. | K10: =E10*10+F10 -> 0 | L10: =OR(K10=31) -> FALSE | M10: =OR(K10=21,K10=32) -> FALSE | N10: =OR(K10=22,K10=33) -> FALSE | O10: =OR(K10=11,K10=12) -> FALSE | P10: =OR(K10=23,K10=34) -> FALSE | Q10: =OR(K10=13,K10=14,K10=24) -> FALSE | R10: =OR(K10=1,K10=2,K10=3,K10=4) -> FALSE | S10: =IF(COUNTA(E10:F10)<2,"",(IF(L10=TRUE,$L$5,IF(M10=TRUE,$M$5,IF(N10=TRUE,$N$5,IF(O10=TRUE,$O$5,IF(P10=TRUE,$P$5,IF(Q10=TRUE,$Q$5,IF(R10=TRUE,$R$5,0))))))))) | T10: =IF(COUNTA(E10:F10)<2,"",(IF(L10=TRUE,6,IF(M10=TRUE,5,IF(N10=TRUE,4,IF(O10=TRUE,3,IF(P10=TRUE,2,IF(Q10=TRUE,1,IF(R10=TRUE,0,0))))))))) | U10: =T10*10+H10 -> #VALUE!

Sheet ONR 3
L1: 0 | M1: 1 | N1: 2 | O1: 3 | P1: 4 | Q1: 5
B2: ONR 3 - RSE : S'engager pour des pratiques numériques éthiques et responsables
D4: Importance de la cible | F4: Performance actuelle | H4: Compétences interne-externe | J4: Priorité | V4: Mise en œuvre
D5: Enjeux: opportunités et menaces | E5: Importance de la cible (Objectifs de TNRC) | F5: Performance actuelle évaluée (Expérimentations) | G5: Documentation de la performance actuelle et description des mesures déjà en place ( Analyse des expérimentations à date ) | H5: Compétences | I5: Forces et faiblesses | J5: Niveau de priorité | K5: Valeur priorité | L5: Intervention urgente | M5: Intervention prioritaire | N5: Intervention à moyen terme | O5: Intervention à long terme | P5: Intervention de consolidation | Q5: Intervention non prioritaire | R5: Intervention non pertinente | S5: Priorité texte | T5: Priorité valeur | U5: Valeur type d'action | V5: Stratégies d'action pouvant contribuer à l'atteinte de la cible
B6: Cibles: évaluer les niveaux d'importance, de performance et de compétence des cibles ci-dessous, et identifier des pistes d'actions favorisant l'atteinte des cibles
B7: 3.1 | C7: En développant des usages raisonnés des données et services dans une démarche éthique vis-à-vis des impacts sur l’environnement et les populations. | J7: =S7 | K7: =E7*10+F7 -> 0 | L7: =OR(K7=31) -> FALSE | M7: =OR(K7=21,K7=32) -> FALSE | N7: =OR(K7=22,K7=33) -> FALSE | O7: =OR(K7=11,K7=12) -> FALSE | P7: =OR(K7=23,K7=34) -> FALSE | Q7: =OR(K7=13,K7=14,K7=24) -> FALSE | R7: =OR(K7=1,K7=2,K7=3,K7=4) -> FALSE | S7: =IF(COUNTA(E7:F7)<2,"",(IF(L7=TRUE,$L$5,IF(M7=TRUE,$M$5,IF(N7=TRUE,$N$5,IF(O7=TRUE,$O$5,IF(P7=TRUE,$P$5,IF(Q7=TRUE,$Q$5,IF(R7=TRUE,$R$5,0))))))))) | T7: =IF(COUNTA(E7:F7)<2,"",(IF(L7=TRUE,6,IF(M7=TRUE,5,IF(N7=TRUE,4,IF(O7=TRUE,3,IF(P7=TRUE,2,IF(Q7=TRUE,1,IF(R7=TRUE,0,0))))))))) | U7: =T7*10+H7 -> #VALUE!
B8: 3.2 | C8: En luttant contre les pratiques trompeuses et présence de dark pattern dans les sites internet et en permettant de se conformer à la réglementation | J8: =S8 | K8: =E8*10+F8 -> 0 | L8: =OR(K8=31) -> FALSE | M8: =OR(K8=21,K8=32) -> FALSE | N8: =OR(K8=22,K8=33) -> FALSE | O8: =OR(K8=11,K8=12) -> FALSE | P8: =OR(K8=23,K8=34) -> FALSE | Q8: =OR(K8=13,K8=14,K8=24) -> FALSE | R8: =OR(K8=1,K8=2,K8=3,K8=4) -> FALSE | S8: =IF(COUNTA(E8:F8)<2,"",(IF(L8=TRUE,$L$5,IF(M8=TRUE,$M$5,IF(N8=TRUE,$N$5,IF(O8=TRUE,$O$5,IF(P8=TRUE,$P$5,IF(Q8=TRUE,$Q$5,IF(R8=TRUE,$R$5,0))))))))) | T8: =IF(COUNTA(E8:F8)<2,"",(IF(L8=TRUE,6,IF(M8=TRUE,5,IF(N8=TRUE,4,IF(O8=TRUE,3,IF(P8=TRUE,2,IF(Q8=TRUE,1,IF(R8=TRUE,0,0))))))))) | U8: =T8*10+H8 -> #VALUE!
B9: 3.3 | C9: En ne collectant que les données utiles et nécessaires au service des utilisateurs, afin de limiter les risques en matière de vie privée et impacts environnementaux en conformité avec le Règlement Général sur la Protection des Données (RGPD). | J9: =S9 | K9: =E9*10+F9 -> 0 | L9: =OR(K9=31) -> FALSE | M9: =OR(K9=21,K9=32) -> FALSE | N9: =OR(K9=22,K9=33) -> FALSE | O9: =OR(K9=11,K9=12) -> FALSE | P9: =OR(K9=23,K9=34) -> FALSE | Q9: =OR(K9=13,K9=14,K9=24) -> FALSE | R9: =OR(K9=1,K9=2,K9=3,K9=4) -> FALSE | S9: =IF(COUNTA(E9:F9)<2,"",(IF(L9=TRUE,$L$5,IF(M9=TRUE,$M$5,IF(N9=TRUE,$N$5,IF(O9=TRUE,$O$5,IF(P9=TRUE,$P$5,IF(Q9=TRUE,$Q$5,IF(R9=TRUE,$R$5,0))))))))) | T9: =IF(COUNTA(E9:F9)<2,"",(IF(L9=TRUE,6,IF(M9=TRUE,5,IF(N9=TRUE,4,IF(O9=TRUE,3,IF(P9=TRUE,2,IF(Q9=TRUE,1,IF(R9=TRUE,0,0))))))))) | U9: =T9*10+H9 -> #VALUE!
B10: 3.4 | C10: En favorisant la diversité des recrutements des métiers du numérique | J10: =S10 | K10: =E10*10+F10 -> 0 | L10: =OR(K10=31) -> FALSE | M10: =OR(K10=21,K10=32) -> FALSE | N10: =OR(K10=22,K10=33) -> FALSE | O10: =OR(K10=11,K10=12) -> FALSE | P10: =OR(K10=23,K10=34) -> FALSE | Q10: =OR(K10=13,K10=14,K10=24) -> FALSE | R10: =OR(K10=1,K10=2,K10=3,K10=4) -> FALSE | S10: =IF(COUNTA(E10:F10)<2,"",(IF(L10=TRUE,$L$5,IF(M10=TRUE,$M$5,IF(N10=TRUE,$N$5,IF(O10=TRUE,$O$5,IF(P10=TRUE,$P$5,IF(Q10=TRUE,$Q$5,IF(R10=TRUE,$R$5,0))))))))) | T10: =IF(COUNTA(E10:F10)<2,"",(IF(L10=TRUE,6,IF(M10=TRUE,5,IF(N10=TRUE,4,IF(O10=TRUE,3,IF(P10=TRUE,2,IF(Q10=TRUE,1,IF(R10=TRUE,0,0))))))))) | U10: =T10*10+H10 -> #VALUE!
B11: 3.5 | C11: En améliorant les conditions des travailleurs du numérique | J11: =S11 | K11: =E11*10+F11 -> 0 | L11: =OR(K11=31) -> FALSE | M11: =OR(K11=21,K11=32) -> FALSE | N11: =OR(K11=22,K11=33) -> FALSE | O11: =OR(K11=11,K11=12) -> FALSE | P11: =OR(K11=23,K11=34) -> FALSE | Q11: =OR(K11=13,K11=14,K11=24) -> FALSE | R11: =OR(K11=1,K11=2,K11=3,K11=4) -> FALSE | S11: =IF(COUNTA(E11:F11)<2,"",(IF(L11=TRUE,$L$5,IF(M11=TRUE,$M$5,IF(N11=TRUE,$N$5,IF(O11=TRUE,$O$5,IF(P11=TRUE,$P$5,IF(Q11=TRUE,$Q$5,IF(R11=TRUE,$R$5,0))))))))) | T11: =IF(COUNTA(E11:F11)<2,"",(IF(L11=TRUE,6,IF(M11=TRUE,5,IF(N11=TRUE,4,IF(O11=TRUE,3,IF(P11=TRUE,2,IF(Q11=TRUE,1,IF(R11=TRUE,0,0))))))))) | U11: =T11*10+H11 -> #VALUE!
B12: 3.6 | C12: En s’inscrivant résolument dans des dispositifs d’éthique algorithmique sur l’utilisation et la protection des données, notamment au regard de l’intelligence artificielle | J12: =S12 | K12: =E12*10+F12 -> 0 | L12: =OR(K12=31) -> FALSE | M12: =OR(K12=21,K12=32) -> FALSE | N12: =OR(K12=22,K12=33) -> FALSE | O12: =OR(K12=11,K12=12) -> FALSE | P12: =OR(K12=23,K12=34) -> FALSE | Q12: =OR(K12=13,K12=14,K12=24) -> FALSE | R12: =OR(K12=1,K12=2,K12=3,K12=4) -> FALSE | S12: =IF(COUNTA(E12:F12)<2,"",(IF(L12=TRUE,$L$5,IF(M12=TRUE,$M$5,IF(N12=TRUE,$N$5,IF(O12=TRUE,$O$5,IF(P12=TRUE,$P$5,IF(Q12=TRUE,$Q$5,IF(R12=TRUE,$R$5,0))))))))) | T12: =IF(COUNTA(E12:F12)<2,"",(IF(L12=TRUE,6,IF(M12=TRUE,5,IF(N12=TRUE,4,IF(O12=TRUE,3,IF(P12=TRUE,2,IF(Q12=TRUE,1,IF(R12=TRUE,0,0))))))))) | U12: =T12*10+H12 -> #VALUE!
B13: 3.7 | C13: En déployant et valorisant la démarche RSE | J13: =S13 | K13: =E13*10+F13 -> 0 | L13: =OR(K13=31) -> FALSE | M13: =OR(K13=21,K13=32) -> FALSE | N13: =OR(K13=22,K13=33) -> FALSE | O13: =OR(K13=11,K13=12) -> FALSE | P13: =OR(K13=23,K13=34) -> FALSE | Q13: =OR(K13=13,K13=14,K13=24) -> FALSE | R13: =OR(K13=1,K13=2,K13=3,K13=4) -> FALSE | S13: =IF(COUNTA(E13:F13)<2,"",(IF(L13=TRUE,$L$5,IF(M13=TRUE,$M$5,IF(N13=TRUE,$N$5,IF(O13=TRUE,$O$5,IF(P13=TRUE,$P$5,IF(Q13=TRUE,$Q$5,IF(R13=TRUE,$R$5,0))))))))) | T13: =IF(COUNTA(E13:F13)<2,"",(IF(L13=TRUE,6,IF(M13=TRUE,5,IF(N13=TRUE,4,IF(O13=TRUE,3,IF(P13=TRUE,2,IF(Q13=TRUE,1,IF(R13=TRUE,0,0))))))))) | U13: =T13*10+H13 -> #VALUE!

Sheet ONR 4
L1: 0 | M1: 1 | N1: 2 | O1: 3 | P1: 4 | Q1: 5
B2: ONR 4 - RESILIENCE ET STRATEGIE : S'engager vers un numérique responsable, indispensable pour assurer la résilience des organisations
D4: Importance de la cible | F4: Performance actuelle | H4: Compétences interne-externe | J4: Priorité | V4: Mise en œuvre
D5: Enjeux: opportunités et menaces | E5: Importance de la cible (Objectifs de TNRC) | F5: Performance actuelle évaluée (Expérimentations) | G5: Documentation de la performance actuelle et description des mesures déjà en place ( Analyse des expérimentations à date ) | H5: Compétences | I5: Forces et faiblesses | J5: Niveau de priorité | K5: Valeur priorité | L5: Intervention urgente | M5: Intervention prioritaire | N5: Intervention à moyen terme | O5: Intervention à long terme | P5: Intervention de consolidation | Q5: Intervention non prioritaire | R5: Intervention non pertinente | S5: Priorité texte | T5: Priorité valeur | U5: Valeur type d'action | V5: Stratégies d'action pouvant contribuer à l'atteinte de la cible
B6: Cibles: évaluer les niveaux d'importance, de performance et de compétence des cibles ci-dessous, et identifier des pistes d'actions favorisant l'atteinte des cibles
B7: 4.1 | C7: En respectant l'application des normes communes pour collecter, rassembler, analyser et partager les données sur les impacts des Technologie de l’Information et de la Communication (TIC) . | J7: =S7 | K7: =E7*10+F7 -> 0 | L7: =OR(K7=31) -> FALSE | M7: =OR(K7=21,K7=32) -> FALSE | N7: =OR(K7=22,K7=33) -> FALSE | O7: =OR(K7=11,K7=12) -> FALSE | P7: =OR(K7=23,K7=34) -> FALSE | Q7: =OR(K7=13,K7=14,K7=24) -> FALSE | R7: =OR(K7=1,K7=2,K7=3,K7=4) -> FALSE | S7: =IF(COUNTA(E7:F7)<2,"",(IF(L7=TRUE,$L$5,IF(M7=TRUE,$M$5,IF(N7=TRUE,$N$5,IF(O7=TRUE,$O$5,IF(P7=TRUE,$P$5,IF(Q7=TRUE,$Q$5,IF(R7=TRUE,$R$5,0))))))))) | T7: =IF(COUNTA(E7:F7)<2,"",(IF(L7=TRUE,6,IF(M7=TRUE,5,IF(N7=TRUE,4,IF(O7=TRUE,3,IF(P7=TRUE,2,IF(Q7=TRUE,1,IF(R7=TRUE,0,0))))))))) | U7: =T7*10+H7 -> #VALUE!
B8: 4.2 | C8: En participant à une démarche collaborative de conception et d’évaluation des services numériques en adéquation avec les réels besoins. | J8: =S8 | K8: =E8*10+F8 -> 0 | L8: =OR(K8=31) -> FALSE | M8: =OR(K8=21,K8=32) -> FALSE | N8: =OR(K8=22,K8=33) -> FALSE | O8: =OR(K8=11,K8=12) -> FALSE | P8: =OR(K8=23,K8=34) -> FALSE | Q8: =OR(K8=13,K8=14,K8=24) -> FALSE | R8: =OR(K8=1,K8=2,K8=3,K8=4) -> FALSE | S8: =IF(COUNTA(E8:F8)<2,"",(IF(L8=TRUE,$L$5,IF(M8=TRUE,$M$5,IF(N8=TRUE,$N$5,IF(O8=TRUE,$O$5,IF(P8=TRUE,$P$5,IF(Q8=TRUE,$Q$5,IF(R8=TRUE,$R$5,0))))))))) | T8: =IF(COUNTA(E8:F8)<2,"",(IF(L8=TRUE,6,IF(M8=TRUE,5,IF(N8=TRUE,4,IF(O8=TRUE,3,IF(P8=TRUE,2,IF(Q8=TRUE,1,IF(R8=TRUE,0,0))))))))) | U8: =T8*10+H8 -> #VALUE!
B9: 4.3 | C9: En restant innovant dans l’utilisation de nouveaux outils numériques et assurer leur analyse d'impact avec transparence et visibilité pour les utilisatuer | J9: =S9 | K9: =E9*10+F9 -> 0 | L9: =OR(K9=31) -> FALSE | M9: =OR(K9=21,K9=32) -> FALSE | N9: =OR(K9=22,K9=33) -> FALSE | O9: =OR(K9=11,K9=12) -> FALSE | P9: =OR(K9=23,K9=34) -> FALSE | Q9: =OR(K9=13,K9=14,K9=24) -> FALSE | R9: =OR(K9=1,K9=2,K9=3,K9=4) -> FALSE | S9: =IF(COUNTA(E9:F9)<2,"",(IF(L9=TRUE,$L$5,IF(M9=TRUE,$M$5,IF(N9=TRUE,$N$5,IF(O9=TRUE,$O$5,IF(P9=TRUE,$P$5,IF(Q9=TRUE,$Q$5,IF(R9=TRUE,$R$5,0))))))))) | T9: =IF(COUNTA(E9:F9)<2,"",(IF(L9=TRUE,6,IF(M9=TRUE,5,IF(N9=TRUE,4,IF(O9=TRUE,3,IF(P9=TRUE,2,IF(Q9=TRUE,1,IF(R9=TRUE,0,0))))))))) | U9: =T9*10+H9 -> #VALUE!
B10: 4.4 | C10: En permettant et en garrantissant plus de souveraineté numérique | J10: =S10 | K10: =E10*10+F10 -> 0 | L10: =OR(K10=31) -> FALSE | M10: =OR(K10=21,K10=32) -> FALSE | N10: =OR(K10=22,K10=33) -> FALSE | O10: =OR(K10=11,K10=12) -> FALSE | P10: =OR(K10=23,K10=34) -> FALSE | Q10: =OR(K10=13,K10=14,K10=24) -> FALSE | R10: =OR(K10=1,K10=2,K10=3,K10=4) -> FALSE | S10: =IF(COUNTA(E10:F10)<2,"",(IF(L10=TRUE,$L$5,IF(M10=TRUE,$M$5,IF(N10=TRUE,$N$5,IF(O10=TRUE,$O$5,IF(P10=TRUE,$P$5,IF(Q10=TRUE,$Q$5,IF(R10=TRUE,$R$5,0))))))))) | T10: =IF(COUNTA(E10:F10)<2,"",(IF(L10=TRUE,6,IF(M10=TRUE,5,IF(N10=TRUE,4,IF(O10=TRUE,3,IF(P10=TRUE,2,IF(Q10=TRUE,1,IF(R10=TRUE,0,0))))))))) | U10: =T10*10+H10 -> #VALUE!

Sheet ONR 5
L1: 0 | M1: 1 | N1: 2 | O1: 3 | P1: 4 | Q1: 5
B2: ONR 5 - MANAGEMENT : S'engager à faire les choses avec sens en respectant et en préservant les ressources qui produisent
D4: Importance de la cible | F4: Performance actuelle | H4: Compétences interne-externe | J4: Priorité | V4: Mise en œuvre
D5: Enjeux: opportunités et menaces | E5: Importance de la cible (Objectifs de TNRC) | F5: Performance actuelle évaluée (Expérimentations) | G5: Documentation de la performance actuelle et description des mesures déjà en place ( Analyse des expérimentations à date ) | H5: Compétences | I5: Forces et faiblesses | J5: Niveau de priorité | K5: Valeur priorité | L5: Intervention urgente | M5: Intervention prioritaire | N5: Intervention à moyen terme | O5: Intervention à long terme | P5: Intervention de consolidation | Q5: Intervention non prioritaire | R5: Intervention non pertinente | S5: Priorité texte | T5: Priorité valeur | U5: Valeur type d'action | V5: Stratégies d'action pouvant contribuer à l'atteinte de la cible
B6: Cibles: évaluer les niveaux d'importance, de performance et de compétence des cibles ci-dessous, et identifier des pistes d'actions favorisant l'atteinte des cibles
B7: 5.1 | C7: En incluant l’innovation sociale dans la définition de nouveaux systèmes et services numériques. | J7: =S7 | K7: =E7*10+F7 -> 0 | L7: =OR(K7=31) -> FALSE | M7: =OR(K7=21,K7=32) -> FALSE | N7: =OR(K7=22,K7=33) -> FALSE | O7: =OR(K7=11,K7=12) -> FALSE | P7: =OR(K7=23,K7=34) -> FALSE | Q7: =OR(K7=13,K7=14,K7=24) -> FALSE | R7: =OR(K7=1,K7=2,K7=3,K7=4) -> FALSE | S7: =IF(COUNTA(E7:F7)<2,"",(IF(L7=TRUE,$L$5,IF(M7=TRUE,$M$5,IF(N7=TRUE,$N$5,IF(O7=TRUE,$O$5,IF(P7=TRUE,$P$5,IF(Q7=TRUE,$Q$5,IF(R7=TRUE,$R$5,0))))))))) | T7: =IF(COUNTA(E7:F7)<2,"",(IF(L7=TRUE,6,IF(M7=TRUE,5,IF(N7=TRUE,4,IF(O7=TRUE,3,IF(P7=TRUE,2,IF(Q7=TRUE,1,IF(R7=TRUE,0,0))))))))) | U7: =T7*10+H7 -> #VALUE!
B8: 5.2 | C8: En valorisant les initiatives internes qui mobilisent l’organisation, favorisent les collaborations transversales et le bien-être au travail. | J8: =S8 | K8: =E8*10+F8 -> 0 | L8: =OR(K8=31) -> FALSE | M8: =OR(K8=21,K8=32) -> FALSE | N8: =OR(K8=22,K8=33) -> FALSE | O8: =OR(K8=11,K8=12) -> FALSE | P8: =OR(K8=23,K8=34) -> FALSE | Q8: =OR(K8=13,K8=14,K8=24) -> FALSE | R8: =OR(K8=1,K8=2,K8=3,K8=4) -> FALSE | S8: =IF(COUNTA(E8:F8)<2,"",(IF(L8=TRUE,$L$5,IF(M8=TRUE,$M$5,IF(N8=TRUE,$N$5,IF(O8=TRUE,$O$5,IF(P8=TRUE,$P$5,IF(Q8=TRUE,$Q$5,IF(R8=TRUE,$R$5,0))))))))) | T8: =IF(COUNTA(E8:F8)<2,"",(IF(L8=TRUE,6,IF(M8=TRUE,5,IF(N8=TRUE,4,IF(O8=TRUE,3,IF(P8=TRUE,2,IF(Q8=TRUE,1,IF(R8=TRUE,0,0))))))))) | U8: =T8*10+H8 -> #VALUE!
B9: 5.3 | C9: En sollicitant l’engagement et l’expertise des parties prenantes ( sur les sujets environnementaux, sociaux et sociétaux) | J9: =S9 | K9: =E9*10+F9 -> 0 | L9: =OR(K9=31) -> FALSE | M9: =OR(K9=21,K9=32) -> FALSE | N9: =OR(K9=22,K9=33) -> FALSE | O9: =OR(K9=11,K9=12) -> FALSE | P9: =OR(K9=23,K9=34) -> FALSE | Q9: =OR(K9=13,K9=14,K9=24) -> FALSE | R9: =OR(K9=1,K9=2,K9=3,K9=4) -> FALSE | S9: =IF(COUNTA(E9:F9)<2,"",(IF(L9=TRUE,$L$5,IF(M9=TRUE,$M$5,IF(N9=TRUE,$N$5,IF(O9=TRUE,$O$5,IF(P9=TRUE,$P$5,IF(Q9=TRUE,$Q$5,IF(R9=TRUE,$R$5,0))))))))) | T9: =IF(COUNTA(E9:F9)<2,"",(IF(L9=TRUE,6,IF(M9=TRUE,5,IF(N9=TRUE,4,IF(O9=TRUE,3,IF(P9=TRUE,2,IF(Q9=TRUE,1,IF(R9=TRUE,0,0))))))))) | U9: =T9*10+H9 -> #VALUE!
B10: 5.4 | C10: En permettant aux générations futures d’innover pour construire un monde ouvert à l’autre soucieux de l’équilibre des écosystèmes et du bien-vivre ensemble. | J10: =S10 | K10: =E10*10+F10 -> 0 | L10: =OR(K10=31) -> FALSE | M10: =OR(K10=21,K10=32) -> FALSE | N10: =OR(K10=22,K10=33) -> FALSE | O10: =OR(K10=11,K10=12) -> FALSE | P10: =OR(K10=23,K10=34) -> FALSE | Q10: =OR(K10=13,K10=14,K10=24) -> FALSE | R10: =OR(K10=1,K10=2,K10=3,K10=4) -> FALSE | S10: =IF(COUNTA(E10:F10)<2,"",(IF(L10=TRUE,$L$5,IF(M10=TRUE,$M$5,IF(N10=TRUE,$N$5,IF(O10=TRUE,$O$5,IF(P10=TRUE,$P$5,IF(Q10=TRUE,$Q$5,IF(R10=TRUE,$R$5,0))))))))) | T10: =IF(COUNTA(E10:F10)<2,"",(IF(L10=TRUE,6,IF(M10=TRUE,5,IF(N10=TRUE,4,IF(O10=TRUE,3,IF(P10=TRUE,2,IF(Q10=TRUE,1,IF(R10=TRUE,0,0))))))))) | U10: =T10*10+H10 -> #VALUE!
B11: 5.5 | C11: En suivant les indicateurs de performances et de conformité | J11: =S11 | K11: =E11*10+F11 -> 0 | L11: =OR(K11=31) -> FALSE | M11: =OR(K11=21,K11=32) -> FALSE | N11: =OR(K11=22,K11=33) -> FALSE | O11: =OR(K11=11,K11=12) -> FALSE | P11: =OR(K11=23,K11=34) -> FALSE | Q11: =OR(K11=13,K11=14,K11=24) -> FALSE | R11: =OR(K11=1,K11=2,K11=3,K11=4) -> FALSE | S11: =IF(COUNTA(E11:F11)<2,"",(IF(L11=TRUE,$L$5,IF(M11=TRUE,$M$5,IF(N11=TRUE,$N$5,IF(O11=TRUE,$O$5,IF(P11=TRUE,$P$5,IF(Q11=TRUE,$Q$5,IF(R11=TRUE,$R$5,0))))))))) | T11: =IF(COUNTA(E11:F11)<2,"",(IF(L11=TRUE,6,IF(M11=TRUE,5,IF(N11=TRUE,4,IF(O11=TRUE,3,IF(P11=TRUE,2,IF(Q11=TRUE,1,IF(R11=TRUE,0,0))))))))) | U11: =T11*10+H11 -> #VALUE!
B12: 5.6 | C12: En proposant des axes d’amélioration et d'innovation autour du NR ( y compris s'ils ne sont pas numériques ) | J12: =S12 | K12: =E12*10+F12 -> 0 | L12: =OR(K12=31) -> FALSE | M12: =OR(K12=21,K12=32) -> FALSE | N12: =OR(K12=22,K12=33) -> FALSE | O12: =OR(K12=11,K12=12) -> FALSE | P12: =OR(K12=23,K12=34) -> FALSE | Q12: =OR(K12=13,K12=14,K12=24) -> FALSE | R12: =OR(K12=1,K12=2,K12=3,K12=4) -> FALSE | S12: =IF(COUNTA(E12:F12)<2,"",(IF(L12=TRUE,$L$5,IF(M12=TRUE,$M$5,IF(N12=TRUE,$N$5,IF(O12=TRUE,$O$5,IF(P12=TRUE,$P$5,IF(Q12=TRUE,$Q$5,IF(R12=TRUE,$R$5,0))))))))) | T12: =IF(COUNTA(E12:F12)<2,"",(IF(L12=TRUE,6,IF(M12=TRUE,5,IF(N12=TRUE,4,IF(O12=TRUE,3,IF(P12=TRUE,2,IF(Q12=TRUE,1,IF(R12=TRUE,0,0))))))))) | U12: =T12*10+H12 -> #VALUE!

Sheet Priorisation
B2: Tableau de priorisation des cibles
A4: Importance de la cible | B4: 3 | H4: Intervention urgente | I4: Intervention de consolidation
B5: 2 | H5: Intervention prioritaire | I5: Intervention non prioritaire
B6: 1 | H6: Intervention à moyen terme | I6: Intervention non pertinente
B7: 0 | H7: Intervention à long terme
C8: 1 | D8: 2 | E8: 3 | F8: 4
C9: État de la situation actuelle

Sheet Résultats détaillés
L1: 0 | M1: 1 | N1: 2 | O1: 3 | P1: 4 | Q1: 5
B2: Résultats détaillés | V2: Mise en œuvre des actions | Y2: Analyse des Forces, Faiblesses, Opportunités et Menaces (FFOM)
D3: Enjeux locaux associés à la cible | E3: ='ONR 1'!E5 -> Importance de la cible (Objectifs de TNRC) | F3: ='ONR 1'!F5 -> Performance actuelle évaluée (Expérimentations) | G3: ='ONR 1'!G5 -> Documentation de la performance actuelle et description des mesures déjà en place ( Analyse des expérimentations à date ) | H3: ='ONR 1'!H5 -> Compétences | I3: ='ONR 1'!I5 -> Forces et faiblesses | J3: ='ONR 1'!J5 -> Niveau de priorité | K3: Valeur priorité | L3: Intervention urgente | M3: Intervention prioritaire | N3: Intervention à moyen terme | O3: Intervention à long terme | P3: Intervention de consolidation | Q3: Intervention non prioritaire | R3: Intervention non pertinente | S3: Priorité texte | T3: Priorité valeur | U3: Valeur type d'action | V3: Mesures et actions déjà en place | W3: Stratégies d'action pouvant contribuer à l'atteinte de la cible et proposées lors de l'analyse | X3: Synergies avec les Modules (M3 stratégie, M4 sensibiliser, M5 action) | Y3: Forces et faiblesses en regard de la cible | Z3: Opportunités et menaces en regard de la cible | AB3: ODD | AC3: Nombre de cibles | AD3: Nombre de cibles analysées | AE3: Cible non complétée | AF3: Nombre de cibles urgentes | AG3: Nombre de cibles prioritaires | AH3: Nombre de cibles à moyen terme | AI3: Nombre de cibles à long terme | AJ3: Nombre de cibles à consolider | AK3: Nombre de cibles non prioritaires | AL3: Nombre de cibles non pertinentes
B4: ='ONR 1'!B2 -> ONR 1 - SOBRIÉTÉ : S'engager à optimiser les outils numériques pour limiter leurs impacts et consommation | AB4: =B4 -> ONR 1 - SOBRIÉTÉ : S'engager à optimiser les outils numériques pour limiter leurs impacts et consommation | AC4: 6 | AD4: =AC4-AE4 -> -1 | AE4: =SUM(AE5:AE11) -> 7 | AF4: =SUM(AF5:AF11) -> 0 | AG4: =SUM(AG5:AG11) -> 0 | AH4: =SUM(AH5:AH11) -> 0 | AI4: =SUM(AI5:AI11) -> 0 | AJ4: =SUM(AJ5:AJ11) -> 0 | AK4: =SUM(AK5:AK11) -> 0 | AL4: =SUM(AL5:AL11) -> 0
B5: ='ONR 1'!B7 -> 1.1 | C5: ='ONR 1'!C7 -> En intégrant le Cycle de Vie complet des équipements et logiciels pour le mettre au service de la transition énergétique | D5: ='ONR 1'!D7 -> 0 | E5: ='ONR 1'!E7 -> 0 | F5: ='ONR 1'!F7 -> 0 | G5: ='ONR 1'!G7 -> 0 | H5: ='ONR 1'!H7 -> 0 | I5: ='ONR 1'!I7 -> 0 | J5: =S5 -> 0 | K5: =E5*10+F5 -> 0 | L5: =OR(K5=31) -> FALSE | M5: =OR(K5=21,K5=32) -> FALSE | N5: =OR(K5=22,K5=33) -> FALSE | O5: =OR(K5=11,K5=12) -> FALSE | P5: =OR(K5=23,K5=34) -> FALSE | Q5: =OR(K5=13,K5=14,K5=24) -> FALSE | R5: =OR(K5=1,K5=2,K5=3,K5=4) -> FALSE | S5: =IF(COUNTA(E5:F5)<2,"",(IF(L5=TRUE,$L$3,IF(M5=TRUE,$M$3,IF(N5=TRUE,$N$3,IF(O5=TRUE,$O$3,IF(P5=TRUE,$P$3,IF(Q5=TRUE,$Q$3,IF(R5=TRUE,$R$3,0))))))))) -> 0 | T5: =IF(COUNTA(E5:F5)<2,"",(IF(L5=TRUE,6,IF(M5=TRUE,5,IF(N5=TRUE,4,IF(O5=TRUE,3,IF(P5=TRUE,2,IF(Q5=TRUE,1,IF(R5=TRUE,0,0))))))))) -> 0 | U5: =T5*10+H5 -> 0 | V5: =G5 -> 0 | W5: ='ONR 1'!V7 -> 0 | X5: ='ONR 1'!W7 -> 0 | Y5: =I5 -> 0 | Z5: =D5 -> 0 | AE5: =IF(K5=0,1,0) -> 1 | AF5: =IF(L5=TRUE,1,0) -> 0 | AG5: =IF(M5=TRUE,1,0) -> 0 | AH5: =IF(N5=TRUE,1,0) -> 0 | AI5: =IF(O5=TRUE,1,0) -> 0 | AJ5: =IF(P5=TRUE,1,0) -> 0 | AK5: =IF(Q5=TRUE,1,0) -> 0 | AL5: =IF(R5=TRUE,1,0) -> 0
B6: ='ONR 1'!B8 -> 1.2 | C6: ='ONR 1'!C8 -> En permettant la durée de vie des équipements, même au-delà de leur amortissement comptable et en valorisant les gains et roi pour chacune des partie prenantes | D6: ='ONR 1'!D8 -> 0 | E6: ='ONR 1'!E8 -> 0 | F6: ='ONR 1'!F8 -> 0 | G6: ='ONR 1'!G8 -> 0 | H6: ='ONR 1'!H8 -> 0 | I6: ='ONR 1'!I8 -> 0 | J6: =S6 -> 0 | K6: =E6*10+F6 -> 0 | L6: =OR(K6=31) -> FALSE | M6: =OR(K6=21,K6=32) -> FALSE | N6: =OR(K6=22,K6=33) -> FALSE | O6: =OR(K6=11,K6=12) -> FALSE | P6: =OR(K6=23,K6=34) -> FALSE | Q6: =OR(K6=13,K6=14,K6=24) -> FALSE | R6: =OR(K6=1,K6=2,K6=3,K6=4) -> FALSE | S6: =IF(COUNTA(E6:F6)<2,"",(IF(L6=TRUE,$L$3,IF(M6=TRUE,$M$3,IF(N6=TRUE,$N$3,IF(O6=TRUE,$O$3,IF(P6=TRUE,$P$3,IF(Q6=TRUE,$Q$3,IF(R6=TRUE,$R$3,0))))))))) -> 0 | T6: =IF(COUNTA(E6:F6)<2,"",(IF(L6=TRUE,6,IF(M6=TRUE,5,IF(N6=TRUE,4,IF(O6=TRUE,3,IF(P6=TRUE,2,IF(Q6=TRUE,1,IF(R6=TRUE,0,0))))))))) -> 0 | U6: =T6*10+H6 -> 0 | V6: =G6 -> 0 | W6: ='ONR 1'!V8 -> 0 | X6: ='ONR 1'!W8 -> 0 | Y6: =I6 -> 0 | Z6: =D6 -> 0 | AE6: =IF(K6=0,1,0) -> 1 | AF6: =IF(L6=TRUE,1,0) -> 0 | AG6: =IF(M6=TRUE,1,0) -> 0 | AH6: =IF(N6=TRUE,1,0) -> 0 | AI6: =IF(O6=TRUE,1,0) -> 0 | AJ6: =IF(P6=TRUE,1,0) -> 0 | AK6: =IF(Q6=TRUE,1,0) -> 0 | AL6: =IF(R6=TRUE,1,0) -> 0
B7: ='ONR 1'!B9 -> 1.3 | C7: ='ONR 1'!C9 -> En permettant de concevoir de manière responsable les services numériques et en intégrant des technologies ou des dispositifs proactifs vis-àvis des ODD. | D7: ='ONR 1'!D9 -> 0 | E7: ='ONR 1'!E9 -> 0 | F7: ='ONR 1'!F9 -> 0 | G7: ='ONR 1'!G9 -> 0 | H7: ='ONR 1'!H9 -> 0 | I7: ='ONR 1'!I9 -> 0 | J7: =S7 -> 0 | K7: =E7*10+F7 -> 0 | L7: =OR(K7=31) -> FALSE | M7: =OR(K7=21,K7=32) -> FALSE | N7: =OR(K7=22,K7=33) -> FALSE | O7: =OR(K7=11,K7=12) -> FALSE | P7: =OR(K7=23,K7=34) -> FALSE | Q7: =OR(K7=13,K7=14,K7=24) -> FALSE | R7: =OR(K7=1,K7=2,K7=3,K7=4) -> FALSE | S7: =IF(COUNTA(E7:F7)<2,"",(IF(L7=TRUE,$L$3,IF(M7=TRUE,$M$3,IF(N7=TRUE,$N$3,IF(O7=TRUE,$O$3,IF(P7=TRUE,$P$3,IF(Q7=TRUE,$Q$3,IF(R7=TRUE,$R$3,0))))))))) -> 0 | T7: =IF(COUNTA(E7:F7)<2,"",(IF(L7=TRUE,6,IF(M7=TRUE,5,IF(N7=TRUE,4,IF(O7=TRUE,3,IF(P7=TRUE,2,IF(Q7=TRUE,1,IF(R7=TRUE,0,0))))))))) -> 0 | U7: =T7*10+H7 -> 0 | V7: =G7 -> 0 | W7: ='ONR 1'!V9 -> 0 | X7: ='ONR 1'!W9 -> 0 | Y7: =I7 -> 0 | Z7: =D7 -> 0 | AE7: =IF(K7=0,1,0) -> 1 | AF7: =IF(L7=TRUE,1,0) -> 0 | AG7: =IF(M7=TRUE,1,0) -> 0 | AH7: =IF(N7=TRUE,1,0) -> 0 | AI7: =IF(O7=TRUE,1,0) -> 0 | AJ7: =IF(P7=TRUE,1,0) -> 0 | AK7: =IF(Q7=TRUE,1,0) -> 0 | AL7: =IF(R7=TRUE,1,0) -> 0
B8: ='ONR 1'!B10 -> 1.4 | C8: ='ONR 1'!C10 -> En favorisant des usages et des pratiques limitant les consommations de matériels, de ressources, d’énergies et de consommables | D8: ='ONR 1'!D10 -> 0 | E8: ='ONR 1'!E10 -> 0 | F8: ='ONR 1'!F10 -> 0 | G8: ='ONR 1'!G10 -> 0 | H8: ='ONR 1'!H10 -> 0 | I8: ='ONR 1'!I10 -> 0 | J8: =S8 -> 0 | K8: =E8*10+F8 -> 0 | L8: =OR(K8=31) -> FALSE | M8: =OR(K8=21,K8=32) -> FALSE | N8: =OR(K8=22,K8=33) -> FALSE | O8: =OR(K8=11,K8=12) -> FALSE | P8: =OR(K8=23,K8=34) -> FALSE | Q8: =OR(K8=13,K8=14,K8=24) -> FALSE | R8: =OR(K8=1,K8=2,K8=3,K8=4) -> FALSE | S8: =IF(COUNTA(E8:F8)<2,"",(IF(L8=TRUE,$L$3,IF(M8=TRUE,$M$3,IF(N8=TRUE,$N$3,IF(O8=TRUE,$O$3,IF(P8=TRUE,$P$3,IF(Q8=TRUE,$Q$3,IF(R8=TRUE,$R$3,0))))))))) -> 0 | T8: =IF(COUNTA(E8:F8)<2,"",(IF(L8=TRUE,6,IF(M8=TRUE,5,IF(N8=TRUE,4,IF(O8=TRUE,3,IF(P8=TRUE,2,IF(Q8=TRUE,1,IF(R8=TRUE,0,0))))))))) -> 0 | U8: =T8*10+H8 -> 0 | V8: =G8 -> 0 | W8: ='ONR 1'!V10 -> 0 | X8: ='ONR 1'!W10 -> 0 | Y8: =I8 -> 0 | Z8: =D8 -> 0 | AE8: =IF(K8=0,1,0) -> 1 | AF8: =IF(L8=TRUE,1,0) -> 0 | AG8: =IF(M8=TRUE,1,0) -> 0 | AH8: =IF(N8=TRUE,1,0) -> 0 | AI8: =IF(O8=TRUE,1,0) -> 0 | AJ8: =IF(P8=TRUE,1,0) -> 0 | AK8: =IF(Q8=TRUE,1,0) -> 0 | AL8: =IF(R8=TRUE,1,0) -> 0
B9: ='ONR 1'!B11 -> 1.5 | C9: ='ONR 1'!C11 -> En considérant nos déchets comme une ressource et leur traitement comme une source d’emplois participant au développement de l’économie circulaire. | D9: ='ONR 1'!D11 -> 0 | E9: ='ONR 1'!E11 -> 0 | F9: ='ONR 1'!F11 -> 0 | G9: ='ONR 1'!G11 -> 0 | H9: ='ONR 1'!H11 -> 0 | I9: ='ONR 1'!I11 -> 0 | J9: =S9 -> 0 | K9: =E9*10+F9 -> 0 | L9: =OR(K9=31) -> FALSE | M9: =OR(K9=21,K9=32) -> FALSE | N9: =OR(K9=22,K9=33) -> FALSE | O9: =OR(K9=11,K9=12) -> FALSE | P9: =OR(K9=23,K9=34) -> FALSE | Q9: =OR(K9=13,K9=14,K9=24) -> FALSE | R9: =OR(K9=1,K9=2,K9=3,K9=4) -> FALSE | S9: =IF(COUNTA(E9:F9)<2,"",(IF(L9=TRUE,$L$3,IF(M9=TRUE,$M$3,IF(N9=TRUE,$N$3,IF(O9=TRUE,$O$3,IF(P9=TRUE,$P$3,IF(Q9=TRUE,$Q$3,IF(R9=TRUE,$R$3,0))))))))) -> 0 | T9: =IF(COUNTA(E9:F9)<2,"",(IF(L9=TRUE,6,IF(M9=TRUE,5,IF(N9=TRUE,4,IF(O9=TRUE,3,IF(P9=TRUE,2,IF(Q9=TRUE,1,IF(R9=TRUE,0,0))))))))) -> 0 | U9: =T9*10+H9 -> 0 | V9: =G9 -> 0 | W9: ='ONR 1'!V11 -> 0 | X9: ='ONR 1'!W11 -> 0 | Y9: =I9 -> 0 | Z9: =D9 -> 0 | AE9: =IF(K9=0,1,0) -> 1 | AF9: =IF(L9=TRUE,1,0) -> 0 | AG9: =IF(M9=TRUE,1,0) -> 0 | AH9: =IF(N9=TRUE,1,0) -> 0 | AI9: =IF(O9=TRUE,1,0) -> 0 | AJ9: =IF(P9=TRUE,1,0) -> 0 | AK9: =IF(Q9=TRUE,1,0) -> 0 | AL9: =IF(R9=TRUE,1,0) -> 0
B10: ='ONR 1'!B12 -> 1.6 | C10: ='ONR 1'!C12 -> En privilégiant et en favorisant l’utilisation de sources d’énergies renouvelables. | D10: ='ONR 1'!D12 -> 0 | E10: ='ONR 1'!E12 -> 0 | F10: ='ONR 1'!F12 -> 0 | G10: ='ONR 1'!G12 -> 0 | H10: ='ONR 1'!H12 -> 0 | I10: ='ONR 1'!I12 -> 0 | J10: =S10 -> 0 | K10: =E10*10+F10 -> 0 | L10: =OR(K10=31) -> FALSE | M10: =OR(K10=21,K10=32) -> FALSE | N10: =OR(K10=22,K10=33) -> FALSE | O10: =OR(K10=11,K10=12) -> FALSE | P10: =OR(K10=23,K10=34) -> FALSE | Q10: =OR(K10=13,K10=14,K10=24) -> FALSE | R10: =OR(K10=1,K10=2,K10=3,K10=4) -> FALSE | S10: =IF(COUNTA(E10:F10)<2,"",(IF(L10=TRUE,$L$3,IF(M10=TRUE,$M$3,IF(N10=TRUE,$N$3,IF(O10=TRUE,$O$3,IF(P10=TRUE,$P$3,IF(Q10=TRUE,$Q$3,IF(R10=TRUE,$R$3,0))))))))) -> 0 | T10: =IF(COUNTA(E10:F10)<2,"",(IF(L10=TRUE,6,IF(M10=TRUE,5,IF(N10=TRUE,4,IF(O10=TRUE,3,IF(P10=TRUE,2,IF(Q10=TRUE,1,IF(R10=TRUE,0,0))))))))) -> 0 | U10: =T10*10+H10 -> 0 | V10: =G10 -> 0 | W10: ='ONR 1'!V12 -> 0 | X10: ='ONR 1'!W12 -> 0 | Y10: =I10 -> 0 | Z10: =D10 -> 0 | AE10: =IF(K10=0,1,0) -> 1 | AF10: =IF(L10=TRUE,1,0) -> 0 | AG10: =IF(M10=TRUE,1,0) -> 0 | AH10: =IF(N10=TRUE,1,0) -> 0 | AI10: =IF(O10=TRUE,1,0) -> 0 | AJ10: =IF(P10=TRUE,1,0) -> 0 | AK10: =IF(Q10=TRUE,1,0) -> 0 | AL10: =IF(R10=TRUE,1,0) -> 0
B11: ='ONR 1'!B13 -> 1.7 | C11: ='ONR 1'!C13 -> En favorisant l'utilisation d'IA lorsque nécessaire uniquement et en privilégiant des IA frugales | D11: ='ONR 1'!D13 -> 0 | E11: ='ONR 1'!E13 -> 0 | F11: ='ONR 1'!F13 -> 0 | G11: ='ONR 1'!G13 -> 0 | H11: ='ONR 1'!H13 -> 0 | I11: ='ONR 1'!I13 -> 0 | J11: =S11 -> 0 | K11: =E11*10+F11 -> 0 | L11: =OR(K11=31) -> FALSE | M11: =OR(K11=21,K11=32) -> FALSE | N11: =OR(K11=22,K11=33) -> FALSE | O11: =OR(K11=11,K11=12) -> FALSE | P11: =OR(K11=23,K11=34) -> FALSE | Q11: =OR(K11=13,K11=14,K11=24) -> FALSE | R11: =OR(K11=1,K11=2,K11=3,K11=4) -> FALSE | S11: =IF(COUNTA(E11:F11)<2,"",(IF(L11=TRUE,$L$3,IF(M11=TRUE,$M$3,IF(N11=TRUE,$N$3,IF(O11=TRUE,$O$3,IF(P11=TRUE,$P$3,IF(Q11=TRUE,$Q$3,IF(R11=TRUE,$R$3,0))))))))) -> 0 | T11: =IF(COUNTA(E11:F11)<2,"",(IF(L11=TRUE,6,IF(M11=TRUE,5,IF(N11=TRUE,4,IF(O11=TRUE,3,IF(P11=TRUE,2,IF(Q11=TRUE,1,IF(R11=TRUE,0,0))))))))) -> 0 | U11: =T11*10+H11 -> 0 | V11: =G11 -> 0 | W11: ='ONR 1'!V13 -> 0 | X11: ='ONR 1'!W13 -> 0 | Y11: =I11 -> 0 | Z11: =D11 -> 0 | AE11: =IF(K11=0,1,0) -> 1 | AF11: =IF(L11=TRUE,1,0) -> 0 | AG11: =IF(M11=TRUE,1,0) -> 0 | AH11: =IF(N11=TRUE,1,0) -> 0 | AI11: =IF(O11=TRUE,1,0) -> 0 | AJ11: =IF(P11=TRUE,1,0) -> 0 | AK11: =IF(Q11=TRUE,1,0) -> 0 | AL11: =IF(R11=TRUE,1,0) -> 0
B12: ='ONR 2'!B2 -> ONR 2 - INCLUSION : S'engager à développer des services numériques accessibles à toutes et tous, inclusifs et durables | AB12: =B12 -> ONR 2 - INCLUSION : S'engager à développer des services numériques accessibles à toutes et tous, inclusifs et durables | AC12: 4 | AD12: =AC12-AE12 -> 0 | AE12: =SUM(AE13:AE16) -> 4 | AF12: =SUM(AF13:AF16) -> 0 | AG12: =SUM(AG13:AG16) -> 0 | AH12: =SUM(AH13:AH16) -> 0 | AI12: =SUM(AI13:AI16) -> 0 | AJ12: =SUM(AJ13:AJ16) -> 0 | AK12: =SUM(AK13:AK16) -> 0 | AL12: =SUM(AL13:AL16) -> 0
B13: ='ONR 2'!B7 -> 2.1 | C13: ='ONR 2'!C7 -> En généralisant une démarche d’achats responsables avec l’adoption de clauses sociétales et environnementales. | D13: ='ONR 2'!D7 -> 0 | E13: ='ONR 2'!E7 -> 0 | F13: ='ONR 2'!F7 -> 0 | G13: ='ONR 2'!G7 -> 0 | H13: ='ONR 2'!H7 -> 0 | I13: ='ONR 2'!I7 -> 0 | J13: =S13 -> 0 | K13: =E13*10+F13 -> 0 | L13: =OR(K13=31) -> FALSE | M13: =OR(K13=21,K13=32) -> FALSE | N13: =OR(K13=22,K13=33) -> FALSE | O13: =OR(K13=11,K13=12) -> FALSE | P13: =OR(K13=23,K13=34) -> FALSE | Q13: =OR(K13=13,K13=14,K13=24) -> FALSE | R13: =OR(K13=1,K13=2,K13=3,K13=4) -> FALSE | S13: =IF(COUNTA(E13:F13)<2,"",(IF(L13=TRUE,$L$3,IF(M13=TRUE,$M$3,IF(N13=TRUE,$N$3,IF(O13=TRUE,$O$3,IF(P13=TRUE,$P$3,IF(Q13=TRUE,$Q$3,IF(R13=TRUE,$R$3,0))))))))) -> 0 | T13: =IF(COUNTA(E13:F13)<2,"",(IF(L13=TRUE,6,IF(M13=TRUE,5,IF(N13=TRUE,4,IF(O13=TRUE,3,IF(P13=TRUE,2,IF(Q13=TRUE,1,IF(R13=TRUE,0,0))))))))) -> 0 | U13: =T13*10+H13 -> 0 | V13: =G13 -> 0 | W13: ='ONR 2'!V7 -> 0 | X13: ='ONR 2'!W7 -> 0 | Y13: =I13 -> 0 | Z13: =D13 -> 0 | AE13: =IF(K13=0,1,0) -> 1 | AF13: =IF(L13=TRUE,1,0) -> 0 | AG13: =IF(M13=TRUE,1,0) -> 0 | AH13: =IF(N13=TRUE,1,0) -> 0 | AI13: =IF(O13=TRUE,1,0) -> 0 | AJ13: =IF(P13=TRUE,1,0) -> 0 | AK13: =IF(Q13=TRUE,1,0) -> 0 | AL13: =IF(R13=TRUE,1,0) -> 0
B14: ='ONR 2'!B8 -> 2.2 | C14: ='ONR 2'!C8 -> En permettant des applications accessibles à tous - en mesurant le niveau de conformité RGAA et en accompagnat les entreprises du territoire à se conformer à la règlementation | D14: ='ONR 2'!D8 -> 0 | E14: ='ONR 2'!E8 -> 0 | F14: ='ONR 2'!F8 -> 0 | G14: ='ONR 2'!G8 -> 0 | H14: ='ONR 2'!H8 -> 0 | I14: ='ONR 2'!I8 -> 0 | J14: =S14 -> 0 | K14: =E14*10+F14 -> 0 | L14: =OR(K14=31) -> FALSE | M14: =OR(K14=21,K14=32) -> FALSE | N14: =OR(K14=22,K14=33) -> FALSE | O14: =OR(K14=11,K14=12) -> FALSE | P14: =OR(K14=23,K14=34) -> FALSE | Q14: =OR(K14=13,K14=14,K14=24) -> FALSE | R14: =OR(K14=1,K14=2,K14=3,K14=4) -> FALSE | S14: =IF(COUNTA(E14:F14)<2,"",(IF(L14=TRUE,$L$3,IF(M14=TRUE,$M$3,IF(N14=TRUE,$N$3,IF(O14=TRUE,$O$3,IF(P14=TRUE,$P$3,IF(Q14=TRUE,$Q$3,IF(R14=TRUE,$R$3,0))))))))) -> 0 | T14: =IF(COUNTA(E14:F14)<2,"",(IF(L14=TRUE,6,IF(M14=TRUE,5,IF(N14=TRUE,4,IF(O14=TRUE,3,IF(P14=TRUE,2,IF(Q14=TRUE,1,IF(R14=TRUE,0,0))))))))) -> 0 | U14: =T14*10+H14 -> 0 | V14: =G14 -> 0 | W14: ='ONR 2'!V8 -> 0 | X14: ='ONR 2'!W8 -> 0 | Y14: =I14 -> 0 | Z14: =D14 -> 0 | AE14: =IF(K14=0,1,0) -> 1 | AF14: =IF(L14=TRUE,1,0) -> 0 | AG14: =IF(M14=TRUE,1,0) -> 0 | AH14: =IF(N14=TRUE,1,0) -> 0 | AI14: =IF(O14=TRUE,1,0) -> 0 | AJ14: =IF(P14=TRUE,1,0) -> 0 | AK14: =IF(Q14=TRUE,1,0) -> 0 | AL14: =IF(R14=TRUE,1,0) -> 0
B15: ='ONR 2'!B9 -> 2.3 | C15: ='ONR 2'!C9 -> En déployant les applications autour des 3 U : Utiles, Utilisables, Utilisées pour en simplifier l’usage en intégrant l’accessibilité universelle pour réussir l’e-inclusion de tous | D15: ='ONR 2'!D9 -> 0 | E15: ='ONR 2'!E9 -> 0 | F15: ='ONR 2'!F9 -> 0 | G15: ='ONR 2'!G9 -> 0 | H15: ='ONR 2'!H9 -> 0 | I15: ='ONR 2'!I9 -> 0 | J15: =S15 -> 0 | K15: =E15*10+F15 -> 0 | L15: =OR(K15=31) -> FALSE | M15: =OR(K15=21,K15=32) -> FALSE | N15: =OR(K15=22,K15=33) -> FALSE | O15: =OR(K15=11,K15=12) -> FALSE | P15: =OR(K15=23,K15=34) -> FALSE | Q15: =OR(K15=13,K15=14,K15=24) -> FALSE | R15: =OR(K15=1,K15=2,K15=3,K15=4) -> FALSE | S15: =IF(COUNTA(E15:F15)<2,"",(IF(L15=TRUE,$L$3,IF(M15=TRUE,$M$3,IF(N15=TRUE,$N$3,IF(O15=TRUE,$O$3,IF(P15=TRUE,$P$3,IF(Q15=TRUE,$Q$3,IF(R15=TRUE,$R$3,0))))))))) -> 0 | T15: =IF(COUNTA(E15:F15)<2,"",(IF(L15=TRUE,6,IF(M15=TRUE,5,IF(N15=TRUE,4,IF(O15=TRUE,3,IF(P15=TRUE,2,IF(Q15=TRUE,1,IF(R15=TRUE,0,0))))))))) -> 0 | U15: =T15*10+H15 -> 0 | V15: =G15 -> 0 | W15: ='ONR 2'!V9 -> 0 | X15: ='ONR 2'!W9 -> 0 | Y15: =I15 -> 0 | Z15: =D15 -> 0 | AE15: =IF(K15=0,1,0) -> 1 | AF15: =IF(L15=TRUE,1,0) -> 0 | AG15: =IF(M15=TRUE,1,0) -> 0 | AH15: =IF(N15=TRUE,1,0) -> 0 | AI15: =IF(O15=TRUE,1,0) -> 0 | AJ15: =IF(P15=TRUE,1,0) -> 0 | AK15: =IF(Q15=TRUE,1,0) -> 0 | AL15: =IF(R15=TRUE,1,0) -> 0
B16: ='ONR 2'!B10 -> 2.4 | C16: ='ONR 2'!C10 -> En associant l’utilisateur à la conception pour éviter des outils surdimensionnés et améliorer progressivement le niveau de conformité des services en ligne. | D16: ='ONR 2'!D10 -> 0 | E16: ='ONR 2'!E10 -> 0 | F16: ='ONR 2'!F10 -> 0 | G16: ='ONR 2'!G10 -> 0 | H16: ='ONR 2'!H10 -> 0 | I16: ='ONR 2'!I10 -> 0 | J16: =S16 -> 0 | K16: =E16*10+F16 -> 0 | L16: =OR(K16=31) -> FALSE | M16: =OR(K16=21,K16=32) -> FALSE | N16: =OR(K16=22,K16=33) -> FALSE | O16: =OR(K16=11,K16=12) -> FALSE | P16: =OR(K16=23,K16=34) -> FALSE | Q16: =OR(K16=13,K16=14,K16=24) -> FALSE | R16: =OR(K16=1,K16=2,K16=3,K16=4) -> FALSE | S16: =IF(COUNTA(E16:F16)<2,"",(IF(L16=TRUE,$L$3,IF(M16=TRUE,$M$3,IF(N16=TRUE,$N$3,IF(O16=TRUE,$O$3,IF(P16=TRUE,$P$3,IF(Q16=TRUE,$Q$3,IF(R16=TRUE,$R$3,0))))))))) -> 0 | T16: =IF(COUNTA(E16:F16)<2,"",(IF(L16=TRUE,6,IF(M16=TRUE,5,IF(N16=TRUE,4,IF(O16=TRUE,3,IF(P16=TRUE,2,IF(Q16=TRUE,1,IF(R16=TRUE,0,0))))))))) -> 0 | U16: =T16*10+H16 -> 0 | V16: =G16 -> 0 | W16: ='ONR 2'!V10 -> 0 | X16: ='ONR 2'!W10 -> 0 | Y16: =I16 -> 0 | Z16: =D16 -> 0 | AE16: =IF(K16=0,1,0) -> 1 | AF16: =IF(L16=TRUE,1,0) -> 0 | AG16: =IF(M16=TRUE,1,0) -> 0 | AH16: =IF(N16=TRUE,1,0) -> 0 | AI16: =IF(O16=TRUE,1,0) -> 0 | AJ16: =IF(P16=TRUE,1,0) -> 0 | AK16: =IF(Q16=TRUE,1,0) -> 0 | AL16: =IF(R16=TRUE,1,0) -> 0
B17: ='ONR 3'!B2:C2 -> ONR 3 - RSE : S'engager pour des pratiques numériques éthiques et responsables | AB17: =B17 -> ONR 3 - RSE : S'engager pour des pratiques numériques éthiques et responsables | AC17: 7 | AD17: =AC17-AE17 -> 0 | AE17: =SUM(AE18:AE24) -> 7 | AF17: =SUM(AF18:AF24) -> 0 | AG17: =SUM(AG18:AG24) -> 0 | AH17: =SUM(AH18:AH24) -> 0 | AI17: =SUM(AI18:AI24) -> 0 | AJ17: =SUM(AJ18:AJ24) -> 0 | AK17: =SUM(AK18:AK24) -> 0 | AL17: =SUM(AL18:AL24) -> 0
B18: ='ONR 3'!B7 -> 3.1 | C18: ='ONR 3'!C7 -> En développant des usages raisonnés des données et services dans une démarche éthique vis-à-vis des impacts sur l’environnement et les populations. | D18: ='ONR 3'!D7 -> 0 | E18: ='ONR 3'!E7 -> 0 | F18: ='ONR 3'!F7 -> 0 | G18: ='ONR 3'!G7 -> 0 | H18: ='ONR 3'!H7 -> 0 | I18: ='ONR 3'!I7 -> 0 | J18: =S18 -> 0 | K18: =E18*10+F18 -> 0 | L18: =OR(K18=31) -> FALSE | M18: =OR(K18=21,K18=32) -> FALSE | N18: =OR(K18=22,K18=33) -> FALSE | O18: =OR(K18=11,K18=12) -> FALSE | P18: =OR(K18=23,K18=34) -> FALSE | Q18: =OR(K18=13,K18=14,K18=24) -> FALSE | R18: =OR(K18=1,K18=2,K18=3,K18=4) -> FALSE | S18: =IF(COUNTA(E18:F18)<2,"",(IF(L18=TRUE,$L$3,IF(M18=TRUE,$M$3,IF(N18=TRUE,$N$3,IF(O18=TRUE,$O$3,IF(P18=TRUE,$P$3,IF(Q18=TRUE,$Q$3,IF(R18=TRUE,$R$3,0))))))))) -> 0 | T18: =IF(COUNTA(E18:F18)<2,"",(IF(L18=TRUE,6,IF(M18=TRUE,5,IF(N18=TRUE,4,IF(O18=TRUE,3,IF(P18=TRUE,2,IF(Q18=TRUE,1,IF(R18=TRUE,0,0))))))))) -> 0 | U18: =T18*10+H18 -> 0 | V18: =G18 -> 0 | W18: ='ONR 3'!V7 -> 0 | X18: ='ONR 3'!W7 -> 0 | Y18: =I18 -> 0 | Z18: =D18 -> 0 | AE18: =IF(K18=0,1,0) -> 1 | AF18: =IF(L18=TRUE,1,0) -> 0 | AG18: =IF(M18=TRUE,1,0) -> 0 | AH18: =IF(N18=TRUE,1,0) -> 0 | AI18: =IF(O18=TRUE,1,0) -> 0 | AJ18: =IF(P18=TRUE,1,0) -> 0 | AK18: =IF(Q18=TRUE,1,0) -> 0 | AL18: =IF(R18=TRUE,1,0) -> 0
B19: 3.2 | C19: ='ONR 3'!C8 -> En luttant contre les pratiques trompeuses et présence de dark pattern dans les sites internet et en permettant de se conformer à la réglementation | D19: ='ONR 3'!D8 -> 0 | E19: ='ONR 3'!E8 -> 0 | F19: ='ONR 3'!F8 -> 0 | G19: ='ONR 3'!G8 -> 0 | H19: ='ONR 3'!H8 -> 0 | I19: ='ONR 3'!I8 -> 0 | J19: =S19 -> 0 | K19: =E19*10+F19 -> 0 | L19: =OR(K19=31) -> FALSE | M19: =OR(K19=21,K19=32) -> FALSE | N19: =OR(K19=22,K19=33) -> FALSE | O19: =OR(K19=11,K19=12) -> FALSE | P19: =OR(K19=23,K19=34) -> FALSE | Q19: =OR(K19=13,K19=14,K19=24) -> FALSE | R19: =OR(K19=1,K19=2,K19=3,K19=4) -> FALSE | S19: =IF(COUNTA(E19:F19)<2,"",(IF(L19=TRUE,$L$3,IF(M19=TRUE,$M$3,IF(N19=TRUE,$N$3,IF(O19=TRUE,$O$3,IF(P19=TRUE,$P$3,IF(Q19=TRUE,$Q$3,IF(R19=TRUE,$R$3,0))))))))) -> 0 | T19: =IF(COUNTA(E19:F19)<2,"",(IF(L19=TRUE,6,IF(M19=TRUE,5,IF(N19=TRUE,4,IF(O19=TRUE,3,IF(P19=TRUE,2,IF(Q19=TRUE,1,IF(R19=TRUE,0,0))))))))) -> 0 | U19: =T19*10+H19 -> 0 | V19: =G19 -> 0 | W19: ='ONR 3'!V8 -> 0 | X19: ='ONR 3'!W8 -> 0 | Y19: =I19 -> 0 | Z19: =D19 -> 0 | AE19: =IF(K19=0,1,0) -> 1 | AF19: =IF(L19=TRUE,1,0) -> 0 | AG19: =IF(M19=TRUE,1,0) -> 0 | AH19: =IF(N19=TRUE,1,0) -> 0 | AI19: =IF(O19=TRUE,1,0) -> 0 | AJ19: =IF(P19=TRUE,1,0) -> 0 | AK19: =IF(Q19=TRUE,1,0) -> 0 | AL19: =IF(R19=TRUE,1,0) -> 0
B20: 3.3 | C20: ='ONR 3'!C9 -> En ne collectant que les données utiles et nécessaires au service des utilisateurs, afin de limiter les risques en matière de vie privée et impacts environnementaux en conformité avec le Règlement Général sur la Protection des Données (RGPD). | D20: ='ONR 3'!D9 -> 0 | E20: ='ONR 3'!E9 -> 0 | F20: ='ONR 3'!F9 -> 0 | G20: ='ONR 3'!G9 -> 0 | H20: ='ONR 3'!H9 -> 0 | I20: ='ONR 3'!I9 -> 0 | J20: =S20 -> 0 | K20: =E20*10+F20 -> 0 | L20: =OR(K20=31) -> FALSE | M20: =OR(K20=21,K20=32) -> FALSE | N20: =OR(K20=22,K20=33) -> FALSE | O20: =OR(K20=11,K20=12) -> FALSE | P20: =OR(K20=23,K20=34) -> FALSE | Q20: =OR(K20=13,K20=14,K20=24) -> FALSE | R20: =OR(K20=1,K20=2,K20=3,K20=4) -> FALSE | S20: =IF(COUNTA(E20:F20)<2,"",(IF(L20=TRUE,$L$3,IF(M20=TRUE,$M$3,IF(N20=TRUE,$N$3,IF(O20=TRUE,$O$3,IF(P20=TRUE,$P$3,IF(Q20=TRUE,$Q$3,IF(R20=TRUE,$R$3,0))))))))) -> 0 | T20: =IF(COUNTA(E20:F20)<2,"",(IF(L20=TRUE,6,IF(M20=TRUE,5,IF(N20=TRUE,4,IF(O20=TRUE,3,IF(P20=TRUE,2,IF(Q20=TRUE,1,IF(R20=TRUE,0,0))))))))) -> 0 | U20: =T20*10+H20 -> 0 | V20: =G20 -> 0 | W20: ='ONR 3'!V9 -> 0 | X20: ='ONR 3'!W9 -> 0 | Y20: =I20 -> 0 | Z20: =D20 -> 0 | AE20: =IF(K20=0,1,0) -> 1 | AF20: =IF(L20=TRUE,1,0) -> 0 | AG20: =IF(M20=TRUE,1,0) -> 0 | AH20: =IF(N20=TRUE,1,0) -> 0 | AI20: =IF(O20=TRUE,1,0) -> 0 | AJ20: =IF(P20=TRUE,1,0) -> 0 | AK20: =IF(Q20=TRUE,1,0) -> 0 | AL20: =IF(R20=TRUE,1,0) -> 0
B21: 3.4 | C21: ='ONR 3'!C10 -> En favorisant la diversité des recrutements des métiers du numérique | D21: ='ONR 3'!D10 -> 0 | E21: ='ONR 3'!E10 -> 0 | F21: ='ONR 3'!F10 -> 0 | G21: ='ONR 3'!G10 -> 0 | H21: ='ONR 3'!H10 -> 0 | I21: ='ONR 3'!I10 -> 0 | J21: =S21 -> 0 | K21: =E21*10+F21 -> 0 | L21: =OR(K21=31) -> FALSE | M21: =OR(K21=21,K21=32) -> FALSE | N21: =OR(K21=22,K21=33) -> FALSE | O21: =OR(K21=11,K21=12) -> FALSE | P21: =OR(K21=23,K21=34) -> FALSE | Q21: =OR(K21=13,K21=14,K21=24) -> FALSE | R21: =OR(K21=1,K21=2,K21=3,K21=4) -> FALSE | S21: =IF(COUNTA(E21:F21)<2,"",(IF(L21=TRUE,$L$3,IF(M21=TRUE,$M$3,IF(N21=TRUE,$N$3,IF(O21=TRUE,$O$3,IF(P21=TRUE,$P$3,IF(Q21=TRUE,$Q$3,IF(R21=TRUE,$R$3,0))))))))) -> 0 | T21: =IF(COUNTA(E21:F21)<2,"",(IF(L21=TRUE,6,IF(M21=TRUE,5,IF(N21=TRUE,4,IF(O21=TRUE,3,IF(P21=TRUE,2,IF(Q21=TRUE,1,IF(R21=TRUE,0,0))))))))) -> 0 | U21: =T21*10+H21 -> 0 | V21: =G21 -> 0 | W21: ='ONR 3'!V10 -> 0 | X21: ='ONR 3'!W10 -> 0 | Y21: =I21 -> 0 | Z21: =D21 -> 0 | AE21: =IF(K21=0,1,0) -> 1 | AF21: =IF(L21=TRUE,1,0) -> 0 | AG21: =IF(M21=TRUE,1,0) -> 0 | AH21: =IF(N21=TRUE,1,0) -> 0 | AI21: =IF(O21=TRUE,1,0) -> 0 | AJ21: =IF(P21=TRUE,1,0) -> 0 | AK21: =IF(Q21=TRUE,1,0) -> 0 | AL21: =IF(R21=TRUE,1,0) -> 0
B22: 3.5 | C22: ='ONR 3'!C11 -> En améliorant les conditions des travailleurs du numérique | D22: ='ONR 3'!D11 -> 0 | E22: ='ONR 3'!E11 -> 0 | F22: ='ONR 3'!F11 -> 0 | G22: ='ONR 3'!G11 -> 0 | H22: ='ONR 3'!H11 -> 0 | I22: ='ONR 3'!I11 -> 0 | J22: =S22 -> 0 | K22: =E22*10+F22 -> 0 | L22: =OR(K22=31) -> FALSE | M22: =OR(K22=21,K22=32) -> FALSE | N22: =OR(K22=22,K22=33) -> FALSE | O22: =OR(K22=11,K22=12) -> FALSE | P22: =OR(K22=23,K22=34) -> FALSE | Q22: =OR(K22=13,K22=14,K22=24) -> FALSE | R22: =OR(K22=1,K22=2,K22=3,K22=4) -> FALSE | S22: =IF(COUNTA(E22:F22)<2,"",(IF(L22=TRUE,$L$3,IF(M22=TRUE,$M$3,IF(N22=TRUE,$N$3,IF(O22=TRUE,$O$3,IF(P22=TRUE,$P$3,IF(Q22=TRUE,$Q$3,IF(R22=TRUE,$R$3,0))))))))) -> 0 | T22: =IF(COUNTA(E22:F22)<2,"",(IF(L22=TRUE,6,IF(M22=TRUE,5,IF(N22=TRUE,4,IF(O22=TRUE,3,IF(P22=TRUE,2,IF(Q22=TRUE,1,IF(R22=TRUE,0,0))))))))) -> 0 | U22: =T22*10+H22 -> 0 | V22: =G22 -> 0 | W22: ='ONR 3'!V11 -> 0 | X22: ='ONR 3'!W11 -> 0 | Y22: =I22 -> 0 | Z22: =D22 -> 0 | AE22: =IF(K22=0,1,0) -> 1 | AF22: =IF(L22=TRUE,1,0) -> 0 | AG22: =IF(M22=TRUE,1,0) -> 0 | AH22: =IF(N22=TRUE,1,0) -> 0 | AI22: =IF(O22=TRUE,1,0) -> 0 | AJ22: =IF(P22=TRUE,1,0) -> 0 | AK22: =IF(Q22=TRUE,1,0) -> 0 | AL22: =IF(R22=TRUE,1,0) -> 0
B23: 3.6 | C23: ='ONR 3'!C12 -> En s’inscrivant résolument dans des dispositifs d’éthique algorithmique sur l’utilisation et la protection des données, notamment au regard de l’intelligence artificielle | D23: ='ONR 3'!D12 -> 0 | E23: ='ONR 3'!E12 -> 0 | F23: ='ONR 3'!F12 -> 0 | G23: ='ONR 3'!G12 -> 0 | H23: ='ONR 3'!H12 -> 0 | I23: ='ONR 3'!I12 -> 0 | J23: =S23 -> 0 | K23: =E23*10+F23 -> 0 | L23: =OR(K23=31) -> FALSE | M23: =OR(K23=21,K23=32) -> FALSE | N23: =OR(K23=22,K23=33) -> FALSE | O23: =OR(K23=11,K23=12) -> FALSE | P23: =OR(K23=23,K23=34) -> FALSE | Q23: =OR(K23=13,K23=14,K23=24) -> FALSE | R23: =OR(K23=1,K23=2,K23=3,K23=4) -> FALSE | S23: =IF(COUNTA(E23:F23)<2,"",(IF(L23=TRUE,$L$3,IF(M23=TRUE,$M$3,IF(N23=TRUE,$N$3,IF(O23=TRUE,$O$3,IF(P23=TRUE,$P$3,IF(Q23=TRUE,$Q$3,IF(R23=TRUE,$R$3,0))))))))) -> 0 | T23: =IF(COUNTA(E23:F23)<2,"",(IF(L23=TRUE,6,IF(M23=TRUE,5,IF(N23=TRUE,4,IF(O23=TRUE,3,IF(P23=TRUE,2,IF(Q23=TRUE,1,IF(R23=TRUE,0,0))))))))) -> 0 | U23: =T23*10+H23 -> 0 | V23: =G23 -> 0 | W23: ='ONR 3'!V12 -> 0 | X23: ='ONR 3'!W12 -> 0 | Y23: =I23 -> 0 | Z23: =D23 -> 0 | AE23: =IF(K23=0,1,0) -> 1 | AF23: =IF(L23=TRUE,1,0) -> 0 | AG23: =IF(M23=TRUE,1,0) -> 0 | AH23: =IF(N23=TRUE,1,0) -> 0 | AI23: =IF(O23=TRUE,1,0) -> 0 | AJ23: =IF(P23=TRUE,1,0) -> 0 | AK23: =IF(Q23=TRUE,1,0) -> 0 | AL23: =IF(R23=TRUE,1,0) -> 0
B24: 3.7 | C24: ='ONR 3'!C13 -> En déployant et valorisant la démarche RSE | D24: ='ONR 3'!D13 -> 0 | E24: ='ONR 3'!E13 -> 0 | F24: ='ONR 3'!F13 -> 0 | G24: ='ONR 3'!G13 -> 0 | H24: ='ONR 3'!H13 -> 0 | I24: ='ONR 3'!I13 -> 0 | J24: =S24 -> 0 | K24: =E24*10+F24 -> 0 | L24: =OR(K24=31) -> FALSE | M24: =OR(K24=21,K24=32) -> FALSE | N24: =OR(K24=22,K24=33) -> FALSE | O24: =OR(K24=11,K24=12) -> FALSE | P24: =OR(K24=23,K24=34) -> FALSE | Q24: =OR(K24=13,K24=14,K24=24) -> FALSE | R24: =OR(K24=1,K24=2,K24=3,K24=4) -> FALSE | S24: =IF(COUNTA(E24:F24)<2,"",(IF(L24=TRUE,$L$3,IF(M24=TRUE,$M$3,IF(N24=TRUE,$N$3,IF(O24=TRUE,$O$3,IF(P24=TRUE,$P$3,IF(Q24=TRUE,$Q$3,IF(R24=TRUE,$R$3,0))))))))) -> 0 | T24: =IF(COUNTA(E24:F24)<2,"",(IF(L24=TRUE,6,IF(M24=TRUE,5,IF(N24=TRUE,4,IF(O24=TRUE,3,IF(P24=TRUE,2,IF(Q24=TRUE,1,IF(R24=TRUE,0,0))))))))) -> 0 | U24: =T24*10+H24 -> 0 | V24: =G24 -> 0 | W24: ='ONR 3'!V13 -> 0 | X24: ='ONR 3'!W13 -> 0 | Y24: =I24 -> 0 | Z24: =D24 -> 0 | AE24: =IF(K24=0,1,0) -> 1 | AF24: =IF(L24=TRUE,1,0) -> 0 | AG24: =IF(M24=TRUE,1,0) -> 0 | AH24: =IF(N24=TRUE,1,0) -> 0 | AI24: =IF(O24=TRUE,1,0) -> 0 | AJ24: =IF(P24=TRUE,1,0) -> 0 | AK24: =IF(Q24=TRUE,1,0) -> 0 | AL24: =IF(R24=TRUE,1,0) -> 0
B25: ='ONR 4'!B2:C2 -> ONR 4 - RESILIENCE ET STRATEGIE : S'engager vers un numérique responsable, indispensable pour assurer la résilience des organisations | AB25: =B25 -> ONR 4 - RESILIENCE ET STRATEGIE : S'engager vers un numérique responsable, indispensable pour assurer la résilience des organisations | AC25: 3 | AD25: =AC25-AE25 -> -1 | AE25: =SUM(AE26:AE29) -> 4 | AF25: =SUM(AF26:AF29) -> 0 | AG25: =SUM(AG26:AG29) -> 0 | AH25: =SUM(AH26:AH29) -> 0 | AI25: =SUM(AI26:AI29) -> 0 | AJ25: =SUM(AJ26:AJ29) -> 0 | AK25: =SUM(AK26:AK29) -> 0 | AL25: =SUM(AL26:AL29) -> 0
B26: ='ONR 4'!B7 -> 4.1 | C26: ='ONR 4'!C7 -> En respectant l'application des normes communes pour collecter, rassembler, analyser et partager les données sur les impacts des Technologie de l’Information et de la Communication (TIC) . | D26: ='ONR 4'!D7 -> 0 | E26: ='ONR 4'!E7 -> 0 | F26: ='ONR 4'!F7 -> 0 | G26: ='ONR 4'!G7 -> 0 | H26: ='ONR 4'!H7 -> 0 | I26: ='ONR 4'!I7 -> 0 | J26: =S26 -> 0 | K26: =E26*10+F26 -> 0 | L26: =OR(K26=31) -> FALSE | M26: =OR(K26=21,K26=32) -> FALSE | N26: =OR(K26=22,K26=33) -> FALSE | O26: =OR(K26=11,K26=12) -> FALSE | P26: =OR(K26=23,K26=34) -> FALSE | Q26: =OR(K26=13,K26=14,K26=24) -> FALSE | R26: =OR(K26=1,K26=2,K26=3,K26=4) -> FALSE | S26: =IF(COUNTA(E26:F26)<2,"",(IF(L26=TRUE,$L$3,IF(M26=TRUE,$M$3,IF(N26=TRUE,$N$3,IF(O26=TRUE,$O$3,IF(P26=TRUE,$P$3,IF(Q26=TRUE,$Q$3,IF(R26=TRUE,$R$3,0))))))))) -> 0 | T26: =IF(COUNTA(E26:F26)<2,"",(IF(L26=TRUE,6,IF(M26=TRUE,5,IF(N26=TRUE,4,IF(O26=TRUE,3,IF(P26=TRUE,2,IF(Q26=TRUE,1,IF(R26=TRUE,0,0))))))))) -> 0 | U26: =T26*10+H26 -> 0 | V26: =G26 -> 0 | W26: ='ONR 4'!V7 -> 0 | X26: ='ONR 4'!W7 -> 0 | Y26: =I26 -> 0 | Z26: =D26 -> 0 | AE26: =IF(K26=0,1,0) -> 1 | AF26: =IF(L26=TRUE,1,0) -> 0 | AG26: =IF(M26=TRUE,1,0) -> 0 | AH26: =IF(N26=TRUE,1,0) -> 0 | AI26: =IF(O26=TRUE,1,0) -> 0 | AJ26: =IF(P26=TRUE,1,0) -> 0 | AK26: =IF(Q26=TRUE,1,0) -> 0 | AL26: =IF(R26=TRUE,1,0) -> 0
B27: ='ONR 4'!B8 -> 4.2 | C27: ='ONR 4'!C8 -> En participant à une démarche collaborative de conception et d’évaluation des services numériques en adéquation avec les réels besoins. | D27: ='ONR 4'!D8 -> 0 | E27: ='ONR 4'!E8 -> 0 | F27: ='ONR 4'!F8 -> 0 | G27: ='ONR 4'!G8 -> 0 | H27: ='ONR 4'!H8 -> 0 | I27: ='ONR 4'!I8 -> 0 | J27: =S27 -> 0 | K27: =E27*10+F27 -> 0 | L27: =OR(K27=31) -> FALSE | M27: =OR(K27=21,K27=32) -> FALSE | N27: =OR(K27=22,K27=33) -> FALSE | O27: =OR(K27=11,K27=12) -> FALSE | P27: =OR(K27=23,K27=34) -> FALSE | Q27: =OR(K27=13,K27=14,K27=24) -> FALSE | R27: =OR(K27=1,K27=2,K27=3,K27=4) -> FALSE | S27: =IF(COUNTA(E27:F27)<2,"",(IF(L27=TRUE,$L$3,IF(M27=TRUE,$M$3,IF(N27=TRUE,$N$3,IF(O27=TRUE,$O$3,IF(P27=TRUE,$P$3,IF(Q27=TRUE,$Q$3,IF(R27=TRUE,$R$3,0))))))))) -> 0 | T27: =IF(COUNTA(E27:F27)<2,"",(IF(L27=TRUE,6,IF(M27=TRUE,5,IF(N27=TRUE,4,IF(O27=TRUE,3,IF(P27=TRUE,2,IF(Q27=TRUE,1,IF(R27=TRUE,0,0))))))))) -> 0 | U27: =T27*10+H27 -> 0 | V27: =G27 -> 0 | W27: ='ONR 4'!V8 -> 0 | X27: ='ONR 4'!W8 -> 0 | Y27: =I27 -> 0 | Z27: =D27 -> 0 | AE27: =IF(K27=0,1,0) -> 1 | AF27: =IF(L27=TRUE,1,0) -> 0 | AG27: =IF(M27=TRUE,1,0) -> 0 | AH27: =IF(N27=TRUE,1,0) -> 0 | AI27: =IF(O27=TRUE,1,0) -> 0 | AJ27: =IF(P27=TRUE,1,0) -> 0 | AK27: =IF(Q27=TRUE,1,0) -> 0 | AL27: =IF(R27=TRUE,1,0) -> 0
B28: ='ONR 4'!B9 -> 4.3 | C28: ='ONR 4'!C9 -> En restant innovant dans l’utilisation de nouveaux outils numériques et assurer leur analyse d'impact avec transparence et visibilité pour les utilisatuer | D28: ='ONR 4'!D9 -> 0 | E28: ='ONR 4'!E9 -> 0 | F28: ='ONR 4'!F9 -> 0 | G28: ='ONR 4'!G9 -> 0 | H28: ='ONR 4'!H9 -> 0 | I28: ='ONR 4'!I9 -> 0 | J28: =S28 -> 0 | K28: =E28*10+F28 -> 0 | L28: =OR(K28=31) -> FALSE | M28: =OR(K28=21,K28=32) -> FALSE | N28: =OR(K28=22,K28=33) -> FALSE | O28: =OR(K28=11,K28=12) -> FALSE | P28: =OR(K28=23,K28=34) -> FALSE | Q28: =OR(K28=13,K28=14,K28=24) -> FALSE | R28: =OR(K28=1,K28=2,K28=3,K28=4) -> FALSE | S28: =IF(COUNTA(E28:F28)<2,"",(IF(L28=TRUE,$L$3,IF(M28=TRUE,$M$3,IF(N28=TRUE,$N$3,IF(O28=TRUE,$O$3,IF(P28=TRUE,$P$3,IF(Q28=TRUE,$Q$3,IF(R28=TRUE,$R$3,0))))))))) -> 0 | T28: =IF(COUNTA(E28:F28)<2,"",(IF(L28=TRUE,6,IF(M28=TRUE,5,IF(N28=TRUE,4,IF(O28=TRUE,3,IF(P28=TRUE,2,IF(Q28=TRUE,1,IF(R28=TRUE,0,0))))))))) -> 0 | U28: =T28*10+H28 -> 0 | V28: =G28 -> 0 | W28: ='ONR 4'!V9 -> 0 | X28: ='ONR 4'!W9 -> 0 | Y28: =I28 -> 0 | Z28: =D28 -> 0 | AE28: =IF(K28=0,1,0) -> 1 | AF28: =IF(L28=TRUE,1,0) -> 0 | AG28: =IF(M28=TRUE,1,0) -> 0 | AH28: =IF(N28=TRUE,1,0) -> 0 | AI28: =IF(O28=TRUE,1,0) -> 0 | AJ28: =IF(P28=TRUE,1,0) -> 0 | AK28: =IF(Q28=TRUE,1,0) -> 0 | AL28: =IF(R28=TRUE,1,0) -> 0
B29: ='ONR 4'!B10 -> 4.4 | C29: ='ONR 4'!C10 -> En permettant et en garrantissant plus de souveraineté numérique | D29: ='ONR 4'!D10 -> 0 | E29: ='ONR 4'!E10 -> 0 | F29: ='ONR 4'!F10 -> 0 | G29: ='ONR 4'!G10 -> 0 | H29: ='ONR 4'!H10 -> 0 | I29: ='ONR 4'!I10 -> 0 | J29: =S29 -> 0 | K29: =E29*10+F29 -> 0 | L29: =OR(K29=31) -> FALSE | M29: =OR(K29=21,K29=32) -> FALSE | N29: =OR(K29=22,K29=33) -> FALSE | O29: =OR(K29=11,K29=12) -> FALSE | P29: =OR(K29=23,K29=34) -> FALSE | Q29: =OR(K29=13,K29=14,K29=24) -> FALSE | R29: =OR(K29=1,K29=2,K29=3,K29=4) -> FALSE | S29: =IF(COUNTA(E29:F29)<2,"",(IF(L29=TRUE,$L$3,IF(M29=TRUE,$M$3,IF(N29=TRUE,$N$3,IF(O29=TRUE,$O$3,IF(P29=TRUE,$P$3,IF(Q29=TRUE,$Q$3,IF(R29=TRUE,$R$3,0))))))))) -> 0 | T29: =IF(COUNTA(E29:F29)<2,"",(IF(L29=TRUE,6,IF(M29=TRUE,5,IF(N29=TRUE,4,IF(O29=TRUE,3,IF(P29=TRUE,2,IF(Q29=TRUE,1,IF(R29=TRUE,0,0))))))))) -> 0 | U29: =T29*10+H29 -> 0 | V29: =G29 -> 0 | W29: ='ONR 4'!V10 -> 0 | X29: ='ONR 4'!W10 -> 0 | Y29: =I29 -> 0 | Z29: =D29 -> 0 | AE29: =IF(K29=0,1,0) -> 1 | AF29: =IF(L29=TRUE,1,0) -> 0 | AG29: =IF(M29=TRUE,1,0) -> 0 | AH29: =IF(N29=TRUE,1,0) -> 0 | AI29: =IF(O29=TRUE,1,0) -> 0 | AJ29: =IF(P29=TRUE,1,0) -> 0 | AK29: =IF(Q29=TRUE,1,0) -> 0 | AL29: =IF(R29=TRUE,1,0) -> 0
