Workbook
Name liste_évaluation: #REF!
Name valeurs: #REF!
Name valeurs: #REF!
Name valeurs: #REF!
Name valeurs: #REF!
Name valeurs: #REF!
Name valeurs: #REF!
Name valeurs: #REF!

Sheet Accueil

Sheet Méthodologie

Sheet Contexte
B2: Étapes préalables et description du contexte de priorisation
B4: Organisation pour laquelle la priorisation est effectuée
B5: Niveau d'avancement dans la mise en œuvre des ONR
B6: Documents politiques et stratégiques existants ou en préparation qui peuvent faciliter l'identification des cibles et ONR prioritaires
B7: Sources d'information pertinentes sur la situation relativement à l'atteinte des cibles des ONR
B8: Service responsable de la priorisation
B10: Noms et titres des analystes
B11: Personne responsable de l'analyse et du suivi
B12: Date de l'analyse

Sheet ONR 1
L1: 0 | M1: 1 | N1: 2 | O1: 3 | P1: 4 | Q1: 5
B2: ONR 1 : Sobriété · Utiliser les outils numériques pour consommer moins de ressources et réduire leurs effets sur l’environnement
B4: Cibles à évaluer | D4: Importance de la cible | F4: Performance actuelle | H4: Compétences internes et externes | J4: Priorité | V4: Mise en œuvre
D5: Avantages possibles et risques | E5: Importance | F5: Niveau actuel | G5: Ce qui est déjà fait et ce qui justifie la note | H5: Compétences nécessaires | I5: Points forts et points faibles | J5: Niveau de priorité | K5: Clé de priorisation | L5: Intervention urgente | M5: Intervention prioritaire | N5: Intervention à moyen terme | O5: Intervention à long terme | P5: Intervention de consolidation | Q5: Intervention non prioritaire | R5: Intervention non pertinente | S5: Libellé de priorité | T5: Score de priorité | U5: Code priorité et compétences | V5: Actions proposées pour atteindre la cible
B6: Renseigner les cellules jaunes pour les notes, puis les textes utiles. La priorité se calcule automatiquement. Faire défiler vers la droite pour proposer des actions.
B7: 1.1 | C7: Prendre en compte toutes les étapes de la vie des équipements et des logiciels, de leur création à leur fin de vie, pour contribuer à la transition énergétique. | D7: Avantages possibles : réduire les émissions de gaz à effet de serre de l’organisation et se préparer aux futures règles environnementales. Risque : payer plus cher à l’achat certains équipements conçus pour limiter leurs effets sur l’environnement. | E7: 3 | F7: 1 | G7: L’équipe Achats retient le prix d’achat comme seul critère de choix. Elle ne demande pas d’analyse du cycle de vie (ACV) aux fournisseurs dans les appels d’offres. | H7: 3 | I7: Point fort : la direction des achats souhaite adopter des pratiques plus durables. Point faible : l’équipe connaît peu les labels environnementaux des équipements informatiques. | J7: =S7 -> Intervention urgente | K7: =IF(IF(ISNUMBER(E7),AND(E7>=0,E7<=3,MOD(E7,1)=0),FALSE),IF(E7=0,0,IF(IF(ISNUMBER(F7),AND(F7>=1,F7<=4,MOD(F7,1)=0),FALSE),E7*10+F7,"")),"") -> 31 | L7: =IF(ISNUMBER(K7),K7=31,FALSE) -> TRUE | M7: =IF(ISNUMBER(K7),OR(K7=21,K7=32),FALSE) -> FALSE | N7: =IF(ISNUMBER(K7),OR(K7=22,K7=33),FALSE) -> FALSE | O7: =IF(ISNUMBER(K7),OR(K7=11,K7=12),FALSE) -> FALSE | P7: =IF(ISNUMBER(K7),OR(K7=23,K7=34),FALSE) -> FALSE | Q7: =IF(ISNUMBER(K7),OR(K7=13,K7=14,K7=24),FALSE) -> FALSE | R7: =IF(ISNUMBER(K7),K7=0,FALSE) -> FALSE | S7: =IF(ISNUMBER(T7),INDEX($L$5:$R$5,1,7-T7),"") -> Intervention urgente | T7: =IF(ISNUMBER(K7),IF(L7,6,IF(M7,5,IF(N7,4,IF(O7,3,IF(P7,2,IF(Q7,1,0)))))),"") -> 6 | U7: =IF(AND(ISNUMBER(T7),ISNUMBER(H7)),IF(AND(H7>=1,H7<=4,MOD(H7,1)=0),T7*10+H7,""),"") -> 63 | V7: Former l’équipe Achats aux critères du numérique responsable et aux labels TCO et EPEAT. Dans les prochains appels d’offres pour remplacer les serveurs, faire compter les critères environnementaux pour 15 % de la note.
B8: 1.2 | C8: Utiliser les équipements plus longtemps, même après la fin de leur amortissement, c’est-à-dire la période sur laquelle leur coût est réparti dans les comptes. | D8: Avantages possibles : réduire les dépenses d’achat de matériel et les déchets d’équipements électriques et électroniques (DEEE). | E8: 3 | F8: 3 | G8: L’organisation a porté la durée de renouvellement des ordinateurs portables de trois à quatre ans l’année dernière. Elle dispose d’un contrat de maintenance. | H8: 2 | I8: Point fort : l’équipe technique peut réparer les équipements en interne. Point faible : certains utilisateurs demandent du matériel neuf pour son apparence. | J8: =S8 -> Intervention à moyen terme | K8: =IF(IF(ISNUMBER(E8),AND(E8>=0,E8<=3,MOD(E8,1)=0),FALSE),IF(E8=0,0,IF(IF(ISNUMBER(F8),AND(F8>=1,F8<=4,MOD(F8,1)=0),FALSE),E8*10+F8,"")),"") -> 33 | L8: =IF(ISNUMBER(K8),K8=31,FALSE) -> FALSE | M8: =IF(ISNUMBER(K8),OR(K8=21,K8=32),FALSE) -> FALSE | N8: =IF(ISNUMBER(K8),OR(K8=22,K8=33),FALSE) -> TRUE | O8: =IF(ISNUMBER(K8),OR(K8=11,K8=12),FALSE) -> FALSE | P8: =IF(ISNUMBER(K8),OR(K8=23,K8=34),FALSE) -> FALSE | Q8: =IF(ISNUMBER(K8),OR(K8=13,K8=14,K8=24),FALSE) -> FALSE | R8: =IF(ISNUMBER(K8),K8=0,FALSE) -> FALSE | S8: =IF(ISNUMBER(T8),INDEX($L$5:$R$5,1,7-T8),"") -> Intervention à moyen terme | T8: =IF(ISNUMBER(K8),IF(L8,6,IF(M8,5,IF(N8,4,IF(O8,3,IF(P8,2,IF(Q8,1,0)))))),"") -> 4 | U8: =IF(AND(ISNUMBER(T8),ISNUMBER(H8)),IF(AND(H8>=1,H8<=4,MOD(H8,1)=0),T8*10+H8,""),"") -> 42 | V8: Répartir le coût des équipements dans les comptes sur cinq ans au minimum : c’est la durée d’amortissement. Prévoir un stock de pièces détachées pour faciliter les réparations. Expliquer aux équipes comment garder leur ordinateur plus longtemps permet d’éviter des émissions de gaz à effet de serre.
B9: 1.3 | C9: Concevoir des services numériques qui limitent leurs effets sur l’environnement. Choisir des technologies qui contribuent aux Objectifs de développement durable (ODD). | D9: Avantages possibles : réduire les effets des services sur l’environnement dès leur conception, faciliter leur utilisation et contribuer aux Objectifs de développement durable (ODD). Risques : accumuler des problèmes techniques non résolus ou créer des logiciels trop gourmands en ressources, qui obligent à remplacer le matériel plus tôt. | E9: 3 | F9: 2 | G9: Les équipes valident les nouveaux services et sites web selon des critères fonctionnels, graphiques et financiers. Elles ne mesurent ni le poids des pages ni l’impact environnemental du code. | H9: 2 | I9: Point fort : les développeurs et les chefs de produit s’intéressent aux effets de leurs activités sur la société et l’environnement. Points faibles : ils connaissent peu les guides pour concevoir des services numériques moins polluants, comme le RGESN. Ils savent peu comment relier leurs projets aux ODD. | J9: =S9 -> Intervention prioritaire | K9: =IF(IF(ISNUMBER(E9),AND(E9>=0,E9<=3,MOD(E9,1)=0),FALSE),IF(E9=0,0,IF(IF(ISNUMBER(F9),AND(F9>=1,F9<=4,MOD(F9,1)=0),FALSE),E9*10+F9,"")),"") -> 32 | L9: =IF(ISNUMBER(K9),K9=31,FALSE) -> FALSE | M9: =IF(ISNUMBER(K9),OR(K9=21,K9=32),FALSE) -> TRUE | N9: =IF(ISNUMBER(K9),OR(K9=22,K9=33),FALSE) -> FALSE | O9: =IF(ISNUMBER(K9),OR(K9=11,K9=12),FALSE) -> FALSE | P9: =IF(ISNUMBER(K9),OR(K9=23,K9=34),FALSE) -> FALSE | Q9: =IF(ISNUMBER(K9),OR(K9=13,K9=14,K9=24),FALSE) -> FALSE | R9: =IF(ISNUMBER(K9),K9=0,FALSE) -> FALSE | S9: =IF(ISNUMBER(T9),INDEX($L$5:$R$5,1,7-T9),"") -> Intervention prioritaire | T9: =IF(ISNUMBER(K9),IF(L9,6,IF(M9,5,IF(N9,4,IF(O9,3,IF(P9,2,IF(Q9,1,0)))))),"") -> 5 | U9: =IF(AND(ISNUMBER(T9),ISNUMBER(H9)),IF(AND(H9>=1,H9<=4,MOD(H9,1)=0),T9*10+H9,""),"") -> 52 | V9: 1. Former les équipes de conception, de développement et de gestion de projet à créer des services numériques qui limitent leurs effets sur l’environnement. 2. Ajouter des exigences environnementales aux cahiers des charges, comme limiter le poids des images et réduire les demandes envoyées aux serveurs. 3. Pour chaque nouveau projet, préciser à quels Objectifs de développement durable il contribue.
B10: 1.4 | C10: Adopter des pratiques qui consomment moins de matériel, de ressources, d’énergie et de consommables, comme le papier ou l’encre. | J10: =S10 | K10: =IF(IF(ISNUMBER(E10),AND(E10>=0,E10<=3,MOD(E10,1)=0),FALSE),IF(E10=0,0,IF(IF(ISNUMBER(F10),AND(F10>=1,F10<=4,MOD(F10,1)=0),FALSE),E10*10+F10,"")),"") | L10: =IF(ISNUMBER(K10),K10=31,FALSE) -> FALSE | M10: =IF(ISNUMBER(K10),OR(K10=21,K10=32),FALSE) -> FALSE | N10: =IF(ISNUMBER(K10),OR(K10=22,K10=33),FALSE) -> FALSE | O10: =IF(ISNUMBER(K10),OR(K10=11,K10=12),FALSE) -> FALSE | P10: =IF(ISNUMBER(K10),OR(K10=23,K10=34),FALSE) -> FALSE | Q10: =IF(ISNUMBER(K10),OR(K10=13,K10=14,K10=24),FALSE) -> FALSE | R10: =IF(ISNUMBER(K10),K10=0,FALSE) -> FALSE | S10: =IF(ISNUMBER(T10),INDEX($L$5:$R$5,1,7-T10),"") | T10: =IF(ISNUMBER(K10),IF(L10,6,IF(M10,5,IF(N10,4,IF(O10,3,IF(P10,2,IF(Q10,1,0)))))),"") | U10: =IF(AND(ISNUMBER(T10),ISNUMBER(H10)),IF(AND(H10>=1,H10<=4,MOD(H10,1)=0),T10*10+H10,""),"")
B11: 1.5 | C11: Réutiliser ou recycler les déchets pour en faire de nouvelles ressources. Soutenir les emplois liés à leur traitement et à l’économie circulaire. | J11: =S11 | K11: =IF(IF(ISNUMBER(E11),AND(E11>=0,E11<=3,MOD(E11,1)=0),FALSE),IF(E11=0,0,IF(IF(ISNUMBER(F11),AND(F11>=1,F11<=4,MOD(F11,1)=0),FALSE),E11*10+F11,"")),"") | L11: =IF(ISNUMBER(K11),K11=31,FALSE) -> FALSE | M11: =IF(ISNUMBER(K11),OR(K11=21,K11=32),FALSE) -> FALSE | N11: =IF(ISNUMBER(K11),OR(K11=22,K11=33),FALSE) -> FALSE | O11: =IF(ISNUMBER(K11),OR(K11=11,K11=12),FALSE) -> FALSE | P11: =IF(ISNUMBER(K11),OR(K11=23,K11=34),FALSE) -> FALSE | Q11: =IF(ISNUMBER(K11),OR(K11=13,K11=14,K11=24),FALSE) -> FALSE | R11: =IF(ISNUMBER(K11),K11=0,FALSE) -> FALSE | S11: =IF(ISNUMBER(T11),INDEX($L$5:$R$5,1,7-T11),"") | T11: =IF(ISNUMBER(K11),IF(L11,6,IF(M11,5,IF(N11,4,IF(O11,3,IF(P11,2,IF(Q11,1,0)))))),"") | U11: =IF(AND(ISNUMBER(T11),ISNUMBER(H11)),IF(AND(H11>=1,H11<=4,MOD(H11,1)=0),T11*10+H11,""),"")
B12: 1.6 | C12: Choisir des énergies renouvelables et encourager leur utilisation. | J12: =S12 | K12: =IF(IF(ISNUMBER(E12),AND(E12>=0,E12<=3,MOD(E12,1)=0),FALSE),IF(E12=0,0,IF(IF(ISNUMBER(F12),AND(F12>=1,F12<=4,MOD(F12,1)=0),FALSE),E12*10+F12,"")),"") | L12: =IF(ISNUMBER(K12),K12=31,FALSE) -> FALSE | M12: =IF(ISNUMBER(K12),OR(K12=21,K12=32),FALSE) -> FALSE | N12: =IF(ISNUMBER(K12),OR(K12=22,K12=33),FALSE) -> FALSE | O12: =IF(ISNUMBER(K12),OR(K12=11,K12=12),FALSE) -> FALSE | P12: =IF(ISNUMBER(K12),OR(K12=23,K12=34),FALSE) -> FALSE | Q12: =IF(ISNUMBER(K12),OR(K12=13,K12=14,K12=24),FALSE) -> FALSE | R12: =IF(ISNUMBER(K12),K12=0,FALSE) -> FALSE | S12: =IF(ISNUMBER(T12),INDEX($L$5:$R$5,1,7-T12),"") | T12: =IF(ISNUMBER(K12),IF(L12,6,IF(M12,5,IF(N12,4,IF(O12,3,IF(P12,2,IF(Q12,1,0)))))),"") | U12: =IF(AND(ISNUMBER(T12),ISNUMBER(H12)),IF(AND(H12>=1,H12<=4,MOD(H12,1)=0),T12*10+H12,""),"")
B13: 1.7 | C13: Réserver l’intelligence artificielle aux besoins qui la justifient et privilégier des solutions sobres en ressources. | D13: Avantages possibles : maîtriser les coûts du matériel et des services d’IA, et réduire les émissions de gaz à effet de serre liées à leur entraînement et à leur utilisation. Risque : utiliser l’IA par effet de mode, sans besoin réel, et consommer davantage de ressources. | E13: 3 | F13: 1 | G13: Les équipes métiers expérimentent plusieurs projets d’IA générative, dont des usages de ChatGPT. Elles ne mesurent pas leur impact énergétique et ne disposent pas de charte pour encadrer les besoins et les usages. | H13: 2 | I13: Point fort : l’équipe chargée des données et de l’informatique dispose de compétences techniques et souhaite explorer ces outils. Points faibles : elle connaît peu les méthodes pour mesurer et réduire la consommation de l’IA. Elle manque aussi de recul pour savoir quand l’IA est utile. | J13: =S13 -> Intervention urgente | K13: =IF(IF(ISNUMBER(E13),AND(E13>=0,E13<=3,MOD(E13,1)=0),FALSE),IF(E13=0,0,IF(IF(ISNUMBER(F13),AND(F13>=1,F13<=4,MOD(F13,1)=0),FALSE),E13*10+F13,"")),"") -> 31 | L13: =IF(ISNUMBER(K13),K13=31,FALSE) -> TRUE | M13: =IF(ISNUMBER(K13),OR(K13=21,K13=32),FALSE) -> FALSE | N13: =IF(ISNUMBER(K13),OR(K13=22,K13=33),FALSE) -> FALSE | O13: =IF(ISNUMBER(K13),OR(K13=11,K13=12),FALSE) -> FALSE | P13: =IF(ISNUMBER(K13),OR(K13=23,K13=34),FALSE) -> FALSE | Q13: =IF(ISNUMBER(K13),OR(K13=13,K13=14,K13=24),FALSE) -> FALSE | R13: =IF(ISNUMBER(K13),K13=0,FALSE) -> FALSE | S13: =IF(ISNUMBER(T13),INDEX($L$5:$R$5,1,7-T13),"") -> Intervention urgente | T13: =IF(ISNUMBER(K13),IF(L13,6,IF(M13,5,IF(N13,4,IF(O13,3,IF(P13,2,IF(Q13,1,0)))))),"") -> 6 | U13: =IF(AND(ISNUMBER(T13),ISNUMBER(H13)),IF(AND(H13>=1,H13<=4,MOD(H13,1)=0),T13*10+H13,""),"") -> 62 | V13: 1. Vérifier le besoin avant chaque projet : faut-il de l’IA ou un outil informatique classique suffit-il ? 2. Choisir de petits modèles spécialisés quand ils répondent au besoin. 3. Former les développeurs et les spécialistes des données à réduire la consommation de l’IA, en améliorant le code et en évitant les calculs répétés.
B14: 1.8 | C14: Mesurer et réduire ce que consomme l’intelligence artificielle, pendant son entraînement comme pendant son utilisation. | D14: Avantages possibles : maîtriser les coûts du matériel et des services d’IA, et réduire les émissions de gaz à effet de serre liées à leur entraînement et à leur utilisation. Risque : utiliser l’IA par effet de mode, sans besoin réel, et consommer davantage de ressources. | E14: 3 | F14: 1 | G14: Les équipes métiers expérimentent plusieurs projets d’IA générative, dont des usages de ChatGPT. Elles ne mesurent pas leur impact énergétique et ne disposent pas de charte pour encadrer les besoins et les usages. | H14: 2 | I14: Point fort : l’équipe chargée des données et de l’informatique dispose de compétences techniques et souhaite explorer ces outils. Points faibles : elle connaît peu les méthodes pour mesurer et réduire la consommation de l’IA. Elle manque aussi de recul pour savoir quand l’IA est utile. | J14: =S14 -> Intervention urgente | K14: =IF(IF(ISNUMBER(E14),AND(E14>=0,E14<=3,MOD(E14,1)=0),FALSE),IF(E14=0,0,IF(IF(ISNUMBER(F14),AND(F14>=1,F14<=4,MOD(F14,1)=0),FALSE),E14*10+F14,"")),"") -> 31 | L14: =IF(ISNUMBER(K14),K14=31,FALSE) -> TRUE | M14: =IF(ISNUMBER(K14),OR(K14=21,K14=32),FALSE) -> FALSE | N14: =IF(ISNUMBER(K14),OR(K14=22,K14=33),FALSE) -> FALSE | O14: =IF(ISNUMBER(K14),OR(K14=11,K14=12),FALSE) -> FALSE | P14: =IF(ISNUMBER(K14),OR(K14=23,K14=34),FALSE) -> FALSE | Q14: =IF(ISNUMBER(K14),OR(K14=13,K14=14,K14=24),FALSE) -> FALSE | R14: =IF(ISNUMBER(K14),K14=0,FALSE) -> FALSE | S14: =IF(ISNUMBER(T14),INDEX($L$5:$R$5,1,7-T14),"") -> Intervention urgente | T14: =IF(ISNUMBER(K14),IF(L14,6,IF(M14,5,IF(N14,4,IF(O14,3,IF(P14,2,IF(Q14,1,0)))))),"") -> 6 | U14: =IF(AND(ISNUMBER(T14),ISNUMBER(H14)),IF(AND(H14>=1,H14<=4,MOD(H14,1)=0),T14*10+H14,""),"") -> 62 | V14: 1. Vérifier le besoin avant chaque projet : faut-il de l’IA ou un outil informatique classique suffit-il ? 2. Choisir de petits modèles spécialisés quand ils répondent au besoin. 3. Former les développeurs et les spécialistes des données à réduire la consommation de l’IA, en améliorant le code et en évitant les calculs répétés.

Sheet ONR 2
L1: 0 | M1: 1 | N1: 2 | O1: 3 | P1: 4 | Q1: 5
B2: ONR 2 : Inclusion · Développer des services numériques durables que toutes et tous peuvent utiliser
B4: Cibles à évaluer | D4: Importance de la cible | F4: Performance actuelle | H4: Compétences internes et externes | J4: Priorité | V4: Mise en œuvre
D5: Avantages possibles et risques | E5: Importance | F5: Niveau actuel | G5: Ce qui est déjà fait et ce qui justifie la note | H5: Compétences nécessaires | I5: Points forts et points faibles | J5: Niveau de priorité | K5: Clé de priorisation | L5: Intervention urgente | M5: Intervention prioritaire | N5: Intervention à moyen terme | O5: Intervention à long terme | P5: Intervention de consolidation | Q5: Intervention non prioritaire | R5: Intervention non pertinente | S5: Libellé de priorité | T5: Score de priorité | U5: Code priorité et compétences | V5: Actions proposées pour atteindre la cible | W5: Adhérence
B6: Renseigner les cellules jaunes pour les notes, puis les textes utiles. La priorité se calcule automatiquement. Faire défiler vers la droite pour proposer des actions.
B7: 2.1 | C7: Intégrer dans tous les achats des exigences qui tiennent compte de leurs effets sur la société et l’environnement. | J7: =S7 | K7: =IF(IF(ISNUMBER(E7),AND(E7>=0,E7<=3,MOD(E7,1)=0),FALSE),IF(E7=0,0,IF(IF(ISNUMBER(F7),AND(F7>=1,F7<=4,MOD(F7,1)=0),FALSE),E7*10+F7,"")),"") | L7: =IF(ISNUMBER(K7),K7=31,FALSE) -> FALSE | M7: =IF(ISNUMBER(K7),OR(K7=21,K7=32),FALSE) -> FALSE | N7: =IF(ISNUMBER(K7),OR(K7=22,K7=33),FALSE) -> FALSE | O7: =IF(ISNUMBER(K7),OR(K7=11,K7=12),FALSE) -> FALSE | P7: =IF(ISNUMBER(K7),OR(K7=23,K7=34),FALSE) -> FALSE | Q7: =IF(ISNUMBER(K7),OR(K7=13,K7=14,K7=24),FALSE) -> FALSE | R7: =IF(ISNUMBER(K7),K7=0,FALSE) -> FALSE | S7: =IF(ISNUMBER(T7),INDEX($L$5:$R$5,1,7-T7),"") | T7: =IF(ISNUMBER(K7),IF(L7,6,IF(M7,5,IF(N7,4,IF(O7,3,IF(P7,2,IF(Q7,1,0)))))),"") | U7: =IF(AND(ISNUMBER(T7),ISNUMBER(H7)),IF(AND(H7>=1,H7<=4,MOD(H7,1)=0),T7*10+H7,""),"")
B8: 2.2 | C8: Rendre les services numériques accessibles à toutes et tous. Mesurer leur respect du RGAA, le référentiel français sur l’accessibilité numérique. | J8: =S8 | K8: =IF(IF(ISNUMBER(E8),AND(E8>=0,E8<=3,MOD(E8,1)=0),FALSE),IF(E8=0,0,IF(IF(ISNUMBER(F8),AND(F8>=1,F8<=4,MOD(F8,1)=0),FALSE),E8*10+F8,"")),"") | L8: =IF(ISNUMBER(K8),K8=31,FALSE) -> FALSE | M8: =IF(ISNUMBER(K8),OR(K8=21,K8=32),FALSE) -> FALSE | N8: =IF(ISNUMBER(K8),OR(K8=22,K8=33),FALSE) -> FALSE | O8: =IF(ISNUMBER(K8),OR(K8=11,K8=12),FALSE) -> FALSE | P8: =IF(ISNUMBER(K8),OR(K8=23,K8=34),FALSE) -> FALSE | Q8: =IF(ISNUMBER(K8),OR(K8=13,K8=14,K8=24),FALSE) -> FALSE | R8: =IF(ISNUMBER(K8),K8=0,FALSE) -> FALSE | S8: =IF(ISNUMBER(T8),INDEX($L$5:$R$5,1,7-T8),"") | T8: =IF(ISNUMBER(K8),IF(L8,6,IF(M8,5,IF(N8,4,IF(O8,3,IF(P8,2,IF(Q8,1,0)))))),"") | U8: =IF(AND(ISNUMBER(T8),ISNUMBER(H8)),IF(AND(H8>=1,H8<=4,MOD(H8,1)=0),T8*10+H8,""),"")
B9: 2.3 | C9: Créer des applications utiles, faciles à utiliser et réellement utilisées : les « 3 U ». Les rendre accessibles pour permettre à chacun d’utiliser le numérique. | J9: =S9 | K9: =IF(IF(ISNUMBER(E9),AND(E9>=0,E9<=3,MOD(E9,1)=0),FALSE),IF(E9=0,0,IF(IF(ISNUMBER(F9),AND(F9>=1,F9<=4,MOD(F9,1)=0),FALSE),E9*10+F9,"")),"") | L9: =IF(ISNUMBER(K9),K9=31,FALSE) -> FALSE | M9: =IF(ISNUMBER(K9),OR(K9=21,K9=32),FALSE) -> FALSE | N9: =IF(ISNUMBER(K9),OR(K9=22,K9=33),FALSE) -> FALSE | O9: =IF(ISNUMBER(K9),OR(K9=11,K9=12),FALSE) -> FALSE | P9: =IF(ISNUMBER(K9),OR(K9=23,K9=34),FALSE) -> FALSE | Q9: =IF(ISNUMBER(K9),OR(K9=13,K9=14,K9=24),FALSE) -> FALSE | R9: =IF(ISNUMBER(K9),K9=0,FALSE) -> FALSE | S9: =IF(ISNUMBER(T9),INDEX($L$5:$R$5,1,7-T9),"") | T9: =IF(ISNUMBER(K9),IF(L9,6,IF(M9,5,IF(N9,4,IF(O9,3,IF(P9,2,IF(Q9,1,0)))))),"") | U9: =IF(AND(ISNUMBER(T9),ISNUMBER(H9)),IF(AND(H9>=1,H9<=4,MOD(H9,1)=0),T9*10+H9,""),"")
B10: 2.4 | C10: Concevoir les services avec leurs utilisateurs et utilisatrices, en se concentrant sur leurs besoins réels. | J10: =S10 | K10: =IF(IF(ISNUMBER(E10),AND(E10>=0,E10<=3,MOD(E10,1)=0),FALSE),IF(E10=0,0,IF(IF(ISNUMBER(F10),AND(F10>=1,F10<=4,MOD(F10,1)=0),FALSE),E10*10+F10,"")),"") | L10: =IF(ISNUMBER(K10),K10=31,FALSE) -> FALSE | M10: =IF(ISNUMBER(K10),OR(K10=21,K10=32),FALSE) -> FALSE | N10: =IF(ISNUMBER(K10),OR(K10=22,K10=33),FALSE) -> FALSE | O10: =IF(ISNUMBER(K10),OR(K10=11,K10=12),FALSE) -> FALSE | P10: =IF(ISNUMBER(K10),OR(K10=23,K10=34),FALSE) -> FALSE | Q10: =IF(ISNUMBER(K10),OR(K10=13,K10=14,K10=24),FALSE) -> FALSE | R10: =IF(ISNUMBER(K10),K10=0,FALSE) -> FALSE | S10: =IF(ISNUMBER(T10),INDEX($L$5:$R$5,1,7-T10),"") | T10: =IF(ISNUMBER(K10),IF(L10,6,IF(M10,5,IF(N10,4,IF(O10,3,IF(P10,2,IF(Q10,1,0)))))),"") | U10: =IF(AND(ISNUMBER(T10),ISNUMBER(H10)),IF(AND(H10>=1,H10<=4,MOD(H10,1)=0),T10*10+H10,""),"")
B11: 2.5 | C11: Vérifier que l’intelligence artificielle ne discrimine personne et que ses services peuvent être utilisés par toutes et tous. | J11: =S11 -> 0 | K11: =IF(IF(ISNUMBER(E11),AND(E11>=0,E11<=3,MOD(E11,1)=0),FALSE),IF(E11=0,0,IF(IF(ISNUMBER(F11),AND(F11>=1,F11<=4,MOD(F11,1)=0),FALSE),E11*10+F11,"")),"") | L11: =IF(ISNUMBER(K11),K11=31,FALSE) -> FALSE | M11: =IF(ISNUMBER(K11),OR(K11=21,K11=32),FALSE) -> FALSE | N11: =IF(ISNUMBER(K11),OR(K11=22,K11=33),FALSE) -> FALSE | O11: =IF(ISNUMBER(K11),OR(K11=11,K11=12),FALSE) -> FALSE | P11: =IF(ISNUMBER(K11),OR(K11=23,K11=34),FALSE) -> FALSE | Q11: =IF(ISNUMBER(K11),OR(K11=13,K11=14,K11=24),FALSE) -> FALSE | R11: =IF(ISNUMBER(K11),K11=0,FALSE) -> FALSE | S11: =IF(ISNUMBER(T11),INDEX($L$5:$R$5,1,7-T11),"") | T11: =IF(ISNUMBER(K11),IF(L11,6,IF(M11,5,IF(N11,4,IF(O11,3,IF(P11,2,IF(Q11,1,0)))))),"") | U11: =IF(AND(ISNUMBER(T11),ISNUMBER(H11)),IF(AND(H11>=1,H11<=4,MOD(H11,1)=0),T11*10+H11,""),"")

Sheet ONR 3
L1: 0 | M1: 1 | N1: 2 | O1: 3 | P1: 4 | Q1: 5
B2: ONR 3 : RSE · Utiliser le numérique de façon éthique et responsable
B4: Cibles à évaluer | D4: Importance de la cible | F4: Performance actuelle | H4: Compétences internes et externes | J4: Priorité | V4: Mise en œuvre
D5: Avantages possibles et risques | E5: Importance | F5: Niveau actuel | G5: Ce qui est déjà fait et ce qui justifie la note | H5: Compétences nécessaires | I5: Points forts et points faibles | J5: Niveau de priorité | K5: Clé de priorisation | L5: Intervention urgente | M5: Intervention prioritaire | N5: Intervention à moyen terme | O5: Intervention à long terme | P5: Intervention de consolidation | Q5: Intervention non prioritaire | R5: Intervention non pertinente | S5: Libellé de priorité | T5: Score de priorité | U5: Code priorité et compétences | V5: Actions proposées pour atteindre la cible
B6: Renseigner les cellules jaunes pour les notes, puis les textes utiles. La priorité se calcule automatiquement. Faire défiler vers la droite pour proposer des actions.
B7: 3.1 | C7: Utiliser les données et les services numériques avec mesure, en respectant les personnes et l’environnement. | J7: =S7 | K7: =IF(IF(ISNUMBER(E7),AND(E7>=0,E7<=3,MOD(E7,1)=0),FALSE),IF(E7=0,0,IF(IF(ISNUMBER(F7),AND(F7>=1,F7<=4,MOD(F7,1)=0),FALSE),E7*10+F7,"")),"") | L7: =IF(ISNUMBER(K7),K7=31,FALSE) -> FALSE | M7: =IF(ISNUMBER(K7),OR(K7=21,K7=32),FALSE) -> FALSE | N7: =IF(ISNUMBER(K7),OR(K7=22,K7=33),FALSE) -> FALSE | O7: =IF(ISNUMBER(K7),OR(K7=11,K7=12),FALSE) -> FALSE | P7: =IF(ISNUMBER(K7),OR(K7=23,K7=34),FALSE) -> FALSE | Q7: =IF(ISNUMBER(K7),OR(K7=13,K7=14,K7=24),FALSE) -> FALSE | R7: =IF(ISNUMBER(K7),K7=0,FALSE) -> FALSE | S7: =IF(ISNUMBER(T7),INDEX($L$5:$R$5,1,7-T7),"") | T7: =IF(ISNUMBER(K7),IF(L7,6,IF(M7,5,IF(N7,4,IF(O7,3,IF(P7,2,IF(Q7,1,0)))))),"") | U7: =IF(AND(ISNUMBER(T7),ISNUMBER(H7)),IF(AND(H7>=1,H7<=4,MOD(H7,1)=0),T7*10+H7,""),"")
B8: 3.2 | C8: Supprimer les pratiques et les interfaces qui trompent les utilisateurs sur les sites web, aussi appelées « dark patterns ». Respecter la réglementation. | J8: =S8 | K8: =IF(IF(ISNUMBER(E8),AND(E8>=0,E8<=3,MOD(E8,1)=0),FALSE),IF(E8=0,0,IF(IF(ISNUMBER(F8),AND(F8>=1,F8<=4,MOD(F8,1)=0),FALSE),E8*10+F8,"")),"") | L8: =IF(ISNUMBER(K8),K8=31,FALSE) -> FALSE | M8: =IF(ISNUMBER(K8),OR(K8=21,K8=32),FALSE) -> FALSE | N8: =IF(ISNUMBER(K8),OR(K8=22,K8=33),FALSE) -> FALSE | O8: =IF(ISNUMBER(K8),OR(K8=11,K8=12),FALSE) -> FALSE | P8: =IF(ISNUMBER(K8),OR(K8=23,K8=34),FALSE) -> FALSE | Q8: =IF(ISNUMBER(K8),OR(K8=13,K8=14,K8=24),FALSE) -> FALSE | R8: =IF(ISNUMBER(K8),K8=0,FALSE) -> FALSE | S8: =IF(ISNUMBER(T8),INDEX($L$5:$R$5,1,7-T8),"") | T8: =IF(ISNUMBER(K8),IF(L8,6,IF(M8,5,IF(N8,4,IF(O8,3,IF(P8,2,IF(Q8,1,0)))))),"") | U8: =IF(AND(ISNUMBER(T8),ISNUMBER(H8)),IF(AND(H8>=1,H8<=4,MOD(H8,1)=0),T8*10+H8,""),"")
B9: 3.3 | C9: Collecter seulement les données nécessaires au service rendu. Protéger la vie privée, réduire les effets sur l’environnement et respecter le RGPD, le règlement sur la protection des données personnelles. | J9: =S9 | K9: =IF(IF(ISNUMBER(E9),AND(E9>=0,E9<=3,MOD(E9,1)=0),FALSE),IF(E9=0,0,IF(IF(ISNUMBER(F9),AND(F9>=1,F9<=4,MOD(F9,1)=0),FALSE),E9*10+F9,"")),"") | L9: =IF(ISNUMBER(K9),K9=31,FALSE) -> FALSE | M9: =IF(ISNUMBER(K9),OR(K9=21,K9=32),FALSE) -> FALSE | N9: =IF(ISNUMBER(K9),OR(K9=22,K9=33),FALSE) -> FALSE | O9: =IF(ISNUMBER(K9),OR(K9=11,K9=12),FALSE) -> FALSE | P9: =IF(ISNUMBER(K9),OR(K9=23,K9=34),FALSE) -> FALSE | Q9: =IF(ISNUMBER(K9),OR(K9=13,K9=14,K9=24),FALSE) -> FALSE | R9: =IF(ISNUMBER(K9),K9=0,FALSE) -> FALSE | S9: =IF(ISNUMBER(T9),INDEX($L$5:$R$5,1,7-T9),"") | T9: =IF(ISNUMBER(K9),IF(L9,6,IF(M9,5,IF(N9,4,IF(O9,3,IF(P9,2,IF(Q9,1,0)))))),"") | U9: =IF(AND(ISNUMBER(T9),ISNUMBER(H9)),IF(AND(H9>=1,H9<=4,MOD(H9,1)=0),T9*10+H9,""),"")
B10: 3.4 | C10: Recruter des personnes aux profils variés dans les métiers du numérique. | J10: =S10 | K10: =IF(IF(ISNUMBER(E10),AND(E10>=0,E10<=3,MOD(E10,1)=0),FALSE),IF(E10=0,0,IF(IF(ISNUMBER(F10),AND(F10>=1,F10<=4,MOD(F10,1)=0),FALSE),E10*10+F10,"")),"") | L10: =IF(ISNUMBER(K10),K10=31,FALSE) -> FALSE | M10: =IF(ISNUMBER(K10),OR(K10=21,K10=32),FALSE) -> FALSE | N10: =IF(ISNUMBER(K10),OR(K10=22,K10=33),FALSE) -> FALSE | O10: =IF(ISNUMBER(K10),OR(K10=11,K10=12),FALSE) -> FALSE | P10: =IF(ISNUMBER(K10),OR(K10=23,K10=34),FALSE) -> FALSE | Q10: =IF(ISNUMBER(K10),OR(K10=13,K10=14,K10=24),FALSE) -> FALSE | R10: =IF(ISNUMBER(K10),K10=0,FALSE) -> FALSE | S10: =IF(ISNUMBER(T10),INDEX($L$5:$R$5,1,7-T10),"") | T10: =IF(ISNUMBER(K10),IF(L10,6,IF(M10,5,IF(N10,4,IF(O10,3,IF(P10,2,IF(Q10,1,0)))))),"") | U10: =IF(AND(ISNUMBER(T10),ISNUMBER(H10)),IF(AND(H10>=1,H10<=4,MOD(H10,1)=0),T10*10+H10,""),"")
B11: 3.5 | C11: Améliorer les conditions de travail des personnes qui travaillent dans le numérique. | J11: =S11 | K11: =IF(IF(ISNUMBER(E11),AND(E11>=0,E11<=3,MOD(E11,1)=0),FALSE),IF(E11=0,0,IF(IF(ISNUMBER(F11),AND(F11>=1,F11<=4,MOD(F11,1)=0),FALSE),E11*10+F11,"")),"") | L11: =IF(ISNUMBER(K11),K11=31,FALSE) -> FALSE | M11: =IF(ISNUMBER(K11),OR(K11=21,K11=32),FALSE) -> FALSE | N11: =IF(ISNUMBER(K11),OR(K11=22,K11=33),FALSE) -> FALSE | O11: =IF(ISNUMBER(K11),OR(K11=11,K11=12),FALSE) -> FALSE | P11: =IF(ISNUMBER(K11),OR(K11=23,K11=34),FALSE) -> FALSE | Q11: =IF(ISNUMBER(K11),OR(K11=13,K11=14,K11=24),FALSE) -> FALSE | R11: =IF(ISNUMBER(K11),K11=0,FALSE) -> FALSE | S11: =IF(ISNUMBER(T11),INDEX($L$5:$R$5,1,7-T11),"") | T11: =IF(ISNUMBER(K11),IF(L11,6,IF(M11,5,IF(N11,4,IF(O11,3,IF(P11,2,IF(Q11,1,0)))))),"") | U11: =IF(AND(ISNUMBER(T11),ISNUMBER(H11)),IF(AND(H11>=1,H11<=4,MOD(H11,1)=0),T11*10+H11,""),"")
B12: 3.6 | C12: Fixer et appliquer des règles éthiques pour utiliser les algorithmes, en particulier l’intelligence artificielle. Encadrer l’utilisation des données et assurer leur protection. | J12: =S12 | K12: =IF(IF(ISNUMBER(E12),AND(E12>=0,E12<=3,MOD(E12,1)=0),FALSE),IF(E12=0,0,IF(IF(ISNUMBER(F12),AND(F12>=1,F12<=4,MOD(F12,1)=0),FALSE),E12*10+F12,"")),"") | L12: =IF(ISNUMBER(K12),K12=31,FALSE) -> FALSE | M12: =IF(ISNUMBER(K12),OR(K12=21,K12=32),FALSE) -> FALSE | N12: =IF(ISNUMBER(K12),OR(K12=22,K12=33),FALSE) -> FALSE | O12: =IF(ISNUMBER(K12),OR(K12=11,K12=12),FALSE) -> FALSE | P12: =IF(ISNUMBER(K12),OR(K12=23,K12=34),FALSE) -> FALSE | Q12: =IF(ISNUMBER(K12),OR(K12=13,K12=14,K12=24),FALSE) -> FALSE | R12: =IF(ISNUMBER(K12),K12=0,FALSE) -> FALSE | S12: =IF(ISNUMBER(T12),INDEX($L$5:$R$5,1,7-T12),"") | T12: =IF(ISNUMBER(K12),IF(L12,6,IF(M12,5,IF(N12,4,IF(O12,3,IF(P12,2,IF(Q12,1,0)))))),"") | U12: =IF(AND(ISNUMBER(T12),ISNUMBER(H12)),IF(AND(H12>=1,H12<=4,MOD(H12,1)=0),T12*10+H12,""),"")
B13: 3.7 | C13: Mettre en place et faire connaître les actions de responsabilité sociétale (RSE), qui prennent en compte les effets de l’organisation sur la société et l’environnement. | J13: =S13 | K13: =IF(IF(ISNUMBER(E13),AND(E13>=0,E13<=3,MOD(E13,1)=0),FALSE),IF(E13=0,0,IF(IF(ISNUMBER(F13),AND(F13>=1,F13<=4,MOD(F13,1)=0),FALSE),E13*10+F13,"")),"") | L13: =IF(ISNUMBER(K13),K13=31,FALSE) -> FALSE | M13: =IF(ISNUMBER(K13),OR(K13=21,K13=32),FALSE) -> FALSE | N13: =IF(ISNUMBER(K13),OR(K13=22,K13=33),FALSE) -> FALSE | O13: =IF(ISNUMBER(K13),OR(K13=11,K13=12),FALSE) -> FALSE | P13: =IF(ISNUMBER(K13),OR(K13=23,K13=34),FALSE) -> FALSE | Q13: =IF(ISNUMBER(K13),OR(K13=13,K13=14,K13=24),FALSE) -> FALSE | R13: =IF(ISNUMBER(K13),K13=0,FALSE) -> FALSE | S13: =IF(ISNUMBER(T13),INDEX($L$5:$R$5,1,7-T13),"") | T13: =IF(ISNUMBER(K13),IF(L13,6,IF(M13,5,IF(N13,4,IF(O13,3,IF(P13,2,IF(Q13,1,0)))))),"") | U13: =IF(AND(ISNUMBER(T13),ISNUMBER(H13)),IF(AND(H13>=1,H13<=4,MOD(H13,1)=0),T13*10+H13,""),"")
B14: 3.8 | C14: Indiquer quand une intelligence artificielle répond et expliquer comment elle prend ses décisions. Garder un contrôle humain sur les sujets sensibles. | J14: =S14 -> 0 | K14: =IF(IF(ISNUMBER(E14),AND(E14>=0,E14<=3,MOD(E14,1)=0),FALSE),IF(E14=0,0,IF(IF(ISNUMBER(F14),AND(F14>=1,F14<=4,MOD(F14,1)=0),FALSE),E14*10+F14,"")),"") | L14: =IF(ISNUMBER(K14),K14=31,FALSE) -> FALSE | M14: =IF(ISNUMBER(K14),OR(K14=21,K14=32),FALSE) -> FALSE | N14: =IF(ISNUMBER(K14),OR(K14=22,K14=33),FALSE) -> FALSE | O14: =IF(ISNUMBER(K14),OR(K14=11,K14=12),FALSE) -> FALSE | P14: =IF(ISNUMBER(K14),OR(K14=23,K14=34),FALSE) -> FALSE | Q14: =IF(ISNUMBER(K14),OR(K14=13,K14=14,K14=24),FALSE) -> FALSE | R14: =IF(ISNUMBER(K14),K14=0,FALSE) -> FALSE | S14: =IF(ISNUMBER(T14),INDEX($L$5:$R$5,1,7-T14),"") | T14: =IF(ISNUMBER(K14),IF(L14,6,IF(M14,5,IF(N14,4,IF(O14,3,IF(P14,2,IF(Q14,1,0)))))),"") | U14: =IF(AND(ISNUMBER(T14),ISNUMBER(H14)),IF(AND(H14>=1,H14<=4,MOD(H14,1)=0),T14*10+H14,""),"")

Sheet ONR 4
L1: 0 | M1: 1 | N1: 2 | O1: 3 | P1: 4 | Q1: 5
B2: ONR 4 : Résilience et stratégie · Utiliser le numérique responsable pour aider l’organisation à faire face aux difficultés et à s’adapter
B4: Cibles à évaluer | D4: Importance de la cible | F4: Performance actuelle | H4: Compétences internes et externes | J4: Priorité | V4: Mise en œuvre
D5: Avantages possibles et risques | E5: Importance | F5: Niveau actuel | G5: Ce qui est déjà fait et ce qui justifie la note | H5: Compétences nécessaires | I5: Points forts et points faibles | J5: Niveau de priorité | K5: Clé de priorisation | L5: Intervention urgente | M5: Intervention prioritaire | N5: Intervention à moyen terme | O5: Intervention à long terme | P5: Intervention de consolidation | Q5: Intervention non prioritaire | R5: Intervention non pertinente | S5: Libellé de priorité | T5: Score de priorité | U5: Code priorité et compétences | V5: Actions proposées pour atteindre la cible
B6: Renseigner les cellules jaunes pour les notes, puis les textes utiles. La priorité se calcule automatiquement. Faire défiler vers la droite pour proposer des actions.
B7: 4.1 | C7: Suivre des normes communes pour recueillir, regrouper, analyser et partager les données sur les effets des technologies de l’information et de la communication (TIC). | J7: =S7 | K7: =IF(IF(ISNUMBER(E7),AND(E7>=0,E7<=3,MOD(E7,1)=0),FALSE),IF(E7=0,0,IF(IF(ISNUMBER(F7),AND(F7>=1,F7<=4,MOD(F7,1)=0),FALSE),E7*10+F7,"")),"") | L7: =IF(ISNUMBER(K7),K7=31,FALSE) -> FALSE | M7: =IF(ISNUMBER(K7),OR(K7=21,K7=32),FALSE) -> FALSE | N7: =IF(ISNUMBER(K7),OR(K7=22,K7=33),FALSE) -> FALSE | O7: =IF(ISNUMBER(K7),OR(K7=11,K7=12),FALSE) -> FALSE | P7: =IF(ISNUMBER(K7),OR(K7=23,K7=34),FALSE) -> FALSE | Q7: =IF(ISNUMBER(K7),OR(K7=13,K7=14,K7=24),FALSE) -> FALSE | R7: =IF(ISNUMBER(K7),K7=0,FALSE) -> FALSE | S7: =IF(ISNUMBER(T7),INDEX($L$5:$R$5,1,7-T7),"") | T7: =IF(ISNUMBER(K7),IF(L7,6,IF(M7,5,IF(N7,4,IF(O7,3,IF(P7,2,IF(Q7,1,0)))))),"") | U7: =IF(AND(ISNUMBER(T7),ISNUMBER(H7)),IF(AND(H7>=1,H7<=4,MOD(H7,1)=0),T7*10+H7,""),"")
B8: 4.2 | C8: Évaluer les services numériques au fil du temps et partager les résultats. | J8: =S8 | K8: =IF(IF(ISNUMBER(E8),AND(E8>=0,E8<=3,MOD(E8,1)=0),FALSE),IF(E8=0,0,IF(IF(ISNUMBER(F8),AND(F8>=1,F8<=4,MOD(F8,1)=0),FALSE),E8*10+F8,"")),"") | L8: =IF(ISNUMBER(K8),K8=31,FALSE) -> FALSE | M8: =IF(ISNUMBER(K8),OR(K8=21,K8=32),FALSE) -> FALSE | N8: =IF(ISNUMBER(K8),OR(K8=22,K8=33),FALSE) -> FALSE | O8: =IF(ISNUMBER(K8),OR(K8=11,K8=12),FALSE) -> FALSE | P8: =IF(ISNUMBER(K8),OR(K8=23,K8=34),FALSE) -> FALSE | Q8: =IF(ISNUMBER(K8),OR(K8=13,K8=14,K8=24),FALSE) -> FALSE | R8: =IF(ISNUMBER(K8),K8=0,FALSE) -> FALSE | S8: =IF(ISNUMBER(T8),INDEX($L$5:$R$5,1,7-T8),"") | T8: =IF(ISNUMBER(K8),IF(L8,6,IF(M8,5,IF(N8,4,IF(O8,3,IF(P8,2,IF(Q8,1,0)))))),"") | U8: =IF(AND(ISNUMBER(T8),ISNUMBER(H8)),IF(AND(H8>=1,H8<=4,MOD(H8,1)=0),T8*10+H8,""),"")
B9: 4.3 | C9: Innover en utilisant de nouveaux outils numériques. Évaluer leurs effets et expliquer les résultats aux personnes qui les utilisent. | J9: =S9 | K9: =IF(IF(ISNUMBER(E9),AND(E9>=0,E9<=3,MOD(E9,1)=0),FALSE),IF(E9=0,0,IF(IF(ISNUMBER(F9),AND(F9>=1,F9<=4,MOD(F9,1)=0),FALSE),E9*10+F9,"")),"") | L9: =IF(ISNUMBER(K9),K9=31,FALSE) -> FALSE | M9: =IF(ISNUMBER(K9),OR(K9=21,K9=32),FALSE) -> FALSE | N9: =IF(ISNUMBER(K9),OR(K9=22,K9=33),FALSE) -> FALSE | O9: =IF(ISNUMBER(K9),OR(K9=11,K9=12),FALSE) -> FALSE | P9: =IF(ISNUMBER(K9),OR(K9=23,K9=34),FALSE) -> FALSE | Q9: =IF(ISNUMBER(K9),OR(K9=13,K9=14,K9=24),FALSE) -> FALSE | R9: =IF(ISNUMBER(K9),K9=0,FALSE) -> FALSE | S9: =IF(ISNUMBER(T9),INDEX($L$5:$R$5,1,7-T9),"") | T9: =IF(ISNUMBER(K9),IF(L9,6,IF(M9,5,IF(N9,4,IF(O9,3,IF(P9,2,IF(Q9,1,0)))))),"") | U9: =IF(AND(ISNUMBER(T9),ISNUMBER(H9)),IF(AND(H9>=1,H9<=4,MOD(H9,1)=0),T9*10+H9,""),"")
B10: 4.4 | C10: Renforcer la souveraineté numérique : garder la maîtrise de nos choix, de nos outils et de nos données. | J10: =S10 -> 0 | K10: =IF(IF(ISNUMBER(E10),AND(E10>=0,E10<=3,MOD(E10,1)=0),FALSE),IF(E10=0,0,IF(IF(ISNUMBER(F10),AND(F10>=1,F10<=4,MOD(F10,1)=0),FALSE),E10*10+F10,"")),"") | L10: =IF(ISNUMBER(K10),K10=31,FALSE) -> FALSE | M10: =IF(ISNUMBER(K10),OR(K10=21,K10=32),FALSE) -> FALSE | N10: =IF(ISNUMBER(K10),OR(K10=22,K10=33),FALSE) -> FALSE | O10: =IF(ISNUMBER(K10),OR(K10=11,K10=12),FALSE) -> FALSE | P10: =IF(ISNUMBER(K10),OR(K10=23,K10=34),FALSE) -> FALSE | Q10: =IF(ISNUMBER(K10),OR(K10=13,K10=14,K10=24),FALSE) -> FALSE | R10: =IF(ISNUMBER(K10),K10=0,FALSE) -> FALSE | S10: =IF(ISNUMBER(T10),INDEX($L$5:$R$5,1,7-T10),"") | T10: =IF(ISNUMBER(K10),IF(L10,6,IF(M10,5,IF(N10,4,IF(O10,3,IF(P10,2,IF(Q10,1,0)))))),"") | U10: =IF(AND(ISNUMBER(T10),ISNUMBER(H10)),IF(AND(H10>=1,H10<=4,MOD(H10,1)=0),T10*10+H10,""),"")

Sheet ONR 5
L1: 0 | M1: 1 | N1: 2 | O1: 3 | P1: 4 | Q1: 5
B2: ONR 5 : Management · Donner du sens au travail et préserver les personnes et les ressources nécessaires à nos activités
B4: Cibles à évaluer | D4: Importance de la cible | F4: Performance actuelle | H4: Compétences internes et externes | J4: Priorité | V4: Mise en œuvre
D5: Avantages possibles et risques | E5: Importance | F5: Niveau actuel | G5: Ce qui est déjà fait et ce qui justifie la note | H5: Compétences nécessaires | I5: Points forts et points faibles | J5: Niveau de priorité | K5: Clé de priorisation | L5: Intervention urgente | M5: Intervention prioritaire | N5: Intervention à moyen terme | O5: Intervention à long terme | P5: Intervention de consolidation | Q5: Intervention non prioritaire | R5: Intervention non pertinente | S5: Libellé de priorité | T5: Score de priorité | U5: Code priorité et compétences | V5: Actions proposées pour atteindre la cible
B6: Renseigner les cellules jaunes pour les notes, puis les textes utiles. La priorité se calcule automatiquement. Faire défiler vers la droite pour proposer des actions.
B7: 5.1 | C7: Concevoir les systèmes et les services numériques en intégrant de nouvelles façons de répondre aux besoins sociaux. | J7: =S7 | K7: =IF(IF(ISNUMBER(E7),AND(E7>=0,E7<=3,MOD(E7,1)=0),FALSE),IF(E7=0,0,IF(IF(ISNUMBER(F7),AND(F7>=1,F7<=4,MOD(F7,1)=0),FALSE),E7*10+F7,"")),"") | L7: =IF(ISNUMBER(K7),K7=31,FALSE) -> FALSE | M7: =IF(ISNUMBER(K7),OR(K7=21,K7=32),FALSE) -> FALSE | N7: =IF(ISNUMBER(K7),OR(K7=22,K7=33),FALSE) -> FALSE | O7: =IF(ISNUMBER(K7),OR(K7=11,K7=12),FALSE) -> FALSE | P7: =IF(ISNUMBER(K7),OR(K7=23,K7=34),FALSE) -> FALSE | Q7: =IF(ISNUMBER(K7),OR(K7=13,K7=14,K7=24),FALSE) -> FALSE | R7: =IF(ISNUMBER(K7),K7=0,FALSE) -> FALSE | S7: =IF(ISNUMBER(T7),INDEX($L$5:$R$5,1,7-T7),"") | T7: =IF(ISNUMBER(K7),IF(L7,6,IF(M7,5,IF(N7,4,IF(O7,3,IF(P7,2,IF(Q7,1,0)))))),"") | U7: =IF(AND(ISNUMBER(T7),ISNUMBER(H7)),IF(AND(H7>=1,H7<=4,MOD(H7,1)=0),T7*10+H7,""),"")
B8: 5.2 | C8: Faire connaître et soutenir les initiatives des équipes qui encouragent l’engagement, la coopération entre services et le bien-être au travail. | J8: =S8 | K8: =IF(IF(ISNUMBER(E8),AND(E8>=0,E8<=3,MOD(E8,1)=0),FALSE),IF(E8=0,0,IF(IF(ISNUMBER(F8),AND(F8>=1,F8<=4,MOD(F8,1)=0),FALSE),E8*10+F8,"")),"") | L8: =IF(ISNUMBER(K8),K8=31,FALSE) -> FALSE | M8: =IF(ISNUMBER(K8),OR(K8=21,K8=32),FALSE) -> FALSE | N8: =IF(ISNUMBER(K8),OR(K8=22,K8=33),FALSE) -> FALSE | O8: =IF(ISNUMBER(K8),OR(K8=11,K8=12),FALSE) -> FALSE | P8: =IF(ISNUMBER(K8),OR(K8=23,K8=34),FALSE) -> FALSE | Q8: =IF(ISNUMBER(K8),OR(K8=13,K8=14,K8=24),FALSE) -> FALSE | R8: =IF(ISNUMBER(K8),K8=0,FALSE) -> FALSE | S8: =IF(ISNUMBER(T8),INDEX($L$5:$R$5,1,7-T8),"") | T8: =IF(ISNUMBER(K8),IF(L8,6,IF(M8,5,IF(N8,4,IF(O8,3,IF(P8,2,IF(Q8,1,0)))))),"") | U8: =IF(AND(ISNUMBER(T8),ISNUMBER(H8)),IF(AND(H8>=1,H8<=4,MOD(H8,1)=0),T8*10+H8,""),"")
B9: 5.3 | C9: Faire participer les personnes et les organisations concernées. S’appuyer sur leurs connaissances des questions d’environnement, de conditions de vie et de société. | J9: =S9 | K9: =IF(IF(ISNUMBER(E9),AND(E9>=0,E9<=3,MOD(E9,1)=0),FALSE),IF(E9=0,0,IF(IF(ISNUMBER(F9),AND(F9>=1,F9<=4,MOD(F9,1)=0),FALSE),E9*10+F9,"")),"") | L9: =IF(ISNUMBER(K9),K9=31,FALSE) -> FALSE | M9: =IF(ISNUMBER(K9),OR(K9=21,K9=32),FALSE) -> FALSE | N9: =IF(ISNUMBER(K9),OR(K9=22,K9=33),FALSE) -> FALSE | O9: =IF(ISNUMBER(K9),OR(K9=11,K9=12),FALSE) -> FALSE | P9: =IF(ISNUMBER(K9),OR(K9=23,K9=34),FALSE) -> FALSE | Q9: =IF(ISNUMBER(K9),OR(K9=13,K9=14,K9=24),FALSE) -> FALSE | R9: =IF(ISNUMBER(K9),K9=0,FALSE) -> FALSE | S9: =IF(ISNUMBER(T9),INDEX($L$5:$R$5,1,7-T9),"") | T9: =IF(ISNUMBER(K9),IF(L9,6,IF(M9,5,IF(N9,4,IF(O9,3,IF(P9,2,IF(Q9,1,0)))))),"") | U9: =IF(AND(ISNUMBER(T9),ISNUMBER(H9)),IF(AND(H9>=1,H9<=4,MOD(H9,1)=0),T9*10+H9,""),"")
B10: 5.4 | C10: Permettre aux générations futures d’innover pour mieux vivre ensemble, s’ouvrir aux autres et préserver l’équilibre de la nature. | J10: =S10 | K10: =IF(IF(ISNUMBER(E10),AND(E10>=0,E10<=3,MOD(E10,1)=0),FALSE),IF(E10=0,0,IF(IF(ISNUMBER(F10),AND(F10>=1,F10<=4,MOD(F10,1)=0),FALSE),E10*10+F10,"")),"") | L10: =IF(ISNUMBER(K10),K10=31,FALSE) -> FALSE | M10: =IF(ISNUMBER(K10),OR(K10=21,K10=32),FALSE) -> FALSE | N10: =IF(ISNUMBER(K10),OR(K10=22,K10=33),FALSE) -> FALSE | O10: =IF(ISNUMBER(K10),OR(K10=11,K10=12),FALSE) -> FALSE | P10: =IF(ISNUMBER(K10),OR(K10=23,K10=34),FALSE) -> FALSE | Q10: =IF(ISNUMBER(K10),OR(K10=13,K10=14,K10=24),FALSE) -> FALSE | R10: =IF(ISNUMBER(K10),K10=0,FALSE) -> FALSE | S10: =IF(ISNUMBER(T10),INDEX($L$5:$R$5,1,7-T10),"") | T10: =IF(ISNUMBER(K10),IF(L10,6,IF(M10,5,IF(N10,4,IF(O10,3,IF(P10,2,IF(Q10,1,0)))))),"") | U10: =IF(AND(ISNUMBER(T10),ISNUMBER(H10)),IF(AND(H10>=1,H10<=4,MOD(H10,1)=0),T10*10+H10,""),"")
B11: 5.5 | C11: Suivre les résultats obtenus et le respect des règles à l’aide d’indicateurs. | J11: =S11 | K11: =IF(IF(ISNUMBER(E11),AND(E11>=0,E11<=3,MOD(E11,1)=0),FALSE),IF(E11=0,0,IF(IF(ISNUMBER(F11),AND(F11>=1,F11<=4,MOD(F11,1)=0),FALSE),E11*10+F11,"")),"") | L11: =IF(ISNUMBER(K11),K11=31,FALSE) -> FALSE | M11: =IF(ISNUMBER(K11),OR(K11=21,K11=32),FALSE) -> FALSE | N11: =IF(ISNUMBER(K11),OR(K11=22,K11=33),FALSE) -> FALSE | O11: =IF(ISNUMBER(K11),OR(K11=11,K11=12),FALSE) -> FALSE | P11: =IF(ISNUMBER(K11),OR(K11=23,K11=34),FALSE) -> FALSE | Q11: =IF(ISNUMBER(K11),OR(K11=13,K11=14,K11=24),FALSE) -> FALSE | R11: =IF(ISNUMBER(K11),K11=0,FALSE) -> FALSE | S11: =IF(ISNUMBER(T11),INDEX($L$5:$R$5,1,7-T11),"") | T11: =IF(ISNUMBER(K11),IF(L11,6,IF(M11,5,IF(N11,4,IF(O11,3,IF(P11,2,IF(Q11,1,0)))))),"") | U11: =IF(AND(ISNUMBER(T11),ISNUMBER(H11)),IF(AND(H11>=1,H11<=4,MOD(H11,1)=0),T11*10+H11,""),"")
B12: 5.6 | C12: Proposer des améliorations et de nouvelles idées pour un numérique responsable, y compris des solutions sans outils numériques. | J12: =S12 | K12: =IF(IF(ISNUMBER(E12),AND(E12>=0,E12<=3,MOD(E12,1)=0),FALSE),IF(E12=0,0,IF(IF(ISNUMBER(F12),AND(F12>=1,F12<=4,MOD(F12,1)=0),FALSE),E12*10+F12,"")),"") | L12: =IF(ISNUMBER(K12),K12=31,FALSE) -> FALSE | M12: =IF(ISNUMBER(K12),OR(K12=21,K12=32),FALSE) -> FALSE | N12: =IF(ISNUMBER(K12),OR(K12=22,K12=33),FALSE) -> FALSE | O12: =IF(ISNUMBER(K12),OR(K12=11,K12=12),FALSE) -> FALSE | P12: =IF(ISNUMBER(K12),OR(K12=23,K12=34),FALSE) -> FALSE | Q12: =IF(ISNUMBER(K12),OR(K12=13,K12=14,K12=24),FALSE) -> FALSE | R12: =IF(ISNUMBER(K12),K12=0,FALSE) -> FALSE | S12: =IF(ISNUMBER(T12),INDEX($L$5:$R$5,1,7-T12),"") | T12: =IF(ISNUMBER(K12),IF(L12,6,IF(M12,5,IF(N12,4,IF(O12,3,IF(P12,2,IF(Q12,1,0)))))),"") | U12: =IF(AND(ISNUMBER(T12),ISNUMBER(H12)),IF(AND(H12>=1,H12<=4,MOD(H12,1)=0),T12*10+H12,""),"")
B13: 5.7 | C13: Décider avec les équipes comment utiliser l’intelligence artificielle. Les former à ses limites et préserver le sens de leur travail. | J13: =S13 -> 0 | K13: =IF(IF(ISNUMBER(E13),AND(E13>=0,E13<=3,MOD(E13,1)=0),FALSE),IF(E13=0,0,IF(IF(ISNUMBER(F13),AND(F13>=1,F13<=4,MOD(F13,1)=0),FALSE),E13*10+F13,"")),"") | L13: =IF(ISNUMBER(K13),K13=31,FALSE) -> FALSE | M13: =IF(ISNUMBER(K13),OR(K13=21,K13=32),FALSE) -> FALSE | N13: =IF(ISNUMBER(K13),OR(K13=22,K13=33),FALSE) -> FALSE | O13: =IF(ISNUMBER(K13),OR(K13=11,K13=12),FALSE) -> FALSE | P13: =IF(ISNUMBER(K13),OR(K13=23,K13=34),FALSE) -> FALSE | Q13: =IF(ISNUMBER(K13),OR(K13=13,K13=14,K13=24),FALSE) -> FALSE | R13: =IF(ISNUMBER(K13),K13=0,FALSE) -> FALSE | S13: =IF(ISNUMBER(T13),INDEX($L$5:$R$5,1,7-T13),"") | T13: =IF(ISNUMBER(K13),IF(L13,6,IF(M13,5,IF(N13,4,IF(O13,3,IF(P13,2,IF(Q13,1,0)))))),"") | U13: =IF(AND(ISNUMBER(T13),ISNUMBER(H13)),IF(AND(H13>=1,H13<=4,MOD(H13,1)=0),T13*10+H13,""),"")

Sheet Priorisation
B2: Tableau de priorisation des cibles
A4: Importance de la cible | B4: 3 | H4: Intervention urgente | I4: Intervention de consolidation
B5: 2 | H5: Intervention prioritaire | I5: Intervention non prioritaire
B6: 1 | H6: Intervention à moyen terme | I6: Intervention non pertinente
B7: 0 | H7: Intervention à long terme
C8: 1 | D8: 2 | E8: 3 | F8: 4
C9: État de la situation actuelle

Sheet Résultats détaillés
L1: 0 | M1: 1 | N1: 2 | O1: 3 | P1: 4 | Q1: 5
B2: Résultats détaillés | V2: Mise en œuvre des actions | Y2: Analyse des Forces, Faiblesses, Opportunités et Menaces (FFOM)
D3: Enjeux locaux associés à la cible | E3: ='ONR 1'!E5 -> Importance | F3: ='ONR 1'!F5 -> Niveau actuel | G3: ='ONR 1'!G5 -> Ce qui est déjà fait et ce qui justifie la note | H3: ='ONR 1'!H5 -> Compétences nécessaires | I3: ='ONR 1'!I5 -> Points forts et points faibles | J3: ='ONR 1'!J5 -> Niveau de priorité | K3: Valeur priorité | L3: Intervention urgente | M3: Intervention prioritaire | N3: Intervention à moyen terme | O3: Intervention à long terme | P3: Intervention de consolidation | Q3: Intervention non prioritaire | R3: Intervention non pertinente | S3: Priorité texte | T3: Priorité valeur | U3: Valeur type d'action | V3: Mesures et actions déjà en place | W3: Stratégies d'action pouvant contribuer à l'atteinte de la cible et proposées lors de l'analyse | X3: Synergies avec les Modules (M3 stratégie, M4 sensibiliser, M5 action) | Y3: Forces et faiblesses en regard de la cible | Z3: Opportunités et menaces en regard de la cible | AB3: ONR | AC3: Nombre de cibles | AD3: Nombre de cibles analysées | AE3: Cibles à évaluer | AF3: Nombre de cibles urgentes | AG3: Nombre de cibles prioritaires | AH3: Nombre de cibles à moyen terme | AI3: Nombre de cibles à long terme | AJ3: Nombre de cibles à consolider | AK3: Nombre de cibles non prioritaires | AL3: Cibles non applicables | AM3: Piste d’action renseignée
B4: ='ONR 1'!B2 -> ONR 1 : Sobriété · Utiliser les outils numériques pour consommer moins de ressources et réduire leurs effets sur l’environnement | AB4: =B4 -> ONR 1 : Sobriété · Utiliser les outils numériques pour consommer moins de ressources et réduire leurs effets sur l’environnement | AC4: =COUNTA('ONR 1'!B7:B14) -> 8 | AD4: =COUNT(T5:T12) -> 5 | AE4: =SUM(AE5:AE12) -> 3 | AF4: =SUM(AF5:AF12) -> 3 | AG4: =SUM(AG5:AG12) -> 1 | AH4: =SUM(AH5:AH12) -> 1 | AI4: =SUM(AI5:AI12) -> 0 | AJ4: =SUM(AJ5:AJ12) -> 0 | AK4: =SUM(AK5:AK12) -> 0 | AL4: =SUM(AL5:AL12) -> 0
B5: =IF(ISBLANK('ONR 1'!B7),"",'ONR 1'!B7) -> 1.1 | C5: =IF(ISBLANK('ONR 1'!C7),"",'ONR 1'!C7) -> Prendre en compte toutes les étapes de la vie des équipements et des logiciels, de leur création à leur fin de vie, pour contribuer à la transition énergétique. | D5: =IF(ISBLANK('ONR 1'!D7),"",'ONR 1'!D7) -> Avantages possibles : réduire les émissions de gaz à effet de serre de l’organisation et se préparer aux futures règles environnementales. Risque : payer plus cher à l’achat certains équipements conçus pour limiter leurs effets sur l’environnement. | E5: =IF(ISBLANK('ONR 1'!E7),"",'ONR 1'!E7) -> 3 | F5: =IF(ISBLANK('ONR 1'!F7),"",'ONR 1'!F7) -> 1 | G5: =IF(ISBLANK('ONR 1'!G7),"",'ONR 1'!G7) -> L’équipe Achats retient le prix d’achat comme seul critère de choix. Elle ne demande pas d’analyse du cycle de vie (ACV) aux fournisseurs dans les appels d’offres. | H5: =IF(ISBLANK('ONR 1'!H7),"",'ONR 1'!H7) -> 3 | I5: =IF(ISBLANK('ONR 1'!I7),"",'ONR 1'!I7) -> Point fort : la direction des achats souhaite adopter des pratiques plus durables. Point faible : l’équipe connaît peu les labels environnementaux des équipements informatiques. | ... U5: =IF(ISBLANK('ONR 1'!U7),"",'ONR 1'!U7) -> 63 | V5: =IF(ISBLANK('ONR 1'!G7),"",'ONR 1'!G7) -> L’équipe Achats retient le prix d’achat comme seul critère de choix. Elle ne demande pas d’analyse du cycle de vie (ACV) aux fournisseurs dans les appels d’offres. | W5: =IF(ISBLANK('ONR 1'!V7),"",'ONR 1'!V7) -> Former l’équipe Achats aux critères du numérique responsable et aux labels TCO et EPEAT. Dans les prochains appels d’offres pour remplacer les serveurs, faire compter les critères environnementaux pour 15 % de la note. | X5: =IF(ISBLANK('ONR 1'!W7),"",'ONR 1'!W7) | Y5: =IF(ISBLANK('ONR 1'!I7),"",'ONR 1'!I7) -> Point fort : la direction des achats souhaite adopter des pratiques plus durables. Point faible : l’équipe connaît peu les labels environnementaux des équipements informatiques. | Z5: =IF(ISBLANK('ONR 1'!D7),"",'ONR 1'!D7) -> Avantages possibles : réduire les émissions de gaz à effet de serre de l’organisation et se préparer aux futures règles environnementales. Risque : payer plus cher à l’achat certains équipements conçus pour limiter leurs effets sur l’environnement. | AE5: =IF(ISNUMBER(T5),0,1) -> 0 | AF5: =IF(L5=TRUE,1,0) -> 1 | AG5: =IF(M5=TRUE,1,0) -> 0 | AH5: =IF(N5=TRUE,1,0) -> 0 | AI5: =IF(O5=TRUE,1,0) -> 0 | AJ5: =IF(P5=TRUE,1,0) -> 0 | AK5: =IF(Q5=TRUE,1,0) -> 0 | AL5: =IF(R5=TRUE,1,0) -> 0 | AM5: =IF(LEN(TRIM(W5))>0,1,0) -> 1
B6: =IF(ISBLANK('ONR 1'!B8),"",'ONR 1'!B8) -> 1.2 | C6: =IF(ISBLANK('ONR 1'!C8),"",'ONR 1'!C8) -> Utiliser les équipements plus longtemps, même après la fin de leur amortissement, c’est-à-dire la période sur laquelle leur coût est réparti dans les comptes. | D6: =IF(ISBLANK('ONR 1'!D8),"",'ONR 1'!D8) -> Avantages possibles : réduire les dépenses d’achat de matériel et les déchets d’équipements électriques et électroniques (DEEE). | E6: =IF(ISBLANK('ONR 1'!E8),"",'ONR 1'!E8) -> 3 | F6: =IF(ISBLANK('ONR 1'!F8),"",'ONR 1'!F8) -> 3 | G6: =IF(ISBLANK('ONR 1'!G8),"",'ONR 1'!G8) -> L’organisation a porté la durée de renouvellement des ordinateurs portables de trois à quatre ans l’année dernière. Elle dispose d’un contrat de maintenance. | H6: =IF(ISBLANK('ONR 1'!H8),"",'ONR 1'!H8) -> 2 | I6: =IF(ISBLANK('ONR 1'!I8),"",'ONR 1'!I8) -> Point fort : l’équipe technique peut réparer les équipements en interne. Point faible : certains utilisateurs demandent du matériel neuf pour son apparence. | ... U6: =IF(ISBLANK('ONR 1'!U8),"",'ONR 1'!U8) -> 42 | V6: =IF(ISBLANK('ONR 1'!G8),"",'ONR 1'!G8) -> L’organisation a porté la durée de renouvellement des ordinateurs portables de trois à quatre ans l’année dernière. Elle dispose d’un contrat de maintenance. | W6: =IF(ISBLANK('ONR 1'!V8),"",'ONR 1'!V8) -> Répartir le coût des équipements dans les comptes sur cinq ans au minimum : c’est la durée d’amortissement. Prévoir un stock de pièces détachées pour faciliter les réparations. Expliquer aux équipes comment garder leur ordinateur plus longtemps permet d’éviter des émissions de gaz à effet de serre. | X6: =IF(ISBLANK('ONR 1'!W8),"",'ONR 1'!W8) | Y6: =IF(ISBLANK('ONR 1'!I8),"",'ONR 1'!I8) -> Point fort : l’équipe technique peut réparer les équipements en interne. Point faible : certains utilisateurs demandent du matériel neuf pour son apparence. | Z6: =IF(ISBLANK('ONR 1'!D8),"",'ONR 1'!D8) -> Avantages possibles : réduire les dépenses d’achat de matériel et les déchets d’équipements électriques et électroniques (DEEE). | AE6: =IF(ISNUMBER(T6),0,1) -> 0 | AF6: =IF(L6=TRUE,1,0) -> 0 | AG6: =IF(M6=TRUE,1,0) -> 0 | AH6: =IF(N6=TRUE,1,0) -> 1 | AI6: =IF(O6=TRUE,1,0) -> 0 | AJ6: =IF(P6=TRUE,1,0) -> 0 | AK6: =IF(Q6=TRUE,1,0) -> 0 | AL6: =IF(R6=TRUE,1,0) -> 0 | AM6: =IF(LEN(TRIM(W6))>0,1,0) -> 1
B7: =IF(ISBLANK('ONR 1'!B9),"",'ONR 1'!B9) -> 1.3 | C7: =IF(ISBLANK('ONR 1'!C9),"",'ONR 1'!C9) -> Concevoir des services numériques qui limitent leurs effets sur l’environnement. Choisir des technologies qui contribuent aux Objectifs de développement durable (ODD). | D7: =IF(ISBLANK('ONR 1'!D9),"",'ONR 1'!D9) -> Avantages possibles : réduire les effets des services sur l’environnement dès leur conception, faciliter leur utilisation et contribuer aux Objectifs de développement durable (ODD). Risques : accumuler des problèmes techniques non résolus ou créer des logiciels trop gourmands en ressources, qui obligent à remplacer le matériel plus tôt. | E7: =IF(ISBLANK('ONR 1'!E9),"",'ONR 1'!E9) -> 3 | F7: =IF(ISBLANK('ONR 1'!F9),"",'ONR 1'!F9) -> 2 | G7: =IF(ISBLANK('ONR 1'!G9),"",'ONR 1'!G9) -> Les équipes valident les nouveaux services et sites web selon des critères fonctionnels, graphiques et financiers. Elles ne mesurent ni le poids des pages ni l’impact environnemental du code. | H7: =IF(ISBLANK('ONR 1'!H9),"",'ONR 1'!H9) -> 2 | I7: =IF(ISBLANK('ONR 1'!I9),"",'ONR 1'!I9) -> Point fort : les développeurs et les chefs de produit s’intéressent aux effets de leurs activités sur la société et l’environnement. Points faibles : ils connaissent peu les guides pour concevoir des services numériques moins polluants, comme le RGESN. Ils savent peu comment relier leurs projets aux ODD. | ... U7: =IF(ISBLANK('ONR 1'!U9),"",'ONR 1'!U9) -> 52 | V7: =IF(ISBLANK('ONR 1'!G9),"",'ONR 1'!G9) -> Les équipes valident les nouveaux services et sites web selon des critères fonctionnels, graphiques et financiers. Elles ne mesurent ni le poids des pages ni l’impact environnemental du code. | W7: =IF(ISBLANK('ONR 1'!V9),"",'ONR 1'!V9) -> 1. Former les équipes de conception, de développement et de gestion de projet à créer des services numériques qui limitent leurs effets sur l’environnement. 2. Ajouter des exigences environnementales aux cahiers des charges, comme limiter le poids des images et réduire les demandes envoyées aux serveurs. 3. Pour chaque nouveau projet, préciser à quels Objectifs de développement durable il contribue. | X7: =IF(ISBLANK('ONR 1'!W9),"",'ONR 1'!W9) | Y7: =IF(ISBLANK('ONR 1'!I9),"",'ONR 1'!I9) -> Point fort : les développeurs et les chefs de produit s’intéressent aux effets de leurs activités sur la société et l’environnement. Points faibles : ils connaissent peu les guides pour concevoir des services numériques moins polluants, comme le RGESN. Ils savent peu comment relier leurs projets aux ODD. | Z7: =IF(ISBLANK('ONR 1'!D9),"",'ONR 1'!D9) -> Avantages possibles : réduire les effets des services sur l’environnement dès leur conception, faciliter leur utilisation et contribuer aux Objectifs de développement durable (ODD). Risques : accumuler des problèmes techniques non résolus ou créer des logiciels trop gourmands en ressources, qui obligent à remplacer le matériel plus tôt. | AE7: =IF(ISNUMBER(T7),0,1) -> 0 | AF7: =IF(L7=TRUE,1,0) -> 0 | AG7: =IF(M7=TRUE,1,0) -> 1 | AH7: =IF(N7=TRUE,1,0) -> 0 | AI7: =IF(O7=TRUE,1,0) -> 0 | AJ7: =IF(P7=TRUE,1,0) -> 0 | AK7: =IF(Q7=TRUE,1,0) -> 0 | AL7: =IF(R7=TRUE,1,0) -> 0 | AM7: =IF(LEN(TRIM(W7))>0,1,0) -> 1
B8: =IF(ISBLANK('ONR 1'!B10),"",'ONR 1'!B10) -> 1.4 | C8: =IF(ISBLANK('ONR 1'!C10),"",'ONR 1'!C10) -> Adopter des pratiques qui consomment moins de matériel, de ressources, d’énergie et de consommables, comme le papier ou l’encre. | D8: =IF(ISBLANK('ONR 1'!D10),"",'ONR 1'!D10) | E8: =IF(ISBLANK('ONR 1'!E10),"",'ONR 1'!E10) | F8: =IF(ISBLANK('ONR 1'!F10),"",'ONR 1'!F10) | G8: =IF(ISBLANK('ONR 1'!G10),"",'ONR 1'!G10) | H8: =IF(ISBLANK('ONR 1'!H10),"",'ONR 1'!H10) | I8: =IF(ISBLANK('ONR 1'!I10),"",'ONR 1'!I10) | ... U8: =IF(ISBLANK('ONR 1'!U10),"",'ONR 1'!U10) | V8: =IF(ISBLANK('ONR 1'!G10),"",'ONR 1'!G10) | W8: =IF(ISBLANK('ONR 1'!V10),"",'ONR 1'!V10) | X8: =IF(ISBLANK('ONR 1'!W10),"",'ONR 1'!W10) | Y8: =IF(ISBLANK('ONR 1'!I10),"",'ONR 1'!I10) | Z8: =IF(ISBLANK('ONR 1'!D10),"",'ONR 1'!D10) | AE8: =IF(ISNUMBER(T8),0,1) -> 1 | AF8: =IF(L8=TRUE,1,0) -> 0 | AG8: =IF(M8=TRUE,1,0) -> 0 | AH8: =IF(N8=TRUE,1,0) -> 0 | AI8: =IF(O8=TRUE,1,0) -> 0 | AJ8: =IF(P8=TRUE,1,0) -> 0 | AK8: =IF(Q8=TRUE,1,0) -> 0 | AL8: =IF(R8=TRUE,1,0) -> 0 | AM8: =IF(LEN(TRIM(W8))>0,1,0) -> 0
B9: =IF(ISBLANK('ONR 1'!B11),"",'ONR 1'!B11) -> 1.5 | C9: =IF(ISBLANK('ONR 1'!C11),"",'ONR 1'!C11) -> Réutiliser ou recycler les déchets pour en faire de nouvelles ressources. Soutenir les emplois liés à leur traitement et à l’économie circulaire. | D9: =IF(ISBLANK('ONR 1'!D11),"",'ONR 1'!D11) | E9: =IF(ISBLANK('ONR 1'!E11),"",'ONR 1'!E11) | F9: =IF(ISBLANK('ONR 1'!F11),"",'ONR 1'!F11) | G9: =IF(ISBLANK('ONR 1'!G11),"",'ONR 1'!G11) | H9: =IF(ISBLANK('ONR 1'!H11),"",'ONR 1'!H11) | I9: =IF(ISBLANK('ONR 1'!I11),"",'ONR 1'!I11) | ... U9: =IF(ISBLANK('ONR 1'!U11),"",'ONR 1'!U11) | V9: =IF(ISBLANK('ONR 1'!G11),"",'ONR 1'!G11) | W9: =IF(ISBLANK('ONR 1'!V11),"",'ONR 1'!V11) | X9: =IF(ISBLANK('ONR 1'!W11),"",'ONR 1'!W11) | Y9: =IF(ISBLANK('ONR 1'!I11),"",'ONR 1'!I11) | Z9: =IF(ISBLANK('ONR 1'!D11),"",'ONR 1'!D11) | AE9: =IF(ISNUMBER(T9),0,1) -> 1 | AF9: =IF(L9=TRUE,1,0) -> 0 | AG9: =IF(M9=TRUE,1,0) -> 0 | AH9: =IF(N9=TRUE,1,0) -> 0 | AI9: =IF(O9=TRUE,1,0) -> 0 | AJ9: =IF(P9=TRUE,1,0) -> 0 | AK9: =IF(Q9=TRUE,1,0) -> 0 | AL9: =IF(R9=TRUE,1,0) -> 0 | AM9: =IF(LEN(TRIM(W9))>0,1,0) -> 0
B10: =IF(ISBLANK('ONR 1'!B12),"",'ONR 1'!B12) -> 1.6 | C10: =IF(ISBLANK('ONR 1'!C12),"",'ONR 1'!C12) -> Choisir des énergies renouvelables et encourager leur utilisation. | D10: =IF(ISBLANK('ONR 1'!D12),"",'ONR 1'!D12) | E10: =IF(ISBLANK('ONR 1'!E12),"",'ONR 1'!E12) | F10: =IF(ISBLANK('ONR 1'!F12),"",'ONR 1'!F12) | G10: =IF(ISBLANK('ONR 1'!G12),"",'ONR 1'!G12) | H10: =IF(ISBLANK('ONR 1'!H12),"",'ONR 1'!H12) | I10: =IF(ISBLANK('ONR 1'!I12),"",'ONR 1'!I12) | ... U10: =IF(ISBLANK('ONR 1'!U12),"",'ONR 1'!U12) | V10: =IF(ISBLANK('ONR 1'!G12),"",'ONR 1'!G12) | W10: =IF(ISBLANK('ONR 1'!V12),"",'ONR 1'!V12) | X10: =IF(ISBLANK('ONR 1'!W12),"",'ONR 1'!W12) | Y10: =IF(ISBLANK('ONR 1'!I12),"",'ONR 1'!I12) | Z10: =IF(ISBLANK('ONR 1'!D12),"",'ONR 1'!D12) | AE10: =IF(ISNUMBER(T10),0,1) -> 1 | AF10: =IF(L10=TRUE,1,0) -> 0 | AG10: =IF(M10=TRUE,1,0) -> 0 | AH10: =IF(N10=TRUE,1,0) -> 0 | AI10: =IF(O10=TRUE,1,0) -> 0 | AJ10: =IF(P10=TRUE,1,0) -> 0 | AK10: =IF(Q10=TRUE,1,0) -> 0 | AL10: =IF(R10=TRUE,1,0) -> 0 | AM10: =IF(LEN(TRIM(W10))>0,1,0) -> 0
B11: =IF(ISBLANK('ONR 1'!B13),"",'ONR 1'!B13) -> 1.7 | C11: =IF(ISBLANK('ONR 1'!C13),"",'ONR 1'!C13) -> Réserver l’intelligence artificielle aux besoins qui la justifient et privilégier des solutions sobres en ressources. | D11: =IF(ISBLANK('ONR 1'!D13),"",'ONR 1'!D13) -> Avantages possibles : maîtriser les coûts du matériel et des services d’IA, et réduire les émissions de gaz à effet de serre liées à leur entraînement et à leur utilisation. Risque : utiliser l’IA par effet de mode, sans besoin réel, et consommer davantage de ressources. | E11: =IF(ISBLANK('ONR 1'!E13),"",'ONR 1'!E13) -> 3 | F11: =IF(ISBLANK('ONR 1'!F13),"",'ONR 1'!F13) -> 1 | G11: =IF(ISBLANK('ONR 1'!G13),"",'ONR 1'!G13) -> Les équipes métiers expérimentent plusieurs projets d’IA générative, dont des usages de ChatGPT. Elles ne mesurent pas leur impact énergétique et ne disposent pas de charte pour encadrer les besoins et les usages. | H11: =IF(ISBLANK('ONR 1'!H13),"",'ONR 1'!H13) -> 2 | I11: =IF(ISBLANK('ONR 1'!I13),"",'ONR 1'!I13) -> Point fort : l’équipe chargée des données et de l’informatique dispose de compétences techniques et souhaite explorer ces outils. Points faibles : elle connaît peu les méthodes pour mesurer et réduire la consommation de l’IA. Elle manque aussi de recul pour savoir quand l’IA est utile. | ... U11: =IF(ISBLANK('ONR 1'!U13),"",'ONR 1'!U13) -> 62 | V11: =IF(ISBLANK('ONR 1'!G13),"",'ONR 1'!G13) -> Les équipes métiers expérimentent plusieurs projets d’IA générative, dont des usages de ChatGPT. Elles ne mesurent pas leur impact énergétique et ne disposent pas de charte pour encadrer les besoins et les usages. | W11: =IF(ISBLANK('ONR 1'!V13),"",'ONR 1'!V13) -> 1. Vérifier le besoin avant chaque projet : faut-il de l’IA ou un outil informatique classique suffit-il ? 2. Choisir de petits modèles spécialisés quand ils répondent au besoin. 3. Former les développeurs et les spécialistes des données à réduire la consommation de l’IA, en améliorant le code et en évitant les calculs répétés. | X11: =IF(ISBLANK('ONR 1'!W13),"",'ONR 1'!W13) | Y11: =IF(ISBLANK('ONR 1'!I13),"",'ONR 1'!I13) -> Point fort : l’équipe chargée des données et de l’informatique dispose de compétences techniques et souhaite explorer ces outils. Points faibles : elle connaît peu les méthodes pour mesurer et réduire la consommation de l’IA. Elle manque aussi de recul pour savoir quand l’IA est utile. | Z11: =IF(ISBLANK('ONR 1'!D13),"",'ONR 1'!D13) -> Avantages possibles : maîtriser les coûts du matériel et des services d’IA, et réduire les émissions de gaz à effet de serre liées à leur entraînement et à leur utilisation. Risque : utiliser l’IA par effet de mode, sans besoin réel, et consommer davantage de ressources. | AE11: =IF(ISNUMBER(T11),0,1) -> 0 | AF11: =IF(L11=TRUE,1,0) -> 1 | AG11: =IF(M11=TRUE,1,0) -> 0 | AH11: =IF(N11=TRUE,1,0) -> 0 | AI11: =IF(O11=TRUE,1,0) -> 0 | AJ11: =IF(P11=TRUE,1,0) -> 0 | AK11: =IF(Q11=TRUE,1,0) -> 0 | AL11: =IF(R11=TRUE,1,0) -> 0 | AM11: =IF(LEN(TRIM(W11))>0,1,0) -> 1
