Workbook
Name liste_évaluation: #REF!
Name valeurs: #REF!
Name valeurs: #REF!
Name valeurs: #REF!
Name valeurs: #REF!
Name valeurs: #REF!
Name valeurs: #REF!
Name valeurs: #REF!

Sheet Accueil

Sheet Méthodologie

Sheet Contexte
B2: Étapes préalables et description du contexte de priorisation
B4: Organisation pour laquelle la priorisation est effectuée
B5: Niveau d'avancement dans la mise en œuvre des ONR
B6: Documents politiques et stratégiques existants ou en préparation qui peuvent faciliter l'identification des cibles et ONR prioritaires
B7: Sources d'information pertinentes sur la situation relativement à l'atteinte des cibles des ONR
B8: Service responsable de la priorisation
B10: Noms et titres des analystes
B11: Personne responsable de l'analyse et du suivi
B12: Date de l'analyse

Sheet ONR 1
L1: 0 | M1: 1 | N1: 2 | O1: 3 | P1: 4 | Q1: 5
B2: ONR 1 : Sobriété · Utiliser les outils numériques pour consommer moins de ressources et réduire leurs effets sur l’environnement
B4: Cibles à évaluer | D4: Importance de la cible | F4: Performance actuelle | H4: Compétences internes et externes | J4: Priorité | V4: Mise en œuvre
D5: Avantages possibles et risques | E5: Importance | F5: Niveau actuel | G5: Ce qui est déjà fait et ce qui justifie la note | H5: Compétences nécessaires | I5: Points forts et points faibles | J5: Niveau de priorité | K5: Clé de priorisation | L5: Intervention urgente | M5: Intervention prioritaire | N5: Intervention à moyen terme | O5: Intervention à long terme | P5: Intervention de consolidation | Q5: Intervention non prioritaire | R5: Intervention non pertinente | S5: Libellé de priorité | T5: Score de priorité | U5: Code priorité et compétences | V5: Actions proposées pour atteindre la cible
B6: Renseigner les cellules jaunes pour les notes, puis les textes utiles. La priorité se calcule automatiquement. Faire défiler vers la droite pour proposer des actions.
B7: 1.1 | C7: Prendre en compte toute la vie des équipements et des logiciels de l'établissement, de l'achat à la fin de vie : postes, salles informatiques, équipements de laboratoire et de calcul. | J7: =S7 | K7: =IF(IF(ISNUMBER(E7),AND(E7>=0,E7<=3,MOD(E7,1)=0),FALSE),IF(E7=0,0,IF(IF(ISNUMBER(F7),AND(F7>=1,F7<=4,MOD(F7,1)=0),FALSE),E7*10+F7,"")),"") | L7: =IF(ISNUMBER(K7),K7=31,FALSE) -> FALSE | M7: =IF(ISNUMBER(K7),OR(K7=21,K7=32),FALSE) -> FALSE | N7: =IF(ISNUMBER(K7),OR(K7=22,K7=33),FALSE) -> FALSE | O7: =IF(ISNUMBER(K7),OR(K7=11,K7=12),FALSE) -> FALSE | P7: =IF(ISNUMBER(K7),OR(K7=23,K7=34),FALSE) -> FALSE | Q7: =IF(ISNUMBER(K7),OR(K7=13,K7=14,K7=24),FALSE) -> FALSE | R7: =IF(ISNUMBER(K7),K7=0,FALSE) -> FALSE | S7: =IF(ISNUMBER(T7),INDEX($L$5:$R$5,1,7-T7),"") | T7: =IF(ISNUMBER(K7),IF(L7,6,IF(M7,5,IF(N7,4,IF(O7,3,IF(P7,2,IF(Q7,1,0)))))),"") | U7: =IF(AND(ISNUMBER(T7),ISNUMBER(H7)),IF(AND(H7>=1,H7<=4,MOD(H7,1)=0),T7*10+H7,""),"")
B8: 1.2 | C8: Utiliser plus longtemps les équipements des personnels, des salles et des laboratoires, même après leur amortissement, en organisant leur réparation et leur réaffectation. | J8: =S8 | K8: =IF(IF(ISNUMBER(E8),AND(E8>=0,E8<=3,MOD(E8,1)=0),FALSE),IF(E8=0,0,IF(IF(ISNUMBER(F8),AND(F8>=1,F8<=4,MOD(F8,1)=0),FALSE),E8*10+F8,"")),"") | L8: =IF(ISNUMBER(K8),K8=31,FALSE) -> FALSE | M8: =IF(ISNUMBER(K8),OR(K8=21,K8=32),FALSE) -> FALSE | N8: =IF(ISNUMBER(K8),OR(K8=22,K8=33),FALSE) -> FALSE | O8: =IF(ISNUMBER(K8),OR(K8=11,K8=12),FALSE) -> FALSE | P8: =IF(ISNUMBER(K8),OR(K8=23,K8=34),FALSE) -> FALSE | Q8: =IF(ISNUMBER(K8),OR(K8=13,K8=14,K8=24),FALSE) -> FALSE | R8: =IF(ISNUMBER(K8),K8=0,FALSE) -> FALSE | S8: =IF(ISNUMBER(T8),INDEX($L$5:$R$5,1,7-T8),"") | T8: =IF(ISNUMBER(K8),IF(L8,6,IF(M8,5,IF(N8,4,IF(O8,3,IF(P8,2,IF(Q8,1,0)))))),"") | U8: =IF(AND(ISNUMBER(T8),ISNUMBER(H8)),IF(AND(H8>=1,H8<=4,MOD(H8,1)=0),T8*10+H8,""),"")
B9: 1.3 | C9: Concevoir des services numériques qui limitent leurs effets sur l'environnement, en suivant le RGESN : plateforme pédagogique (LMS comme Moodle), environnement numérique de travail (ENT), applications de scolarité, logiciels de recherche. Choisir des technologies qui contribuent aux ODD. | J9: =S9 | K9: =IF(IF(ISNUMBER(E9),AND(E9>=0,E9<=3,MOD(E9,1)=0),FALSE),IF(E9=0,0,IF(IF(ISNUMBER(F9),AND(F9>=1,F9<=4,MOD(F9,1)=0),FALSE),E9*10+F9,"")),"") | L9: =IF(ISNUMBER(K9),K9=31,FALSE) -> FALSE | M9: =IF(ISNUMBER(K9),OR(K9=21,K9=32),FALSE) -> FALSE | N9: =IF(ISNUMBER(K9),OR(K9=22,K9=33),FALSE) -> FALSE | O9: =IF(ISNUMBER(K9),OR(K9=11,K9=12),FALSE) -> FALSE | P9: =IF(ISNUMBER(K9),OR(K9=23,K9=34),FALSE) -> FALSE | Q9: =IF(ISNUMBER(K9),OR(K9=13,K9=14,K9=24),FALSE) -> FALSE | R9: =IF(ISNUMBER(K9),K9=0,FALSE) -> FALSE | S9: =IF(ISNUMBER(T9),INDEX($L$5:$R$5,1,7-T9),"") | T9: =IF(ISNUMBER(K9),IF(L9,6,IF(M9,5,IF(N9,4,IF(O9,3,IF(P9,2,IF(Q9,1,0)))))),"") | U9: =IF(AND(ISNUMBER(T9),ISNUMBER(H9)),IF(AND(H9>=1,H9<=4,MOD(H9,1)=0),T9*10+H9,""),"")
B10: 1.4 | C10: Adopter, dans les cours, les examens, l'administration et les laboratoires, des pratiques qui consomment moins de matériel, d'énergie, de papier et de stockage. | J10: =S10 | K10: =IF(IF(ISNUMBER(E10),AND(E10>=0,E10<=3,MOD(E10,1)=0),FALSE),IF(E10=0,0,IF(IF(ISNUMBER(F10),AND(F10>=1,F10<=4,MOD(F10,1)=0),FALSE),E10*10+F10,"")),"") | L10: =IF(ISNUMBER(K10),K10=31,FALSE) -> FALSE | M10: =IF(ISNUMBER(K10),OR(K10=21,K10=32),FALSE) -> FALSE | N10: =IF(ISNUMBER(K10),OR(K10=22,K10=33),FALSE) -> FALSE | O10: =IF(ISNUMBER(K10),OR(K10=11,K10=12),FALSE) -> FALSE | P10: =IF(ISNUMBER(K10),OR(K10=23,K10=34),FALSE) -> FALSE | Q10: =IF(ISNUMBER(K10),OR(K10=13,K10=14,K10=24),FALSE) -> FALSE | R10: =IF(ISNUMBER(K10),K10=0,FALSE) -> FALSE | S10: =IF(ISNUMBER(T10),INDEX($L$5:$R$5,1,7-T10),"") | T10: =IF(ISNUMBER(K10),IF(L10,6,IF(M10,5,IF(N10,4,IF(O10,3,IF(P10,2,IF(Q10,1,0)))))),"") | U10: =IF(AND(ISNUMBER(T10),ISNUMBER(H10)),IF(AND(H10>=1,H10<=4,MOD(H10,1)=0),T10*10+H10,""),"")
B11: 1.5 | C11: Confier les équipements en fin d'usage à des filières de réemploi et de l'économie sociale et solidaire, par exemple pour équiper des étudiants. | J11: =S11 | K11: =IF(IF(ISNUMBER(E11),AND(E11>=0,E11<=3,MOD(E11,1)=0),FALSE),IF(E11=0,0,IF(IF(ISNUMBER(F11),AND(F11>=1,F11<=4,MOD(F11,1)=0),FALSE),E11*10+F11,"")),"") | L11: =IF(ISNUMBER(K11),K11=31,FALSE) -> FALSE | M11: =IF(ISNUMBER(K11),OR(K11=21,K11=32),FALSE) -> FALSE | N11: =IF(ISNUMBER(K11),OR(K11=22,K11=33),FALSE) -> FALSE | O11: =IF(ISNUMBER(K11),OR(K11=11,K11=12),FALSE) -> FALSE | P11: =IF(ISNUMBER(K11),OR(K11=23,K11=34),FALSE) -> FALSE | Q11: =IF(ISNUMBER(K11),OR(K11=13,K11=14,K11=24),FALSE) -> FALSE | R11: =IF(ISNUMBER(K11),K11=0,FALSE) -> FALSE | S11: =IF(ISNUMBER(T11),INDEX($L$5:$R$5,1,7-T11),"") | T11: =IF(ISNUMBER(K11),IF(L11,6,IF(M11,5,IF(N11,4,IF(O11,3,IF(P11,2,IF(Q11,1,0)))))),"") | U11: =IF(AND(ISNUMBER(T11),ISNUMBER(H11)),IF(AND(H11>=1,H11<=4,MOD(H11,1)=0),T11*10+H11,""),"")
B12: 1.6 | C12: Alimenter les campus, les centres de données et les moyens de calcul avec des énergies renouvelables, et valoriser leur chaleur fatale. | J12: =S12 | K12: =IF(IF(ISNUMBER(E12),AND(E12>=0,E12<=3,MOD(E12,1)=0),FALSE),IF(E12=0,0,IF(IF(ISNUMBER(F12),AND(F12>=1,F12<=4,MOD(F12,1)=0),FALSE),E12*10+F12,"")),"") | L12: =IF(ISNUMBER(K12),K12=31,FALSE) -> FALSE | M12: =IF(ISNUMBER(K12),OR(K12=21,K12=32),FALSE) -> FALSE | N12: =IF(ISNUMBER(K12),OR(K12=22,K12=33),FALSE) -> FALSE | O12: =IF(ISNUMBER(K12),OR(K12=11,K12=12),FALSE) -> FALSE | P12: =IF(ISNUMBER(K12),OR(K12=23,K12=34),FALSE) -> FALSE | Q12: =IF(ISNUMBER(K12),OR(K12=13,K12=14,K12=24),FALSE) -> FALSE | R12: =IF(ISNUMBER(K12),K12=0,FALSE) -> FALSE | S12: =IF(ISNUMBER(T12),INDEX($L$5:$R$5,1,7-T12),"") | T12: =IF(ISNUMBER(K12),IF(L12,6,IF(M12,5,IF(N12,4,IF(O12,3,IF(P12,2,IF(Q12,1,0)))))),"") | U12: =IF(AND(ISNUMBER(T12),ISNUMBER(H12)),IF(AND(H12>=1,H12<=4,MOD(H12,1)=0),T12*10+H12,""),"")
B13: 1.7 | C13: Réserver l'intelligence artificielle aux besoins de formation, de recherche et de gestion qui la justifient, et choisir des solutions sobres. | J13: =S13 | K13: =IF(IF(ISNUMBER(E13),AND(E13>=0,E13<=3,MOD(E13,1)=0),FALSE),IF(E13=0,0,IF(IF(ISNUMBER(F13),AND(F13>=1,F13<=4,MOD(F13,1)=0),FALSE),E13*10+F13,"")),"") | L13: =IF(ISNUMBER(K13),K13=31,FALSE) -> FALSE | M13: =IF(ISNUMBER(K13),OR(K13=21,K13=32),FALSE) -> FALSE | N13: =IF(ISNUMBER(K13),OR(K13=22,K13=33),FALSE) -> FALSE | O13: =IF(ISNUMBER(K13),OR(K13=11,K13=12),FALSE) -> FALSE | P13: =IF(ISNUMBER(K13),OR(K13=23,K13=34),FALSE) -> FALSE | Q13: =IF(ISNUMBER(K13),OR(K13=13,K13=14,K13=24),FALSE) -> FALSE | R13: =IF(ISNUMBER(K13),K13=0,FALSE) -> FALSE | S13: =IF(ISNUMBER(T13),INDEX($L$5:$R$5,1,7-T13),"") | T13: =IF(ISNUMBER(K13),IF(L13,6,IF(M13,5,IF(N13,4,IF(O13,3,IF(P13,2,IF(Q13,1,0)))))),"") | U13: =IF(AND(ISNUMBER(T13),ISNUMBER(H13)),IF(AND(H13>=1,H13<=4,MOD(H13,1)=0),T13*10+H13,""),"")
B14: 1.8 | C14: Mesurer et réduire ce que consomme l'intelligence artificielle dans l'établissement, notamment l'entraînement de modèles par les équipes de recherche. | J14: =S14 -> 0 | K14: =IF(IF(ISNUMBER(E14),AND(E14>=0,E14<=3,MOD(E14,1)=0),FALSE),IF(E14=0,0,IF(IF(ISNUMBER(F14),AND(F14>=1,F14<=4,MOD(F14,1)=0),FALSE),E14*10+F14,"")),"") | L14: =IF(ISNUMBER(K14),K14=31,FALSE) -> FALSE | M14: =IF(ISNUMBER(K14),OR(K14=21,K14=32),FALSE) -> FALSE | N14: =IF(ISNUMBER(K14),OR(K14=22,K14=33),FALSE) -> FALSE | O14: =IF(ISNUMBER(K14),OR(K14=11,K14=12),FALSE) -> FALSE | P14: =IF(ISNUMBER(K14),OR(K14=23,K14=34),FALSE) -> FALSE | Q14: =IF(ISNUMBER(K14),OR(K14=13,K14=14,K14=24),FALSE) -> FALSE | R14: =IF(ISNUMBER(K14),K14=0,FALSE) -> FALSE | S14: =IF(ISNUMBER(T14),INDEX($L$5:$R$5,1,7-T14),"") | T14: =IF(ISNUMBER(K14),IF(L14,6,IF(M14,5,IF(N14,4,IF(O14,3,IF(P14,2,IF(Q14,1,0)))))),"") | U14: =IF(AND(ISNUMBER(T14),ISNUMBER(H14)),IF(AND(H14>=1,H14<=4,MOD(H14,1)=0),T14*10+H14,""),"")

Sheet ONR 2
L1: 0 | M1: 1 | N1: 2 | O1: 3 | P1: 4 | Q1: 5
B2: ONR 2 : Inclusion · Développer des services numériques durables que toutes et tous peuvent utiliser
B4: Cibles à évaluer | D4: Importance de la cible | F4: Performance actuelle | H4: Compétences internes et externes | J4: Priorité | V4: Mise en œuvre
D5: Avantages possibles et risques | E5: Importance | F5: Niveau actuel | G5: Ce qui est déjà fait et ce qui justifie la note | H5: Compétences nécessaires | I5: Points forts et points faibles | J5: Niveau de priorité | K5: Clé de priorisation | L5: Intervention urgente | M5: Intervention prioritaire | N5: Intervention à moyen terme | O5: Intervention à long terme | P5: Intervention de consolidation | Q5: Intervention non prioritaire | R5: Intervention non pertinente | S5: Libellé de priorité | T5: Score de priorité | U5: Code priorité et compétences | V5: Actions proposées pour atteindre la cible | W5: Adhérence
B6: Renseigner les cellules jaunes pour les notes, puis les textes utiles. La priorité se calcule automatiquement. Faire défiler vers la droite pour proposer des actions.
B7: 2.1 | C7: Intégrer dans les achats numériques de l'établissement, y compris ceux des laboratoires, des clauses sociales et environnementales et des critères de durabilité. | J7: =S7 | K7: =IF(IF(ISNUMBER(E7),AND(E7>=0,E7<=3,MOD(E7,1)=0),FALSE),IF(E7=0,0,IF(IF(ISNUMBER(F7),AND(F7>=1,F7<=4,MOD(F7,1)=0),FALSE),E7*10+F7,"")),"") | L7: =IF(ISNUMBER(K7),K7=31,FALSE) -> FALSE | M7: =IF(ISNUMBER(K7),OR(K7=21,K7=32),FALSE) -> FALSE | N7: =IF(ISNUMBER(K7),OR(K7=22,K7=33),FALSE) -> FALSE | O7: =IF(ISNUMBER(K7),OR(K7=11,K7=12),FALSE) -> FALSE | P7: =IF(ISNUMBER(K7),OR(K7=23,K7=34),FALSE) -> FALSE | Q7: =IF(ISNUMBER(K7),OR(K7=13,K7=14,K7=24),FALSE) -> FALSE | R7: =IF(ISNUMBER(K7),K7=0,FALSE) -> FALSE | S7: =IF(ISNUMBER(T7),INDEX($L$5:$R$5,1,7-T7),"") | T7: =IF(ISNUMBER(K7),IF(L7,6,IF(M7,5,IF(N7,4,IF(O7,3,IF(P7,2,IF(Q7,1,0)))))),"") | U7: =IF(AND(ISNUMBER(T7),ISNUMBER(H7)),IF(AND(H7>=1,H7<=4,MOD(H7,1)=0),T7*10+H7,""),"")
B8: 2.2 | C8: Rendre accessibles à toutes et tous les sites, l'ENT, le LMS et les ressources pédagogiques : vidéos de cours sous-titrées, documents et supports accessibles. Mesurer leur conformité au RGAA. | J8: =S8 | K8: =IF(IF(ISNUMBER(E8),AND(E8>=0,E8<=3,MOD(E8,1)=0),FALSE),IF(E8=0,0,IF(IF(ISNUMBER(F8),AND(F8>=1,F8<=4,MOD(F8,1)=0),FALSE),E8*10+F8,"")),"") | L8: =IF(ISNUMBER(K8),K8=31,FALSE) -> FALSE | M8: =IF(ISNUMBER(K8),OR(K8=21,K8=32),FALSE) -> FALSE | N8: =IF(ISNUMBER(K8),OR(K8=22,K8=33),FALSE) -> FALSE | O8: =IF(ISNUMBER(K8),OR(K8=11,K8=12),FALSE) -> FALSE | P8: =IF(ISNUMBER(K8),OR(K8=23,K8=34),FALSE) -> FALSE | Q8: =IF(ISNUMBER(K8),OR(K8=13,K8=14,K8=24),FALSE) -> FALSE | R8: =IF(ISNUMBER(K8),K8=0,FALSE) -> FALSE | S8: =IF(ISNUMBER(T8),INDEX($L$5:$R$5,1,7-T8),"") | T8: =IF(ISNUMBER(K8),IF(L8,6,IF(M8,5,IF(N8,4,IF(O8,3,IF(P8,2,IF(Q8,1,0)))))),"") | U8: =IF(AND(ISNUMBER(T8),ISNUMBER(H8)),IF(AND(H8>=1,H8<=4,MOD(H8,1)=0),T8*10+H8,""),"")
B9: 2.3 | C9: Proposer aux étudiants et aux personnels des outils utiles, faciles à utiliser et réellement utilisés, plutôt qu'une multitude de plateformes : un ENT, un LMS, une messagerie, une visioconférence, un outil d'emploi du temps. | J9: =S9 | K9: =IF(IF(ISNUMBER(E9),AND(E9>=0,E9<=3,MOD(E9,1)=0),FALSE),IF(E9=0,0,IF(IF(ISNUMBER(F9),AND(F9>=1,F9<=4,MOD(F9,1)=0),FALSE),E9*10+F9,"")),"") | L9: =IF(ISNUMBER(K9),K9=31,FALSE) -> FALSE | M9: =IF(ISNUMBER(K9),OR(K9=21,K9=32),FALSE) -> FALSE | N9: =IF(ISNUMBER(K9),OR(K9=22,K9=33),FALSE) -> FALSE | O9: =IF(ISNUMBER(K9),OR(K9=11,K9=12),FALSE) -> FALSE | P9: =IF(ISNUMBER(K9),OR(K9=23,K9=34),FALSE) -> FALSE | Q9: =IF(ISNUMBER(K9),OR(K9=13,K9=14,K9=24),FALSE) -> FALSE | R9: =IF(ISNUMBER(K9),K9=0,FALSE) -> FALSE | S9: =IF(ISNUMBER(T9),INDEX($L$5:$R$5,1,7-T9),"") | T9: =IF(ISNUMBER(K9),IF(L9,6,IF(M9,5,IF(N9,4,IF(O9,3,IF(P9,2,IF(Q9,1,0)))))),"") | U9: =IF(AND(ISNUMBER(T9),ISNUMBER(H9)),IF(AND(H9>=1,H9<=4,MOD(H9,1)=0),T9*10+H9,""),"")
B10: 2.4 | C10: Concevoir les services numériques avec les étudiants, les enseignants, les chercheurs et les personnels, en partant de leurs besoins réels. | J10: =S10 | K10: =IF(IF(ISNUMBER(E10),AND(E10>=0,E10<=3,MOD(E10,1)=0),FALSE),IF(E10=0,0,IF(IF(ISNUMBER(F10),AND(F10>=1,F10<=4,MOD(F10,1)=0),FALSE),E10*10+F10,"")),"") | L10: =IF(ISNUMBER(K10),K10=31,FALSE) -> FALSE | M10: =IF(ISNUMBER(K10),OR(K10=21,K10=32),FALSE) -> FALSE | N10: =IF(ISNUMBER(K10),OR(K10=22,K10=33),FALSE) -> FALSE | O10: =IF(ISNUMBER(K10),OR(K10=11,K10=12),FALSE) -> FALSE | P10: =IF(ISNUMBER(K10),OR(K10=23,K10=34),FALSE) -> FALSE | Q10: =IF(ISNUMBER(K10),OR(K10=13,K10=14,K10=24),FALSE) -> FALSE | R10: =IF(ISNUMBER(K10),K10=0,FALSE) -> FALSE | S10: =IF(ISNUMBER(T10),INDEX($L$5:$R$5,1,7-T10),"") | T10: =IF(ISNUMBER(K10),IF(L10,6,IF(M10,5,IF(N10,4,IF(O10,3,IF(P10,2,IF(Q10,1,0)))))),"") | U10: =IF(AND(ISNUMBER(T10),ISNUMBER(H10)),IF(AND(H10>=1,H10<=4,MOD(H10,1)=0),T10*10+H10,""),"")
B11: 2.5 | C11: Vérifier que l'intelligence artificielle utilisée pour orienter, évaluer ou accompagner les étudiants ne discrimine personne : aide à l'orientation, détection de plagiat, correction automatique, agents conversationnels. | J11: =S11 -> 0 | K11: =IF(IF(ISNUMBER(E11),AND(E11>=0,E11<=3,MOD(E11,1)=0),FALSE),IF(E11=0,0,IF(IF(ISNUMBER(F11),AND(F11>=1,F11<=4,MOD(F11,1)=0),FALSE),E11*10+F11,"")),"") | L11: =IF(ISNUMBER(K11),K11=31,FALSE) -> FALSE | M11: =IF(ISNUMBER(K11),OR(K11=21,K11=32),FALSE) -> FALSE | N11: =IF(ISNUMBER(K11),OR(K11=22,K11=33),FALSE) -> FALSE | O11: =IF(ISNUMBER(K11),OR(K11=11,K11=12),FALSE) -> FALSE | P11: =IF(ISNUMBER(K11),OR(K11=23,K11=34),FALSE) -> FALSE | Q11: =IF(ISNUMBER(K11),OR(K11=13,K11=14,K11=24),FALSE) -> FALSE | R11: =IF(ISNUMBER(K11),K11=0,FALSE) -> FALSE | S11: =IF(ISNUMBER(T11),INDEX($L$5:$R$5,1,7-T11),"") | T11: =IF(ISNUMBER(K11),IF(L11,6,IF(M11,5,IF(N11,4,IF(O11,3,IF(P11,2,IF(Q11,1,0)))))),"") | U11: =IF(AND(ISNUMBER(T11),ISNUMBER(H11)),IF(AND(H11>=1,H11<=4,MOD(H11,1)=0),T11*10+H11,""),"")

Sheet ONR 3
L1: 0 | M1: 1 | N1: 2 | O1: 3 | P1: 4 | Q1: 5
B2: ONR 3 : RSE · Utiliser le numérique de façon éthique et responsable
B4: Cibles à évaluer | D4: Importance de la cible | F4: Performance actuelle | H4: Compétences internes et externes | J4: Priorité | V4: Mise en œuvre
D5: Avantages possibles et risques | E5: Importance | F5: Niveau actuel | G5: Ce qui est déjà fait et ce qui justifie la note | H5: Compétences nécessaires | I5: Points forts et points faibles | J5: Niveau de priorité | K5: Clé de priorisation | L5: Intervention urgente | M5: Intervention prioritaire | N5: Intervention à moyen terme | O5: Intervention à long terme | P5: Intervention de consolidation | Q5: Intervention non prioritaire | R5: Intervention non pertinente | S5: Libellé de priorité | T5: Score de priorité | U5: Code priorité et compétences | V5: Actions proposées pour atteindre la cible
B6: Renseigner les cellules jaunes pour les notes, puis les textes utiles. La priorité se calcule automatiquement. Faire défiler vers la droite pour proposer des actions.
B7: 3.1 | C7: Utiliser avec mesure les données des étudiants, des personnels et de la recherche, y compris les traces d'apprentissage collectées par le LMS, en respectant les personnes et l'environnement. | J7: =S7 | K7: =IF(IF(ISNUMBER(E7),AND(E7>=0,E7<=3,MOD(E7,1)=0),FALSE),IF(E7=0,0,IF(IF(ISNUMBER(F7),AND(F7>=1,F7<=4,MOD(F7,1)=0),FALSE),E7*10+F7,"")),"") | L7: =IF(ISNUMBER(K7),K7=31,FALSE) -> FALSE | M7: =IF(ISNUMBER(K7),OR(K7=21,K7=32),FALSE) -> FALSE | N7: =IF(ISNUMBER(K7),OR(K7=22,K7=33),FALSE) -> FALSE | O7: =IF(ISNUMBER(K7),OR(K7=11,K7=12),FALSE) -> FALSE | P7: =IF(ISNUMBER(K7),OR(K7=23,K7=34),FALSE) -> FALSE | Q7: =IF(ISNUMBER(K7),OR(K7=13,K7=14,K7=24),FALSE) -> FALSE | R7: =IF(ISNUMBER(K7),K7=0,FALSE) -> FALSE | S7: =IF(ISNUMBER(T7),INDEX($L$5:$R$5,1,7-T7),"") | T7: =IF(ISNUMBER(K7),IF(L7,6,IF(M7,5,IF(N7,4,IF(O7,3,IF(P7,2,IF(Q7,1,0)))))),"") | U7: =IF(AND(ISNUMBER(T7),ISNUMBER(H7)),IF(AND(H7>=1,H7<=4,MOD(H7,1)=0),T7*10+H7,""),"")
B8: 3.2 | C8: Supprimer des services numériques de l'établissement les interfaces qui trompent ou poussent les utilisateurs (« dark patterns »), et respecter la réglementation. | J8: =S8 | K8: =IF(IF(ISNUMBER(E8),AND(E8>=0,E8<=3,MOD(E8,1)=0),FALSE),IF(E8=0,0,IF(IF(ISNUMBER(F8),AND(F8>=1,F8<=4,MOD(F8,1)=0),FALSE),E8*10+F8,"")),"") | L8: =IF(ISNUMBER(K8),K8=31,FALSE) -> FALSE | M8: =IF(ISNUMBER(K8),OR(K8=21,K8=32),FALSE) -> FALSE | N8: =IF(ISNUMBER(K8),OR(K8=22,K8=33),FALSE) -> FALSE | O8: =IF(ISNUMBER(K8),OR(K8=11,K8=12),FALSE) -> FALSE | P8: =IF(ISNUMBER(K8),OR(K8=23,K8=34),FALSE) -> FALSE | Q8: =IF(ISNUMBER(K8),OR(K8=13,K8=14,K8=24),FALSE) -> FALSE | R8: =IF(ISNUMBER(K8),K8=0,FALSE) -> FALSE | S8: =IF(ISNUMBER(T8),INDEX($L$5:$R$5,1,7-T8),"") | T8: =IF(ISNUMBER(K8),IF(L8,6,IF(M8,5,IF(N8,4,IF(O8,3,IF(P8,2,IF(Q8,1,0)))))),"") | U8: =IF(AND(ISNUMBER(T8),ISNUMBER(H8)),IF(AND(H8>=1,H8<=4,MOD(H8,1)=0),T8*10+H8,""),"")
B9: 3.3 | C9: Collecter seulement les données nécessaires dans les applications de scolarité, le LMS et les projets de recherche, et respecter le RGPD avec l'appui du délégué à la protection des données. | J9: =S9 | K9: =IF(IF(ISNUMBER(E9),AND(E9>=0,E9<=3,MOD(E9,1)=0),FALSE),IF(E9=0,0,IF(IF(ISNUMBER(F9),AND(F9>=1,F9<=4,MOD(F9,1)=0),FALSE),E9*10+F9,"")),"") | L9: =IF(ISNUMBER(K9),K9=31,FALSE) -> FALSE | M9: =IF(ISNUMBER(K9),OR(K9=21,K9=32),FALSE) -> FALSE | N9: =IF(ISNUMBER(K9),OR(K9=22,K9=33),FALSE) -> FALSE | O9: =IF(ISNUMBER(K9),OR(K9=11,K9=12),FALSE) -> FALSE | P9: =IF(ISNUMBER(K9),OR(K9=23,K9=34),FALSE) -> FALSE | Q9: =IF(ISNUMBER(K9),OR(K9=13,K9=14,K9=24),FALSE) -> FALSE | R9: =IF(ISNUMBER(K9),K9=0,FALSE) -> FALSE | S9: =IF(ISNUMBER(T9),INDEX($L$5:$R$5,1,7-T9),"") | T9: =IF(ISNUMBER(K9),IF(L9,6,IF(M9,5,IF(N9,4,IF(O9,3,IF(P9,2,IF(Q9,1,0)))))),"") | U9: =IF(AND(ISNUMBER(T9),ISNUMBER(H9)),IF(AND(H9>=1,H9<=4,MOD(H9,1)=0),T9*10+H9,""),"")
B10: 3.4 | C10: Diversifier les profils dans les formations et les métiers du numérique de l'établissement, en particulier la place des femmes. | J10: =S10 | K10: =IF(IF(ISNUMBER(E10),AND(E10>=0,E10<=3,MOD(E10,1)=0),FALSE),IF(E10=0,0,IF(IF(ISNUMBER(F10),AND(F10>=1,F10<=4,MOD(F10,1)=0),FALSE),E10*10+F10,"")),"") | L10: =IF(ISNUMBER(K10),K10=31,FALSE) -> FALSE | M10: =IF(ISNUMBER(K10),OR(K10=21,K10=32),FALSE) -> FALSE | N10: =IF(ISNUMBER(K10),OR(K10=22,K10=33),FALSE) -> FALSE | O10: =IF(ISNUMBER(K10),OR(K10=11,K10=12),FALSE) -> FALSE | P10: =IF(ISNUMBER(K10),OR(K10=23,K10=34),FALSE) -> FALSE | Q10: =IF(ISNUMBER(K10),OR(K10=13,K10=14,K10=24),FALSE) -> FALSE | R10: =IF(ISNUMBER(K10),K10=0,FALSE) -> FALSE | S10: =IF(ISNUMBER(T10),INDEX($L$5:$R$5,1,7-T10),"") | T10: =IF(ISNUMBER(K10),IF(L10,6,IF(M10,5,IF(N10,4,IF(O10,3,IF(P10,2,IF(Q10,1,0)))))),"") | U10: =IF(AND(ISNUMBER(T10),ISNUMBER(H10)),IF(AND(H10>=1,H10<=4,MOD(H10,1)=0),T10*10+H10,""),"")
B11: 3.5 | C11: Améliorer les conditions de travail des personnels du numérique, des doctorants et des contractuels, et les exiger des prestataires. | J11: =S11 | K11: =IF(IF(ISNUMBER(E11),AND(E11>=0,E11<=3,MOD(E11,1)=0),FALSE),IF(E11=0,0,IF(IF(ISNUMBER(F11),AND(F11>=1,F11<=4,MOD(F11,1)=0),FALSE),E11*10+F11,"")),"") | L11: =IF(ISNUMBER(K11),K11=31,FALSE) -> FALSE | M11: =IF(ISNUMBER(K11),OR(K11=21,K11=32),FALSE) -> FALSE | N11: =IF(ISNUMBER(K11),OR(K11=22,K11=33),FALSE) -> FALSE | O11: =IF(ISNUMBER(K11),OR(K11=11,K11=12),FALSE) -> FALSE | P11: =IF(ISNUMBER(K11),OR(K11=23,K11=34),FALSE) -> FALSE | Q11: =IF(ISNUMBER(K11),OR(K11=13,K11=14,K11=24),FALSE) -> FALSE | R11: =IF(ISNUMBER(K11),K11=0,FALSE) -> FALSE | S11: =IF(ISNUMBER(T11),INDEX($L$5:$R$5,1,7-T11),"") | T11: =IF(ISNUMBER(K11),IF(L11,6,IF(M11,5,IF(N11,4,IF(O11,3,IF(P11,2,IF(Q11,1,0)))))),"") | U11: =IF(AND(ISNUMBER(T11),ISNUMBER(H11)),IF(AND(H11>=1,H11<=4,MOD(H11,1)=0),T11*10+H11,""),"")
B12: 3.6 | C12: Fixer des règles éthiques pour les algorithmes et l'intelligence artificielle, en formation comme en recherche, avec le comité d'éthique de l'établissement. | J12: =S12 | K12: =IF(IF(ISNUMBER(E12),AND(E12>=0,E12<=3,MOD(E12,1)=0),FALSE),IF(E12=0,0,IF(IF(ISNUMBER(F12),AND(F12>=1,F12<=4,MOD(F12,1)=0),FALSE),E12*10+F12,"")),"") | L12: =IF(ISNUMBER(K12),K12=31,FALSE) -> FALSE | M12: =IF(ISNUMBER(K12),OR(K12=21,K12=32),FALSE) -> FALSE | N12: =IF(ISNUMBER(K12),OR(K12=22,K12=33),FALSE) -> FALSE | O12: =IF(ISNUMBER(K12),OR(K12=11,K12=12),FALSE) -> FALSE | P12: =IF(ISNUMBER(K12),OR(K12=23,K12=34),FALSE) -> FALSE | Q12: =IF(ISNUMBER(K12),OR(K12=13,K12=14,K12=24),FALSE) -> FALSE | R12: =IF(ISNUMBER(K12),K12=0,FALSE) -> FALSE | S12: =IF(ISNUMBER(T12),INDEX($L$5:$R$5,1,7-T12),"") | T12: =IF(ISNUMBER(K12),IF(L12,6,IF(M12,5,IF(N12,4,IF(O12,3,IF(P12,2,IF(Q12,1,0)))))),"") | U12: =IF(AND(ISNUMBER(T12),ISNUMBER(H12)),IF(AND(H12>=1,H12<=4,MOD(H12,1)=0),T12*10+H12,""),"")
B13: 3.7 | C13: Intégrer le numérique responsable à la démarche de développement durable et de responsabilité sociétale (DD&RS) de l'établissement, et la faire connaître. | J13: =S13 | K13: =IF(IF(ISNUMBER(E13),AND(E13>=0,E13<=3,MOD(E13,1)=0),FALSE),IF(E13=0,0,IF(IF(ISNUMBER(F13),AND(F13>=1,F13<=4,MOD(F13,1)=0),FALSE),E13*10+F13,"")),"") | L13: =IF(ISNUMBER(K13),K13=31,FALSE) -> FALSE | M13: =IF(ISNUMBER(K13),OR(K13=21,K13=32),FALSE) -> FALSE | N13: =IF(ISNUMBER(K13),OR(K13=22,K13=33),FALSE) -> FALSE | O13: =IF(ISNUMBER(K13),OR(K13=11,K13=12),FALSE) -> FALSE | P13: =IF(ISNUMBER(K13),OR(K13=23,K13=34),FALSE) -> FALSE | Q13: =IF(ISNUMBER(K13),OR(K13=13,K13=14,K13=24),FALSE) -> FALSE | R13: =IF(ISNUMBER(K13),K13=0,FALSE) -> FALSE | S13: =IF(ISNUMBER(T13),INDEX($L$5:$R$5,1,7-T13),"") | T13: =IF(ISNUMBER(K13),IF(L13,6,IF(M13,5,IF(N13,4,IF(O13,3,IF(P13,2,IF(Q13,1,0)))))),"") | U13: =IF(AND(ISNUMBER(T13),ISNUMBER(H13)),IF(AND(H13>=1,H13<=4,MOD(H13,1)=0),T13*10+H13,""),"")
B14: 3.8 | C14: Indiquer quand une intelligence artificielle répond ou participe à une évaluation, expliquer comment elle décide, et garder une décision humaine pour les sujets sensibles : notes, admission, orientation, suspicion de plagiat. | J14: =S14 -> 0 | K14: =IF(IF(ISNUMBER(E14),AND(E14>=0,E14<=3,MOD(E14,1)=0),FALSE),IF(E14=0,0,IF(IF(ISNUMBER(F14),AND(F14>=1,F14<=4,MOD(F14,1)=0),FALSE),E14*10+F14,"")),"") | L14: =IF(ISNUMBER(K14),K14=31,FALSE) -> FALSE | M14: =IF(ISNUMBER(K14),OR(K14=21,K14=32),FALSE) -> FALSE | N14: =IF(ISNUMBER(K14),OR(K14=22,K14=33),FALSE) -> FALSE | O14: =IF(ISNUMBER(K14),OR(K14=11,K14=12),FALSE) -> FALSE | P14: =IF(ISNUMBER(K14),OR(K14=23,K14=34),FALSE) -> FALSE | Q14: =IF(ISNUMBER(K14),OR(K14=13,K14=14,K14=24),FALSE) -> FALSE | R14: =IF(ISNUMBER(K14),K14=0,FALSE) -> FALSE | S14: =IF(ISNUMBER(T14),INDEX($L$5:$R$5,1,7-T14),"") | T14: =IF(ISNUMBER(K14),IF(L14,6,IF(M14,5,IF(N14,4,IF(O14,3,IF(P14,2,IF(Q14,1,0)))))),"") | U14: =IF(AND(ISNUMBER(T14),ISNUMBER(H14)),IF(AND(H14>=1,H14<=4,MOD(H14,1)=0),T14*10+H14,""),"")

Sheet ONR 4
L1: 0 | M1: 1 | N1: 2 | O1: 3 | P1: 4 | Q1: 5
B2: ONR 4 : Résilience et stratégie · Utiliser le numérique responsable pour aider l’organisation à faire face aux difficultés et à s’adapter
B4: Cibles à évaluer | D4: Importance de la cible | F4: Performance actuelle | H4: Compétences internes et externes | J4: Priorité | V4: Mise en œuvre
D5: Avantages possibles et risques | E5: Importance | F5: Niveau actuel | G5: Ce qui est déjà fait et ce qui justifie la note | H5: Compétences nécessaires | I5: Points forts et points faibles | J5: Niveau de priorité | K5: Clé de priorisation | L5: Intervention urgente | M5: Intervention prioritaire | N5: Intervention à moyen terme | O5: Intervention à long terme | P5: Intervention de consolidation | Q5: Intervention non prioritaire | R5: Intervention non pertinente | S5: Libellé de priorité | T5: Score de priorité | U5: Code priorité et compétences | V5: Actions proposées pour atteindre la cible
B6: Renseigner les cellules jaunes pour les notes, puis les textes utiles. La priorité se calcule automatiquement. Faire défiler vers la droite pour proposer des actions.
B7: 4.1 | C7: Mesurer l'empreinte environnementale du numérique de l'établissement et des projets de recherche avec des méthodes communes, pour se comparer. | J7: =S7 | K7: =IF(IF(ISNUMBER(E7),AND(E7>=0,E7<=3,MOD(E7,1)=0),FALSE),IF(E7=0,0,IF(IF(ISNUMBER(F7),AND(F7>=1,F7<=4,MOD(F7,1)=0),FALSE),E7*10+F7,"")),"") | L7: =IF(ISNUMBER(K7),K7=31,FALSE) -> FALSE | M7: =IF(ISNUMBER(K7),OR(K7=21,K7=32),FALSE) -> FALSE | N7: =IF(ISNUMBER(K7),OR(K7=22,K7=33),FALSE) -> FALSE | O7: =IF(ISNUMBER(K7),OR(K7=11,K7=12),FALSE) -> FALSE | P7: =IF(ISNUMBER(K7),OR(K7=23,K7=34),FALSE) -> FALSE | Q7: =IF(ISNUMBER(K7),OR(K7=13,K7=14,K7=24),FALSE) -> FALSE | R7: =IF(ISNUMBER(K7),K7=0,FALSE) -> FALSE | S7: =IF(ISNUMBER(T7),INDEX($L$5:$R$5,1,7-T7),"") | T7: =IF(ISNUMBER(K7),IF(L7,6,IF(M7,5,IF(N7,4,IF(O7,3,IF(P7,2,IF(Q7,1,0)))))),"") | U7: =IF(AND(ISNUMBER(T7),ISNUMBER(H7)),IF(AND(H7>=1,H7<=4,MOD(H7,1)=0),T7*10+H7,""),"")
B8: 4.2 | C8: Évaluer les services numériques au fil du temps, avec les étudiants et les personnels, et partager les résultats. | J8: =S8 | K8: =IF(IF(ISNUMBER(E8),AND(E8>=0,E8<=3,MOD(E8,1)=0),FALSE),IF(E8=0,0,IF(IF(ISNUMBER(F8),AND(F8>=1,F8<=4,MOD(F8,1)=0),FALSE),E8*10+F8,"")),"") | L8: =IF(ISNUMBER(K8),K8=31,FALSE) -> FALSE | M8: =IF(ISNUMBER(K8),OR(K8=21,K8=32),FALSE) -> FALSE | N8: =IF(ISNUMBER(K8),OR(K8=22,K8=33),FALSE) -> FALSE | O8: =IF(ISNUMBER(K8),OR(K8=11,K8=12),FALSE) -> FALSE | P8: =IF(ISNUMBER(K8),OR(K8=23,K8=34),FALSE) -> FALSE | Q8: =IF(ISNUMBER(K8),OR(K8=13,K8=14,K8=24),FALSE) -> FALSE | R8: =IF(ISNUMBER(K8),K8=0,FALSE) -> FALSE | S8: =IF(ISNUMBER(T8),INDEX($L$5:$R$5,1,7-T8),"") | T8: =IF(ISNUMBER(K8),IF(L8,6,IF(M8,5,IF(N8,4,IF(O8,3,IF(P8,2,IF(Q8,1,0)))))),"") | U8: =IF(AND(ISNUMBER(T8),ISNUMBER(H8)),IF(AND(H8>=1,H8<=4,MOD(H8,1)=0),T8*10+H8,""),"")
B9: 4.3 | C9: Expérimenter de nouveaux outils pour la pédagogie et la recherche. Évaluer leurs effets et expliquer les résultats à celles et ceux qui les utilisent. | J9: =S9 | K9: =IF(IF(ISNUMBER(E9),AND(E9>=0,E9<=3,MOD(E9,1)=0),FALSE),IF(E9=0,0,IF(IF(ISNUMBER(F9),AND(F9>=1,F9<=4,MOD(F9,1)=0),FALSE),E9*10+F9,"")),"") | L9: =IF(ISNUMBER(K9),K9=31,FALSE) -> FALSE | M9: =IF(ISNUMBER(K9),OR(K9=21,K9=32),FALSE) -> FALSE | N9: =IF(ISNUMBER(K9),OR(K9=22,K9=33),FALSE) -> FALSE | O9: =IF(ISNUMBER(K9),OR(K9=11,K9=12),FALSE) -> FALSE | P9: =IF(ISNUMBER(K9),OR(K9=23,K9=34),FALSE) -> FALSE | Q9: =IF(ISNUMBER(K9),OR(K9=13,K9=14,K9=24),FALSE) -> FALSE | R9: =IF(ISNUMBER(K9),K9=0,FALSE) -> FALSE | S9: =IF(ISNUMBER(T9),INDEX($L$5:$R$5,1,7-T9),"") | T9: =IF(ISNUMBER(K9),IF(L9,6,IF(M9,5,IF(N9,4,IF(O9,3,IF(P9,2,IF(Q9,1,0)))))),"") | U9: =IF(AND(ISNUMBER(T9),ISNUMBER(H9)),IF(AND(H9>=1,H9<=4,MOD(H9,1)=0),T9*10+H9,""),"")
B10: 4.4 | C10: Garder la maîtrise des données de recherche et de formation, des outils et des choix techniques : logiciels libres (Moodle, BigBlueButton, Nextcloud), hébergement de confiance, infrastructures mutualisées de l'enseignement supérieur et de la recherche (RENATER, mésocentres). | J10: =S10 -> 0 | K10: =IF(IF(ISNUMBER(E10),AND(E10>=0,E10<=3,MOD(E10,1)=0),FALSE),IF(E10=0,0,IF(IF(ISNUMBER(F10),AND(F10>=1,F10<=4,MOD(F10,1)=0),FALSE),E10*10+F10,"")),"") | L10: =IF(ISNUMBER(K10),K10=31,FALSE) -> FALSE | M10: =IF(ISNUMBER(K10),OR(K10=21,K10=32),FALSE) -> FALSE | N10: =IF(ISNUMBER(K10),OR(K10=22,K10=33),FALSE) -> FALSE | O10: =IF(ISNUMBER(K10),OR(K10=11,K10=12),FALSE) -> FALSE | P10: =IF(ISNUMBER(K10),OR(K10=23,K10=34),FALSE) -> FALSE | Q10: =IF(ISNUMBER(K10),OR(K10=13,K10=14,K10=24),FALSE) -> FALSE | R10: =IF(ISNUMBER(K10),K10=0,FALSE) -> FALSE | S10: =IF(ISNUMBER(T10),INDEX($L$5:$R$5,1,7-T10),"") | T10: =IF(ISNUMBER(K10),IF(L10,6,IF(M10,5,IF(N10,4,IF(O10,3,IF(P10,2,IF(Q10,1,0)))))),"") | U10: =IF(AND(ISNUMBER(T10),ISNUMBER(H10)),IF(AND(H10>=1,H10<=4,MOD(H10,1)=0),T10*10+H10,""),"")

Sheet ONR 5
L1: 0 | M1: 1 | N1: 2 | O1: 3 | P1: 4 | Q1: 5
B2: ONR 5 : Management · Donner du sens au travail et préserver les personnes et les ressources nécessaires à nos activités
B4: Cibles à évaluer | D4: Importance de la cible | F4: Performance actuelle | H4: Compétences internes et externes | J4: Priorité | V4: Mise en œuvre
D5: Avantages possibles et risques | E5: Importance | F5: Niveau actuel | G5: Ce qui est déjà fait et ce qui justifie la note | H5: Compétences nécessaires | I5: Points forts et points faibles | J5: Niveau de priorité | K5: Clé de priorisation | L5: Intervention urgente | M5: Intervention prioritaire | N5: Intervention à moyen terme | O5: Intervention à long terme | P5: Intervention de consolidation | Q5: Intervention non prioritaire | R5: Intervention non pertinente | S5: Libellé de priorité | T5: Score de priorité | U5: Code priorité et compétences | V5: Actions proposées pour atteindre la cible
B6: Renseigner les cellules jaunes pour les notes, puis les textes utiles. La priorité se calcule automatiquement. Faire défiler vers la droite pour proposer des actions.
B7: 5.1 | C7: Concevoir les services numériques en réponse aux besoins sociaux des étudiants et des personnels : précarité, éloignement, handicap. | J7: =S7 | K7: =IF(IF(ISNUMBER(E7),AND(E7>=0,E7<=3,MOD(E7,1)=0),FALSE),IF(E7=0,0,IF(IF(ISNUMBER(F7),AND(F7>=1,F7<=4,MOD(F7,1)=0),FALSE),E7*10+F7,"")),"") | L7: =IF(ISNUMBER(K7),K7=31,FALSE) -> FALSE | M7: =IF(ISNUMBER(K7),OR(K7=21,K7=32),FALSE) -> FALSE | N7: =IF(ISNUMBER(K7),OR(K7=22,K7=33),FALSE) -> FALSE | O7: =IF(ISNUMBER(K7),OR(K7=11,K7=12),FALSE) -> FALSE | P7: =IF(ISNUMBER(K7),OR(K7=23,K7=34),FALSE) -> FALSE | Q7: =IF(ISNUMBER(K7),OR(K7=13,K7=14,K7=24),FALSE) -> FALSE | R7: =IF(ISNUMBER(K7),K7=0,FALSE) -> FALSE | S7: =IF(ISNUMBER(T7),INDEX($L$5:$R$5,1,7-T7),"") | T7: =IF(ISNUMBER(K7),IF(L7,6,IF(M7,5,IF(N7,4,IF(O7,3,IF(P7,2,IF(Q7,1,0)))))),"") | U7: =IF(AND(ISNUMBER(T7),ISNUMBER(H7)),IF(AND(H7>=1,H7<=4,MOD(H7,1)=0),T7*10+H7,""),"")
B8: 5.2 | C8: Faire connaître et soutenir les initiatives des personnels et des étudiants qui encouragent la coopération entre services et le bien-être au travail et aux études. | J8: =S8 | K8: =IF(IF(ISNUMBER(E8),AND(E8>=0,E8<=3,MOD(E8,1)=0),FALSE),IF(E8=0,0,IF(IF(ISNUMBER(F8),AND(F8>=1,F8<=4,MOD(F8,1)=0),FALSE),E8*10+F8,"")),"") | L8: =IF(ISNUMBER(K8),K8=31,FALSE) -> FALSE | M8: =IF(ISNUMBER(K8),OR(K8=21,K8=32),FALSE) -> FALSE | N8: =IF(ISNUMBER(K8),OR(K8=22,K8=33),FALSE) -> FALSE | O8: =IF(ISNUMBER(K8),OR(K8=11,K8=12),FALSE) -> FALSE | P8: =IF(ISNUMBER(K8),OR(K8=23,K8=34),FALSE) -> FALSE | Q8: =IF(ISNUMBER(K8),OR(K8=13,K8=14,K8=24),FALSE) -> FALSE | R8: =IF(ISNUMBER(K8),K8=0,FALSE) -> FALSE | S8: =IF(ISNUMBER(T8),INDEX($L$5:$R$5,1,7-T8),"") | T8: =IF(ISNUMBER(K8),IF(L8,6,IF(M8,5,IF(N8,4,IF(O8,3,IF(P8,2,IF(Q8,1,0)))))),"") | U8: =IF(AND(ISNUMBER(T8),ISNUMBER(H8)),IF(AND(H8>=1,H8<=4,MOD(H8,1)=0),T8*10+H8,""),"")
B9: 5.3 | C9: Associer les étudiants, les personnels, les chercheurs et les partenaires du territoire aux choix numériques, en s'appuyant sur leur expertise. | J9: =S9 | K9: =IF(IF(ISNUMBER(E9),AND(E9>=0,E9<=3,MOD(E9,1)=0),FALSE),IF(E9=0,0,IF(IF(ISNUMBER(F9),AND(F9>=1,F9<=4,MOD(F9,1)=0),FALSE),E9*10+F9,"")),"") | L9: =IF(ISNUMBER(K9),K9=31,FALSE) -> FALSE | M9: =IF(ISNUMBER(K9),OR(K9=21,K9=32),FALSE) -> FALSE | N9: =IF(ISNUMBER(K9),OR(K9=22,K9=33),FALSE) -> FALSE | O9: =IF(ISNUMBER(K9),OR(K9=11,K9=12),FALSE) -> FALSE | P9: =IF(ISNUMBER(K9),OR(K9=23,K9=34),FALSE) -> FALSE | Q9: =IF(ISNUMBER(K9),OR(K9=13,K9=14,K9=24),FALSE) -> FALSE | R9: =IF(ISNUMBER(K9),K9=0,FALSE) -> FALSE | S9: =IF(ISNUMBER(T9),INDEX($L$5:$R$5,1,7-T9),"") | T9: =IF(ISNUMBER(K9),IF(L9,6,IF(M9,5,IF(N9,4,IF(O9,3,IF(P9,2,IF(Q9,1,0)))))),"") | U9: =IF(AND(ISNUMBER(T9),ISNUMBER(H9)),IF(AND(H9>=1,H9<=4,MOD(H9,1)=0),T9*10+H9,""),"")
B10: 5.4 | C10: Former des diplômés capables d'innover pour mieux vivre ensemble et préserver les écosystèmes, en intégrant le numérique responsable dans les formations. | J10: =S10 | K10: =IF(IF(ISNUMBER(E10),AND(E10>=0,E10<=3,MOD(E10,1)=0),FALSE),IF(E10=0,0,IF(IF(ISNUMBER(F10),AND(F10>=1,F10<=4,MOD(F10,1)=0),FALSE),E10*10+F10,"")),"") | L10: =IF(ISNUMBER(K10),K10=31,FALSE) -> FALSE | M10: =IF(ISNUMBER(K10),OR(K10=21,K10=32),FALSE) -> FALSE | N10: =IF(ISNUMBER(K10),OR(K10=22,K10=33),FALSE) -> FALSE | O10: =IF(ISNUMBER(K10),OR(K10=11,K10=12),FALSE) -> FALSE | P10: =IF(ISNUMBER(K10),OR(K10=23,K10=34),FALSE) -> FALSE | Q10: =IF(ISNUMBER(K10),OR(K10=13,K10=14,K10=24),FALSE) -> FALSE | R10: =IF(ISNUMBER(K10),K10=0,FALSE) -> FALSE | S10: =IF(ISNUMBER(T10),INDEX($L$5:$R$5,1,7-T10),"") | T10: =IF(ISNUMBER(K10),IF(L10,6,IF(M10,5,IF(N10,4,IF(O10,3,IF(P10,2,IF(Q10,1,0)))))),"") | U10: =IF(AND(ISNUMBER(T10),ISNUMBER(H10)),IF(AND(H10>=1,H10<=4,MOD(H10,1)=0),T10*10+H10,""),"")
B11: 5.5 | C11: Suivre les résultats de la démarche avec quelques indicateurs, communs avec le plan de transition et le label DD&RS. | J11: =S11 | K11: =IF(IF(ISNUMBER(E11),AND(E11>=0,E11<=3,MOD(E11,1)=0),FALSE),IF(E11=0,0,IF(IF(ISNUMBER(F11),AND(F11>=1,F11<=4,MOD(F11,1)=0),FALSE),E11*10+F11,"")),"") | L11: =IF(ISNUMBER(K11),K11=31,FALSE) -> FALSE | M11: =IF(ISNUMBER(K11),OR(K11=21,K11=32),FALSE) -> FALSE | N11: =IF(ISNUMBER(K11),OR(K11=22,K11=33),FALSE) -> FALSE | O11: =IF(ISNUMBER(K11),OR(K11=11,K11=12),FALSE) -> FALSE | P11: =IF(ISNUMBER(K11),OR(K11=23,K11=34),FALSE) -> FALSE | Q11: =IF(ISNUMBER(K11),OR(K11=13,K11=14,K11=24),FALSE) -> FALSE | R11: =IF(ISNUMBER(K11),K11=0,FALSE) -> FALSE | S11: =IF(ISNUMBER(T11),INDEX($L$5:$R$5,1,7-T11),"") | T11: =IF(ISNUMBER(K11),IF(L11,6,IF(M11,5,IF(N11,4,IF(O11,3,IF(P11,2,IF(Q11,1,0)))))),"") | U11: =IF(AND(ISNUMBER(T11),ISNUMBER(H11)),IF(AND(H11>=1,H11<=4,MOD(H11,1)=0),T11*10+H11,""),"")
B12: 5.6 | C12: Proposer des améliorations pour un numérique responsable, y compris des solutions sans outil numérique, comme des cours ou des examens sans écran. | J12: =S12 | K12: =IF(IF(ISNUMBER(E12),AND(E12>=0,E12<=3,MOD(E12,1)=0),FALSE),IF(E12=0,0,IF(IF(ISNUMBER(F12),AND(F12>=1,F12<=4,MOD(F12,1)=0),FALSE),E12*10+F12,"")),"") | L12: =IF(ISNUMBER(K12),K12=31,FALSE) -> FALSE | M12: =IF(ISNUMBER(K12),OR(K12=21,K12=32),FALSE) -> FALSE | N12: =IF(ISNUMBER(K12),OR(K12=22,K12=33),FALSE) -> FALSE | O12: =IF(ISNUMBER(K12),OR(K12=11,K12=12),FALSE) -> FALSE | P12: =IF(ISNUMBER(K12),OR(K12=23,K12=34),FALSE) -> FALSE | Q12: =IF(ISNUMBER(K12),OR(K12=13,K12=14,K12=24),FALSE) -> FALSE | R12: =IF(ISNUMBER(K12),K12=0,FALSE) -> FALSE | S12: =IF(ISNUMBER(T12),INDEX($L$5:$R$5,1,7-T12),"") | T12: =IF(ISNUMBER(K12),IF(L12,6,IF(M12,5,IF(N12,4,IF(O12,3,IF(P12,2,IF(Q12,1,0)))))),"") | U12: =IF(AND(ISNUMBER(T12),ISNUMBER(H12)),IF(AND(H12>=1,H12<=4,MOD(H12,1)=0),T12*10+H12,""),"")
B13: 5.7 | C13: Décider avec les enseignants, les chercheurs, les personnels et les étudiants comment utiliser l'intelligence artificielle. Les former à ses limites et préserver le sens de l'apprentissage et de la recherche. | J13: =S13 -> 0 | K13: =IF(IF(ISNUMBER(E13),AND(E13>=0,E13<=3,MOD(E13,1)=0),FALSE),IF(E13=0,0,IF(IF(ISNUMBER(F13),AND(F13>=1,F13<=4,MOD(F13,1)=0),FALSE),E13*10+F13,"")),"") | L13: =IF(ISNUMBER(K13),K13=31,FALSE) -> FALSE | M13: =IF(ISNUMBER(K13),OR(K13=21,K13=32),FALSE) -> FALSE | N13: =IF(ISNUMBER(K13),OR(K13=22,K13=33),FALSE) -> FALSE | O13: =IF(ISNUMBER(K13),OR(K13=11,K13=12),FALSE) -> FALSE | P13: =IF(ISNUMBER(K13),OR(K13=23,K13=34),FALSE) -> FALSE | Q13: =IF(ISNUMBER(K13),OR(K13=13,K13=14,K13=24),FALSE) -> FALSE | R13: =IF(ISNUMBER(K13),K13=0,FALSE) -> FALSE | S13: =IF(ISNUMBER(T13),INDEX($L$5:$R$5,1,7-T13),"") | T13: =IF(ISNUMBER(K13),IF(L13,6,IF(M13,5,IF(N13,4,IF(O13,3,IF(P13,2,IF(Q13,1,0)))))),"") | U13: =IF(AND(ISNUMBER(T13),ISNUMBER(H13)),IF(AND(H13>=1,H13<=4,MOD(H13,1)=0),T13*10+H13,""),"")

Sheet Cibles métier
L1: 0 | M1: 1 | N1: 2 | O1: 3 | P1: 4 | Q1: 5
B2: Cibles propres au secteur · Enseignement supérieur et recherche
B4: Cibles à évaluer | D4: Importance de la cible | F4: Performance actuelle | H4: Compétences internes et externes | J4: Priorité | V4: Mise en œuvre
D5: Avantages possibles et risques | E5: Importance | F5: Niveau actuel | G5: Ce qui est déjà fait et ce qui justifie la note | H5: Compétences nécessaires | I5: Points forts et points faibles | J5: Niveau de priorité | K5: Clé de priorisation | L5: Intervention urgente | M5: Intervention prioritaire | N5: Intervention à moyen terme | O5: Intervention à long terme | P5: Intervention de consolidation | Q5: Intervention non prioritaire | R5: Intervention non pertinente | S5: Libellé de priorité | T5: Score de priorité | U5: Code priorité et compétences | V5: Actions proposées pour atteindre la cible | W5: Adhérence
B6: Renseigner les cellules jaunes pour les notes, puis les textes utiles. La priorité se calcule automatiquement. Faire défiler vers la droite pour proposer des actions.
B7: E.1 | C7: Rendre sobres le calcul et le stockage de la recherche : utiliser les mésocentres et les centres nationaux plutôt que des serveurs par équipe, mesurer l'empreinte des projets, et ne conserver que les données utiles. | J7: =S7 | K7: =IF(IF(ISNUMBER(E7),AND(E7>=0,E7<=3,MOD(E7,1)=0),FALSE),IF(E7=0,0,IF(IF(ISNUMBER(F7),AND(F7>=1,F7<=4,MOD(F7,1)=0),FALSE),E7*10+F7,"")),"") | L7: =IF(ISNUMBER(K7),K7=31,FALSE) -> FALSE | M7: =IF(ISNUMBER(K7),OR(K7=21,K7=32),FALSE) -> FALSE | N7: =IF(ISNUMBER(K7),OR(K7=22,K7=33),FALSE) -> FALSE | O7: =IF(ISNUMBER(K7),OR(K7=11,K7=12),FALSE) -> FALSE | P7: =IF(ISNUMBER(K7),OR(K7=23,K7=34),FALSE) -> FALSE | Q7: =IF(ISNUMBER(K7),OR(K7=13,K7=14,K7=24),FALSE) -> FALSE | R7: =IF(ISNUMBER(K7),K7=0,FALSE) -> FALSE | S7: =IF(ISNUMBER(T7),INDEX($L$5:$R$5,1,7-T7),"") | T7: =IF(ISNUMBER(K7),IF(L7,6,IF(M7,5,IF(N7,4,IF(O7,3,IF(P7,2,IF(Q7,1,0)))))),"") | U7: =IF(AND(ISNUMBER(T7),ISNUMBER(H7)),IF(AND(H7>=1,H7<=4,MOD(H7,1)=0),T7*10+H7,""),"")
B8: E.2 | C8: Garantir à chaque étudiant un accès égal aux outils et aux enseignements numériques : équipement, connexion, accessibilité des contenus et accompagnement. | J8: =S8 | K8: =IF(IF(ISNUMBER(E8),AND(E8>=0,E8<=3,MOD(E8,1)=0),FALSE),IF(E8=0,0,IF(IF(ISNUMBER(F8),AND(F8>=1,F8<=4,MOD(F8,1)=0),FALSE),E8*10+F8,"")),"") | L8: =IF(ISNUMBER(K8),K8=31,FALSE) -> FALSE | M8: =IF(ISNUMBER(K8),OR(K8=21,K8=32),FALSE) -> FALSE | N8: =IF(ISNUMBER(K8),OR(K8=22,K8=33),FALSE) -> FALSE | O8: =IF(ISNUMBER(K8),OR(K8=11,K8=12),FALSE) -> FALSE | P8: =IF(ISNUMBER(K8),OR(K8=23,K8=34),FALSE) -> FALSE | Q8: =IF(ISNUMBER(K8),OR(K8=13,K8=14,K8=24),FALSE) -> FALSE | R8: =IF(ISNUMBER(K8),K8=0,FALSE) -> FALSE | S8: =IF(ISNUMBER(T8),INDEX($L$5:$R$5,1,7-T8),"") | T8: =IF(ISNUMBER(K8),IF(L8,6,IF(M8,5,IF(N8,4,IF(O8,3,IF(P8,2,IF(Q8,1,0)))))),"") | U8: =IF(AND(ISNUMBER(T8),ISNUMBER(H8)),IF(AND(H8>=1,H8<=4,MOD(H8,1)=0),T8*10+H8,""),"")
B9: E.3 | C9: Ouvrir les publications, les données et les logiciels de recherche, selon le plan national pour la science ouverte (HAL, Recherche Data Gouv, Software Heritage), dans le respect de la vie privée. | J9: =S9 | K9: =IF(IF(ISNUMBER(E9),AND(E9>=0,E9<=3,MOD(E9,1)=0),FALSE),IF(E9=0,0,IF(IF(ISNUMBER(F9),AND(F9>=1,F9<=4,MOD(F9,1)=0),FALSE),E9*10+F9,"")),"") | L9: =IF(ISNUMBER(K9),K9=31,FALSE) -> FALSE | M9: =IF(ISNUMBER(K9),OR(K9=21,K9=32),FALSE) -> FALSE | N9: =IF(ISNUMBER(K9),OR(K9=22,K9=33),FALSE) -> FALSE | O9: =IF(ISNUMBER(K9),OR(K9=11,K9=12),FALSE) -> FALSE | P9: =IF(ISNUMBER(K9),OR(K9=23,K9=34),FALSE) -> FALSE | Q9: =IF(ISNUMBER(K9),OR(K9=13,K9=14,K9=24),FALSE) -> FALSE | R9: =IF(ISNUMBER(K9),K9=0,FALSE) -> FALSE | S9: =IF(ISNUMBER(T9),INDEX($L$5:$R$5,1,7-T9),"") | T9: =IF(ISNUMBER(K9),IF(L9,6,IF(M9,5,IF(N9,4,IF(O9,3,IF(P9,2,IF(Q9,1,0)))))),"") | U9: =IF(AND(ISNUMBER(T9),ISNUMBER(H9)),IF(AND(H9>=1,H9<=4,MOD(H9,1)=0),T9*10+H9,""),"")
B10: E.4 | C10: Intégrer le numérique responsable au plan de transition, au schéma directeur du numérique et au label DD&RS de l'établissement. | J10: =S10 | K10: =IF(IF(ISNUMBER(E10),AND(E10>=0,E10<=3,MOD(E10,1)=0),FALSE),IF(E10=0,0,IF(IF(ISNUMBER(F10),AND(F10>=1,F10<=4,MOD(F10,1)=0),FALSE),E10*10+F10,"")),"") | L10: =IF(ISNUMBER(K10),K10=31,FALSE) -> FALSE | M10: =IF(ISNUMBER(K10),OR(K10=21,K10=32),FALSE) -> FALSE | N10: =IF(ISNUMBER(K10),OR(K10=22,K10=33),FALSE) -> FALSE | O10: =IF(ISNUMBER(K10),OR(K10=11,K10=12),FALSE) -> FALSE | P10: =IF(ISNUMBER(K10),OR(K10=23,K10=34),FALSE) -> FALSE | Q10: =IF(ISNUMBER(K10),OR(K10=13,K10=14,K10=24),FALSE) -> FALSE | R10: =IF(ISNUMBER(K10),K10=0,FALSE) -> FALSE | S10: =IF(ISNUMBER(T10),INDEX($L$5:$R$5,1,7-T10),"") | T10: =IF(ISNUMBER(K10),IF(L10,6,IF(M10,5,IF(N10,4,IF(O10,3,IF(P10,2,IF(Q10,1,0)))))),"") | U10: =IF(AND(ISNUMBER(T10),ISNUMBER(H10)),IF(AND(H10>=1,H10<=4,MOD(H10,1)=0),T10*10+H10,""),"")
B11: E.5 | C11: Former tous les étudiants et les personnels au numérique responsable, dans le cadre de la formation à la transition écologique. | J11: =S11 -> 0 | K11: =IF(IF(ISNUMBER(E11),AND(E11>=0,E11<=3,MOD(E11,1)=0),FALSE),IF(E11=0,0,IF(IF(ISNUMBER(F11),AND(F11>=1,F11<=4,MOD(F11,1)=0),FALSE),E11*10+F11,"")),"") | L11: =IF(ISNUMBER(K11),K11=31,FALSE) -> FALSE | M11: =IF(ISNUMBER(K11),OR(K11=21,K11=32),FALSE) -> FALSE | N11: =IF(ISNUMBER(K11),OR(K11=22,K11=33),FALSE) -> FALSE | O11: =IF(ISNUMBER(K11),OR(K11=11,K11=12),FALSE) -> FALSE | P11: =IF(ISNUMBER(K11),OR(K11=23,K11=34),FALSE) -> FALSE | Q11: =IF(ISNUMBER(K11),OR(K11=13,K11=14,K11=24),FALSE) -> FALSE | R11: =IF(ISNUMBER(K11),K11=0,FALSE) -> FALSE | S11: =IF(ISNUMBER(T11),INDEX($L$5:$R$5,1,7-T11),"") | T11: =IF(ISNUMBER(K11),IF(L11,6,IF(M11,5,IF(N11,4,IF(O11,3,IF(P11,2,IF(Q11,1,0)))))),"") | U11: =IF(AND(ISNUMBER(T11),ISNUMBER(H11)),IF(AND(H11>=1,H11<=4,MOD(H11,1)=0),T11*10+H11,""),"")

Sheet Priorisation
B2: Tableau de priorisation des cibles
A4: Importance de la cible | B4: 3 | H4: Intervention urgente | I4: Intervention de consolidation
B5: 2 | H5: Intervention prioritaire | I5: Intervention non prioritaire
B6: 1 | H6: Intervention à moyen terme | I6: Intervention non pertinente
B7: 0 | H7: Intervention à long terme
C8: 1 | D8: 2 | E8: 3 | F8: 4
C9: État de la situation actuelle

Sheet Résultats détaillés
L1: 0 | M1: 1 | N1: 2 | O1: 3 | P1: 4 | Q1: 5
B2: Résultats détaillés | V2: Mise en œuvre des actions | Y2: Analyse des Forces, Faiblesses, Opportunités et Menaces (FFOM)
D3: Enjeux locaux associés à la cible | E3: ='ONR 1'!E5 -> Importance | F3: ='ONR 1'!F5 -> Niveau actuel | G3: ='ONR 1'!G5 -> Ce qui est déjà fait et ce qui justifie la note | H3: ='ONR 1'!H5 -> Compétences nécessaires | I3: ='ONR 1'!I5 -> Points forts et points faibles | J3: ='ONR 1'!J5 -> Niveau de priorité | K3: Valeur priorité | L3: Intervention urgente | M3: Intervention prioritaire | N3: Intervention à moyen terme | O3: Intervention à long terme | P3: Intervention de consolidation | Q3: Intervention non prioritaire | R3: Intervention non pertinente | S3: Priorité texte | T3: Priorité valeur | U3: Valeur type d'action | V3: Mesures et actions déjà en place | W3: Stratégies d'action pouvant contribuer à l'atteinte de la cible et proposées lors de l'analyse | X3: Synergies avec les Modules (M3 stratégie, M4 sensibiliser, M5 action) | Y3: Forces et faiblesses en regard de la cible | Z3: Opportunités et menaces en regard de la cible | AB3: ONR | AC3: Nombre de cibles | AD3: Nombre de cibles analysées | AE3: Cibles à évaluer | AF3: Nombre de cibles urgentes | AG3: Nombre de cibles prioritaires | AH3: Nombre de cibles à moyen terme | AI3: Nombre de cibles à long terme | AJ3: Nombre de cibles à consolider | AK3: Nombre de cibles non prioritaires | AL3: Cibles non applicables | AM3: Piste d’action renseignée
B4: ='ONR 1'!B2 -> ONR 1 : Sobriété · Utiliser les outils numériques pour consommer moins de ressources et réduire leurs effets sur l’environnement | AB4: =B4 -> ONR 1 : Sobriété · Utiliser les outils numériques pour consommer moins de ressources et réduire leurs effets sur l’environnement | AC4: =COUNTA('ONR 1'!B7:B14) -> 8 | AD4: =COUNT(T5:T12) -> 0 | AE4: =SUM(AE5:AE12) -> 8 | AF4: =SUM(AF5:AF12) -> 0 | AG4: =SUM(AG5:AG12) -> 0 | AH4: =SUM(AH5:AH12) -> 0 | AI4: =SUM(AI5:AI12) -> 0 | AJ4: =SUM(AJ5:AJ12) -> 0 | AK4: =SUM(AK5:AK12) -> 0 | AL4: =SUM(AL5:AL12) -> 0
B5: =IF(ISBLANK('ONR 1'!B7),"",'ONR 1'!B7) -> 1.1 | C5: =IF(ISBLANK('ONR 1'!C7),"",'ONR 1'!C7) -> Prendre en compte toute la vie des équipements et des logiciels de l'établissement, de l'achat à la fin de vie : postes, salles informatiques, équipements de laboratoire et de calcul. | D5: =IF(ISBLANK('ONR 1'!D7),"",'ONR 1'!D7) | E5: =IF(ISBLANK('ONR 1'!E7),"",'ONR 1'!E7) | F5: =IF(ISBLANK('ONR 1'!F7),"",'ONR 1'!F7) | G5: =IF(ISBLANK('ONR 1'!G7),"",'ONR 1'!G7) | H5: =IF(ISBLANK('ONR 1'!H7),"",'ONR 1'!H7) | I5: =IF(ISBLANK('ONR 1'!I7),"",'ONR 1'!I7) | ... U5: =IF(ISBLANK('ONR 1'!U7),"",'ONR 1'!U7) | V5: =IF(ISBLANK('ONR 1'!G7),"",'ONR 1'!G7) | W5: =IF(ISBLANK('ONR 1'!V7),"",'ONR 1'!V7) | X5: =IF(ISBLANK('ONR 1'!W7),"",'ONR 1'!W7) | Y5: =IF(ISBLANK('ONR 1'!I7),"",'ONR 1'!I7) | Z5: =IF(ISBLANK('ONR 1'!D7),"",'ONR 1'!D7) | AE5: =IF(ISNUMBER(T5),0,1) | AF5: =IF(L5=TRUE,1,0) | AG5: =IF(M5=TRUE,1,0) | AH5: =IF(N5=TRUE,1,0) | AI5: =IF(O5=TRUE,1,0) | AJ5: =IF(P5=TRUE,1,0) | AK5: =IF(Q5=TRUE,1,0) | AL5: =IF(R5=TRUE,1,0) | AM5: =IF(LEN(TRIM(W5))>0,1,0) -> 0
B6: =IF(ISBLANK('ONR 1'!B8),"",'ONR 1'!B8) -> 1.2 | C6: =IF(ISBLANK('ONR 1'!C8),"",'ONR 1'!C8) -> Utiliser plus longtemps les équipements des personnels, des salles et des laboratoires, même après leur amortissement, en organisant leur réparation et leur réaffectation. | D6: =IF(ISBLANK('ONR 1'!D8),"",'ONR 1'!D8) | E6: =IF(ISBLANK('ONR 1'!E8),"",'ONR 1'!E8) | F6: =IF(ISBLANK('ONR 1'!F8),"",'ONR 1'!F8) | G6: =IF(ISBLANK('ONR 1'!G8),"",'ONR 1'!G8) | H6: =IF(ISBLANK('ONR 1'!H8),"",'ONR 1'!H8) | I6: =IF(ISBLANK('ONR 1'!I8),"",'ONR 1'!I8) | ... U6: =IF(ISBLANK('ONR 1'!U8),"",'ONR 1'!U8) | V6: =IF(ISBLANK('ONR 1'!G8),"",'ONR 1'!G8) | W6: =IF(ISBLANK('ONR 1'!V8),"",'ONR 1'!V8) | X6: =IF(ISBLANK('ONR 1'!W8),"",'ONR 1'!W8) | Y6: =IF(ISBLANK('ONR 1'!I8),"",'ONR 1'!I8) | Z6: =IF(ISBLANK('ONR 1'!D8),"",'ONR 1'!D8) | AE6: =IF(ISNUMBER(T6),0,1) | AF6: =IF(L6=TRUE,1,0) | AG6: =IF(M6=TRUE,1,0) | AH6: =IF(N6=TRUE,1,0) | AI6: =IF(O6=TRUE,1,0) | AJ6: =IF(P6=TRUE,1,0) | AK6: =IF(Q6=TRUE,1,0) | AL6: =IF(R6=TRUE,1,0) | AM6: =IF(LEN(TRIM(W6))>0,1,0) -> 0
B7: =IF(ISBLANK('ONR 1'!B9),"",'ONR 1'!B9) -> 1.3 | C7: =IF(ISBLANK('ONR 1'!C9),"",'ONR 1'!C9) -> Concevoir des services numériques qui limitent leurs effets sur l'environnement, en suivant le RGESN : plateforme pédagogique (LMS comme Moodle), environnement numérique de travail (ENT), applications de scolarité, logiciels de recherche. Choisir des technologies qui contribuent aux ODD. | D7: =IF(ISBLANK('ONR 1'!D9),"",'ONR 1'!D9) | E7: =IF(ISBLANK('ONR 1'!E9),"",'ONR 1'!E9) | F7: =IF(ISBLANK('ONR 1'!F9),"",'ONR 1'!F9) | G7: =IF(ISBLANK('ONR 1'!G9),"",'ONR 1'!G9) | H7: =IF(ISBLANK('ONR 1'!H9),"",'ONR 1'!H9) | I7: =IF(ISBLANK('ONR 1'!I9),"",'ONR 1'!I9) | ... U7: =IF(ISBLANK('ONR 1'!U9),"",'ONR 1'!U9) | V7: =IF(ISBLANK('ONR 1'!G9),"",'ONR 1'!G9) | W7: =IF(ISBLANK('ONR 1'!V9),"",'ONR 1'!V9) | X7: =IF(ISBLANK('ONR 1'!W9),"",'ONR 1'!W9) | Y7: =IF(ISBLANK('ONR 1'!I9),"",'ONR 1'!I9) | Z7: =IF(ISBLANK('ONR 1'!D9),"",'ONR 1'!D9) | AE7: =IF(ISNUMBER(T7),0,1) | AF7: =IF(L7=TRUE,1,0) | AG7: =IF(M7=TRUE,1,0) | AH7: =IF(N7=TRUE,1,0) | AI7: =IF(O7=TRUE,1,0) | AJ7: =IF(P7=TRUE,1,0) | AK7: =IF(Q7=TRUE,1,0) | AL7: =IF(R7=TRUE,1,0) | AM7: =IF(LEN(TRIM(W7))>0,1,0) -> 0
B8: =IF(ISBLANK('ONR 1'!B10),"",'ONR 1'!B10) -> 1.4 | C8: =IF(ISBLANK('ONR 1'!C10),"",'ONR 1'!C10) -> Adopter, dans les cours, les examens, l'administration et les laboratoires, des pratiques qui consomment moins de matériel, d'énergie, de papier et de stockage. | D8: =IF(ISBLANK('ONR 1'!D10),"",'ONR 1'!D10) | E8: =IF(ISBLANK('ONR 1'!E10),"",'ONR 1'!E10) | F8: =IF(ISBLANK('ONR 1'!F10),"",'ONR 1'!F10) | G8: =IF(ISBLANK('ONR 1'!G10),"",'ONR 1'!G10) | H8: =IF(ISBLANK('ONR 1'!H10),"",'ONR 1'!H10) | I8: =IF(ISBLANK('ONR 1'!I10),"",'ONR 1'!I10) | ... U8: =IF(ISBLANK('ONR 1'!U10),"",'ONR 1'!U10) | V8: =IF(ISBLANK('ONR 1'!G10),"",'ONR 1'!G10) | W8: =IF(ISBLANK('ONR 1'!V10),"",'ONR 1'!V10) | X8: =IF(ISBLANK('ONR 1'!W10),"",'ONR 1'!W10) | Y8: =IF(ISBLANK('ONR 1'!I10),"",'ONR 1'!I10) | Z8: =IF(ISBLANK('ONR 1'!D10),"",'ONR 1'!D10) | AE8: =IF(ISNUMBER(T8),0,1) | AF8: =IF(L8=TRUE,1,0) | AG8: =IF(M8=TRUE,1,0) | AH8: =IF(N8=TRUE,1,0) | AI8: =IF(O8=TRUE,1,0) | AJ8: =IF(P8=TRUE,1,0) | AK8: =IF(Q8=TRUE,1,0) | AL8: =IF(R8=TRUE,1,0) | AM8: =IF(LEN(TRIM(W8))>0,1,0) -> 0
B9: =IF(ISBLANK('ONR 1'!B11),"",'ONR 1'!B11) -> 1.5 | C9: =IF(ISBLANK('ONR 1'!C11),"",'ONR 1'!C11) -> Confier les équipements en fin d'usage à des filières de réemploi et de l'économie sociale et solidaire, par exemple pour équiper des étudiants. | D9: =IF(ISBLANK('ONR 1'!D11),"",'ONR 1'!D11) | E9: =IF(ISBLANK('ONR 1'!E11),"",'ONR 1'!E11) | F9: =IF(ISBLANK('ONR 1'!F11),"",'ONR 1'!F11) | G9: =IF(ISBLANK('ONR 1'!G11),"",'ONR 1'!G11) | H9: =IF(ISBLANK('ONR 1'!H11),"",'ONR 1'!H11) | I9: =IF(ISBLANK('ONR 1'!I11),"",'ONR 1'!I11) | ... U9: =IF(ISBLANK('ONR 1'!U11),"",'ONR 1'!U11) | V9: =IF(ISBLANK('ONR 1'!G11),"",'ONR 1'!G11) | W9: =IF(ISBLANK('ONR 1'!V11),"",'ONR 1'!V11) | X9: =IF(ISBLANK('ONR 1'!W11),"",'ONR 1'!W11) | Y9: =IF(ISBLANK('ONR 1'!I11),"",'ONR 1'!I11) | Z9: =IF(ISBLANK('ONR 1'!D11),"",'ONR 1'!D11) | AE9: =IF(ISNUMBER(T9),0,1) | AF9: =IF(L9=TRUE,1,0) | AG9: =IF(M9=TRUE,1,0) | AH9: =IF(N9=TRUE,1,0) | AI9: =IF(O9=TRUE,1,0) | AJ9: =IF(P9=TRUE,1,0) | AK9: =IF(Q9=TRUE,1,0) | AL9: =IF(R9=TRUE,1,0) | AM9: =IF(LEN(TRIM(W9))>0,1,0) -> 0
B10: =IF(ISBLANK('ONR 1'!B12),"",'ONR 1'!B12) -> 1.6 | C10: =IF(ISBLANK('ONR 1'!C12),"",'ONR 1'!C12) -> Alimenter les campus, les centres de données et les moyens de calcul avec des énergies renouvelables, et valoriser leur chaleur fatale. | D10: =IF(ISBLANK('ONR 1'!D12),"",'ONR 1'!D12) | E10: =IF(ISBLANK('ONR 1'!E12),"",'ONR 1'!E12) | F10: =IF(ISBLANK('ONR 1'!F12),"",'ONR 1'!F12) | G10: =IF(ISBLANK('ONR 1'!G12),"",'ONR 1'!G12) | H10: =IF(ISBLANK('ONR 1'!H12),"",'ONR 1'!H12) | I10: =IF(ISBLANK('ONR 1'!I12),"",'ONR 1'!I12) | ... U10: =IF(ISBLANK('ONR 1'!U12),"",'ONR 1'!U12) | V10: =IF(ISBLANK('ONR 1'!G12),"",'ONR 1'!G12) | W10: =IF(ISBLANK('ONR 1'!V12),"",'ONR 1'!V12) | X10: =IF(ISBLANK('ONR 1'!W12),"",'ONR 1'!W12) | Y10: =IF(ISBLANK('ONR 1'!I12),"",'ONR 1'!I12) | Z10: =IF(ISBLANK('ONR 1'!D12),"",'ONR 1'!D12) | AE10: =IF(ISNUMBER(T10),0,1) | AF10: =IF(L10=TRUE,1,0) | AG10: =IF(M10=TRUE,1,0) | AH10: =IF(N10=TRUE,1,0) | AI10: =IF(O10=TRUE,1,0) | AJ10: =IF(P10=TRUE,1,0) | AK10: =IF(Q10=TRUE,1,0) | AL10: =IF(R10=TRUE,1,0) | AM10: =IF(LEN(TRIM(W10))>0,1,0) -> 0
B11: =IF(ISBLANK('ONR 1'!B13),"",'ONR 1'!B13) -> 1.7 | C11: =IF(ISBLANK('ONR 1'!C13),"",'ONR 1'!C13) -> Réserver l'intelligence artificielle aux besoins de formation, de recherche et de gestion qui la justifient, et choisir des solutions sobres. | D11: =IF(ISBLANK('ONR 1'!D13),"",'ONR 1'!D13) | E11: =IF(ISBLANK('ONR 1'!E13),"",'ONR 1'!E13) | F11: =IF(ISBLANK('ONR 1'!F13),"",'ONR 1'!F13) | G11: =IF(ISBLANK('ONR 1'!G13),"",'ONR 1'!G13) | H11: =IF(ISBLANK('ONR 1'!H13),"",'ONR 1'!H13) | I11: =IF(ISBLANK('ONR 1'!I13),"",'ONR 1'!I13) | ... U11: =IF(ISBLANK('ONR 1'!U13),"",'ONR 1'!U13) | V11: =IF(ISBLANK('ONR 1'!G13),"",'ONR 1'!G13) | W11: =IF(ISBLANK('ONR 1'!V13),"",'ONR 1'!V13) | X11: =IF(ISBLANK('ONR 1'!W13),"",'ONR 1'!W13) | Y11: =IF(ISBLANK('ONR 1'!I13),"",'ONR 1'!I13) | Z11: =IF(ISBLANK('ONR 1'!D13),"",'ONR 1'!D13) | AE11: =IF(ISNUMBER(T11),0,1) | AF11: =IF(L11=TRUE,1,0) | AG11: =IF(M11=TRUE,1,0) | AH11: =IF(N11=TRUE,1,0) | AI11: =IF(O11=TRUE,1,0) | AJ11: =IF(P11=TRUE,1,0) | AK11: =IF(Q11=TRUE,1,0) | AL11: =IF(R11=TRUE,1,0) | AM11: =IF(LEN(TRIM(W11))>0,1,0) -> 0
B12: =IF(ISBLANK('ONR 1'!B14),"",'ONR 1'!B14) -> 1.8 | C12: =IF(ISBLANK('ONR 1'!C14),"",'ONR 1'!C14) -> Mesurer et réduire ce que consomme l'intelligence artificielle dans l'établissement, notamment l'entraînement de modèles par les équipes de recherche. | D12: =IF(ISBLANK('ONR 1'!D14),"",'ONR 1'!D14) | E12: =IF(ISBLANK('ONR 1'!E14),"",'ONR 1'!E14) | F12: =IF(ISBLANK('ONR 1'!F14),"",'ONR 1'!F14) | G12: =IF(ISBLANK('ONR 1'!G14),"",'ONR 1'!G14) | H12: =IF(ISBLANK('ONR 1'!H14),"",'ONR 1'!H14) | I12: =IF(ISBLANK('ONR 1'!I14),"",'ONR 1'!I14) | ... U12: =IF(ISBLANK('ONR 1'!U14),"",'ONR 1'!U14) | V12: =IF(ISBLANK('ONR 1'!G14),"",'ONR 1'!G14) | W12: =IF(ISBLANK('ONR 1'!V14),"",'ONR 1'!V14) | X12: =IF(ISBLANK('ONR 1'!W14),"",'ONR 1'!W14) | Y12: =IF(ISBLANK('ONR 1'!I14),"",'ONR 1'!I14) | Z12: =IF(ISBLANK('ONR 1'!D14),"",'ONR 1'!D14) | AE12: =IF(ISNUMBER(T12),0,1) -> 1 | AF12: =IF(L12=TRUE,1,0) -> 0 | AG12: =IF(M12=TRUE,1,0) -> 0 | AH12: =IF(N12=TRUE,1,0) -> 0 | AI12: =IF(O12=TRUE,1,0) -> 0 | AJ12: =IF(P12=TRUE,1,0) -> 0 | AK12: =IF(Q12=TRUE,1,0) -> 0 | AL12: =IF(R12=TRUE,1,0) -> 0 | AM12: =IF(LEN(TRIM(W12))>0,1,0) -> 0
B13: ='ONR 2'!B2 -> ONR 2 : Inclusion · Développer des services numériques durables que toutes et tous peuvent utiliser | AB13: =B13 -> ONR 2 : Inclusion · Développer des services numériques durables que toutes et tous peuvent utiliser | AC13: =COUNTA('ONR 2'!B7:B11) -> 5 | AD13: =COUNT(T14:T18) -> 0 | AE13: =SUM(AE14:AE18) -> 5 | AF13: =SUM(AF14:AF18) -> 0 | AG13: =SUM(AG14:AG18) -> 0 | AH13: =SUM(AH14:AH18) -> 0 | AI13: =SUM(AI14:AI18) -> 0 | AJ13: =SUM(AJ14:AJ18) -> 0 | AK13: =SUM(AK14:AK18) -> 0 | AL13: =SUM(AL14:AL18) -> 0
B14: =IF(ISBLANK('ONR 2'!B7),"",'ONR 2'!B7) -> 2.1 | C14: =IF(ISBLANK('ONR 2'!C7),"",'ONR 2'!C7) -> Intégrer dans les achats numériques de l'établissement, y compris ceux des laboratoires, des clauses sociales et environnementales et des critères de durabilité. | D14: =IF(ISBLANK('ONR 2'!D7),"",'ONR 2'!D7) | E14: =IF(ISBLANK('ONR 2'!E7),"",'ONR 2'!E7) | F14: =IF(ISBLANK('ONR 2'!F7),"",'ONR 2'!F7) | G14: =IF(ISBLANK('ONR 2'!G7),"",'ONR 2'!G7) | H14: =IF(ISBLANK('ONR 2'!H7),"",'ONR 2'!H7) | I14: =IF(ISBLANK('ONR 2'!I7),"",'ONR 2'!I7) | ... U14: =IF(ISBLANK('ONR 2'!U7),"",'ONR 2'!U7) | V14: =IF(ISBLANK('ONR 2'!G7),"",'ONR 2'!G7) | W14: =IF(ISBLANK('ONR 2'!V7),"",'ONR 2'!V7) | X14: =IF(ISBLANK('ONR 2'!W7),"",'ONR 2'!W7) | Y14: =IF(ISBLANK('ONR 2'!I7),"",'ONR 2'!I7) | Z14: =IF(ISBLANK('ONR 2'!D7),"",'ONR 2'!D7) | AE14: =IF(ISNUMBER(T14),0,1) -> 1 | AF14: =IF(L14=TRUE,1,0) | AG14: =IF(M14=TRUE,1,0) | AH14: =IF(N14=TRUE,1,0) | AI14: =IF(O14=TRUE,1,0) | AJ14: =IF(P14=TRUE,1,0) | AK14: =IF(Q14=TRUE,1,0) | AL14: =IF(R14=TRUE,1,0) | AM14: =IF(LEN(TRIM(W14))>0,1,0) -> 0
B15: =IF(ISBLANK('ONR 2'!B8),"",'ONR 2'!B8) -> 2.2 | C15: =IF(ISBLANK('ONR 2'!C8),"",'ONR 2'!C8) -> Rendre accessibles à toutes et tous les sites, l'ENT, le LMS et les ressources pédagogiques : vidéos de cours sous-titrées, documents et supports accessibles. Mesurer leur conformité au RGAA. | D15: =IF(ISBLANK('ONR 2'!D8),"",'ONR 2'!D8) | E15: =IF(ISBLANK('ONR 2'!E8),"",'ONR 2'!E8) | F15: =IF(ISBLANK('ONR 2'!F8),"",'ONR 2'!F8) | G15: =IF(ISBLANK('ONR 2'!G8),"",'ONR 2'!G8) | H15: =IF(ISBLANK('ONR 2'!H8),"",'ONR 2'!H8) | I15: =IF(ISBLANK('ONR 2'!I8),"",'ONR 2'!I8) | ... U15: =IF(ISBLANK('ONR 2'!U8),"",'ONR 2'!U8) | V15: =IF(ISBLANK('ONR 2'!G8),"",'ONR 2'!G8) | W15: =IF(ISBLANK('ONR 2'!V8),"",'ONR 2'!V8) | X15: =IF(ISBLANK('ONR 2'!W8),"",'ONR 2'!W8) | Y15: =IF(ISBLANK('ONR 2'!I8),"",'ONR 2'!I8) | Z15: =IF(ISBLANK('ONR 2'!D8),"",'ONR 2'!D8) | AE15: =IF(ISNUMBER(T15),0,1) -> 1 | AF15: =IF(L15=TRUE,1,0) | AG15: =IF(M15=TRUE,1,0) | AH15: =IF(N15=TRUE,1,0) | AI15: =IF(O15=TRUE,1,0) | AJ15: =IF(P15=TRUE,1,0) | AK15: =IF(Q15=TRUE,1,0) | AL15: =IF(R15=TRUE,1,0) | AM15: =IF(LEN(TRIM(W15))>0,1,0) -> 0
B16: =IF(ISBLANK('ONR 2'!B9),"",'ONR 2'!B9) -> 2.3 | C16: =IF(ISBLANK('ONR 2'!C9),"",'ONR 2'!C9) -> Proposer aux étudiants et aux personnels des outils utiles, faciles à utiliser et réellement utilisés, plutôt qu'une multitude de plateformes : un ENT, un LMS, une messagerie, une visioconférence, un outil d'emploi du temps. | D16: =IF(ISBLANK('ONR 2'!D9),"",'ONR 2'!D9) | E16: =IF(ISBLANK('ONR 2'!E9),"",'ONR 2'!E9) | F16: =IF(ISBLANK('ONR 2'!F9),"",'ONR 2'!F9) | G16: =IF(ISBLANK('ONR 2'!G9),"",'ONR 2'!G9) | H16: =IF(ISBLANK('ONR 2'!H9),"",'ONR 2'!H9) | I16: =IF(ISBLANK('ONR 2'!I9),"",'ONR 2'!I9) | ... U16: =IF(ISBLANK('ONR 2'!U9),"",'ONR 2'!U9) | V16: =IF(ISBLANK('ONR 2'!G9),"",'ONR 2'!G9) | W16: =IF(ISBLANK('ONR 2'!V9),"",'ONR 2'!V9) | X16: =IF(ISBLANK('ONR 2'!W9),"",'ONR 2'!W9) | Y16: =IF(ISBLANK('ONR 2'!I9),"",'ONR 2'!I9) | Z16: =IF(ISBLANK('ONR 2'!D9),"",'ONR 2'!D9) | AE16: =IF(ISNUMBER(T16),0,1) -> 1 | AF16: =IF(L16=TRUE,1,0) | AG16: =IF(M16=TRUE,1,0) | AH16: =IF(N16=TRUE,1,0) | AI16: =IF(O16=TRUE,1,0) | AJ16: =IF(P16=TRUE,1,0) | AK16: =IF(Q16=TRUE,1,0) | AL16: =IF(R16=TRUE,1,0) | AM16: =IF(LEN(TRIM(W16))>0,1,0) -> 0
B17: =IF(ISBLANK('ONR 2'!B10),"",'ONR 2'!B10) -> 2.4 | C17: =IF(ISBLANK('ONR 2'!C10),"",'ONR 2'!C10) -> Concevoir les services numériques avec les étudiants, les enseignants, les chercheurs et les personnels, en partant de leurs besoins réels. | D17: =IF(ISBLANK('ONR 2'!D10),"",'ONR 2'!D10) | E17: =IF(ISBLANK('ONR 2'!E10),"",'ONR 2'!E10) | F17: =IF(ISBLANK('ONR 2'!F10),"",'ONR 2'!F10) | G17: =IF(ISBLANK('ONR 2'!G10),"",'ONR 2'!G10) | H17: =IF(ISBLANK('ONR 2'!H10),"",'ONR 2'!H10) | I17: =IF(ISBLANK('ONR 2'!I10),"",'ONR 2'!I10) | ... U17: =IF(ISBLANK('ONR 2'!U10),"",'ONR 2'!U10) | V17: =IF(ISBLANK('ONR 2'!G10),"",'ONR 2'!G10) | W17: =IF(ISBLANK('ONR 2'!V10),"",'ONR 2'!V10) | X17: =IF(ISBLANK('ONR 2'!W10),"",'ONR 2'!W10) | Y17: =IF(ISBLANK('ONR 2'!I10),"",'ONR 2'!I10) | Z17: =IF(ISBLANK('ONR 2'!D10),"",'ONR 2'!D10) | AE17: =IF(ISNUMBER(T17),0,1) -> 1 | AF17: =IF(L17=TRUE,1,0) | AG17: =IF(M17=TRUE,1,0) | AH17: =IF(N17=TRUE,1,0) | AI17: =IF(O17=TRUE,1,0) | AJ17: =IF(P17=TRUE,1,0) | AK17: =IF(Q17=TRUE,1,0) | AL17: =IF(R17=TRUE,1,0) | AM17: =IF(LEN(TRIM(W17))>0,1,0) -> 0
